2020-02-06 01:39:24,070 INFO org.apache.hadoop.yarn.server.resourcemanager.ResourceManager: STARTUP_MSG: 
/************************************************************
STARTUP_MSG: Starting ResourceManager
STARTUP_MSG:   host = nodemaster/172.28.1.15
STARTUP_MSG:   args = []
STARTUP_MSG:   version = 2.7.4
STARTUP_MSG:   build = https://shv@git-wip-us.apache.org/repos/asf/hadoop.git -r cd915e1e8d9d0131462a0b7301586c175728a282; compiled by 'kshvachk' on 2017-08-01T00:29Z
STARTUP_MSG:   java = 1.8.0_232
************************************************************/
2020-02-06 01:39:24,077 INFO org.apache.hadoop.yarn.server.resourcemanager.ResourceManager: registered UNIX signal handlers for [TERM, HUP, INT]
2020-02-06 01:39:24,235 INFO org.apache.hadoop.conf.Configuration: found resource core-site.xml at file:/home/hadoop/hadoop/etc/hadoop/core-site.xml
2020-02-06 01:39:24,260 WARN org.apache.hadoop.util.NativeCodeLoader: Unable to load native-hadoop library for your platform... using builtin-java classes where applicable
2020-02-06 01:39:24,276 INFO org.apache.hadoop.security.Groups: clearing userToGroupsMap cache
2020-02-06 01:39:24,311 INFO org.apache.hadoop.conf.Configuration: found resource yarn-site.xml at file:/home/hadoop/hadoop/etc/hadoop/yarn-site.xml
2020-02-06 01:39:24,389 INFO org.apache.hadoop.yarn.event.AsyncDispatcher: Registering class org.apache.hadoop.yarn.server.resourcemanager.RMFatalEventType for class org.apache.hadoop.yarn.server.resourcemanager.ResourceManager$RMFatalEventDispatcher
2020-02-06 01:39:24,420 INFO org.apache.hadoop.yarn.server.resourcemanager.security.NMTokenSecretManagerInRM: NMTokenKeyRollingInterval: 86400000ms and NMTokenKeyActivationDelay: 900000ms
2020-02-06 01:39:24,422 INFO org.apache.hadoop.yarn.server.resourcemanager.security.RMContainerTokenSecretManager: ContainerTokenKeyRollingInterval: 86400000ms and ContainerTokenKeyActivationDelay: 900000ms
2020-02-06 01:39:24,426 INFO org.apache.hadoop.yarn.server.resourcemanager.security.AMRMTokenSecretManager: AMRMTokenKeyRollingInterval: 86400000ms and AMRMTokenKeyActivationDelay: 900000 ms
2020-02-06 01:39:24,447 INFO org.apache.hadoop.yarn.event.AsyncDispatcher: Registering class org.apache.hadoop.yarn.server.resourcemanager.recovery.RMStateStoreEventType for class org.apache.hadoop.yarn.server.resourcemanager.recovery.RMStateStore$ForwardingEventHandler
2020-02-06 01:39:24,448 INFO org.apache.hadoop.yarn.event.AsyncDispatcher: Registering class org.apache.hadoop.yarn.server.resourcemanager.NodesListManagerEventType for class org.apache.hadoop.yarn.server.resourcemanager.NodesListManager
2020-02-06 01:39:24,448 INFO org.apache.hadoop.yarn.server.resourcemanager.ResourceManager: Using Scheduler: org.apache.hadoop.yarn.server.resourcemanager.scheduler.capacity.CapacityScheduler
2020-02-06 01:39:24,456 INFO org.apache.hadoop.yarn.event.AsyncDispatcher: Registering class org.apache.hadoop.yarn.server.resourcemanager.scheduler.event.SchedulerEventType for class org.apache.hadoop.yarn.server.resourcemanager.ResourceManager$SchedulerEventDispatcher
2020-02-06 01:39:24,457 INFO org.apache.hadoop.yarn.event.AsyncDispatcher: Registering class org.apache.hadoop.yarn.server.resourcemanager.rmapp.RMAppEventType for class org.apache.hadoop.yarn.server.resourcemanager.ResourceManager$ApplicationEventDispatcher
2020-02-06 01:39:24,457 INFO org.apache.hadoop.yarn.event.AsyncDispatcher: Registering class org.apache.hadoop.yarn.server.resourcemanager.rmapp.attempt.RMAppAttemptEventType for class org.apache.hadoop.yarn.server.resourcemanager.ResourceManager$ApplicationAttemptEventDispatcher
2020-02-06 01:39:24,457 INFO org.apache.hadoop.yarn.event.AsyncDispatcher: Registering class org.apache.hadoop.yarn.server.resourcemanager.rmnode.RMNodeEventType for class org.apache.hadoop.yarn.server.resourcemanager.ResourceManager$NodeEventDispatcher
2020-02-06 01:39:24,488 INFO org.apache.hadoop.metrics2.impl.MetricsConfig: loaded properties from hadoop-metrics2.properties
2020-02-06 01:39:24,519 INFO org.apache.hadoop.metrics2.impl.MetricsSystemImpl: Scheduled snapshot period at 10 second(s).
2020-02-06 01:39:24,519 INFO org.apache.hadoop.metrics2.impl.MetricsSystemImpl: ResourceManager metrics system started
2020-02-06 01:39:24,526 INFO org.apache.hadoop.yarn.event.AsyncDispatcher: Registering class org.apache.hadoop.yarn.server.resourcemanager.RMAppManagerEventType for class org.apache.hadoop.yarn.server.resourcemanager.RMAppManager
2020-02-06 01:39:24,529 INFO org.apache.hadoop.yarn.event.AsyncDispatcher: Registering class org.apache.hadoop.yarn.server.resourcemanager.amlauncher.AMLauncherEventType for class org.apache.hadoop.yarn.server.resourcemanager.amlauncher.ApplicationMasterLauncher
2020-02-06 01:39:24,530 INFO org.apache.hadoop.yarn.server.resourcemanager.RMNMInfo: Registered RMNMInfo MBean
2020-02-06 01:39:24,531 INFO org.apache.hadoop.yarn.security.YarnAuthorizationProvider: org.apache.hadoop.yarn.security.ConfiguredYarnAuthorizer is instiantiated.
2020-02-06 01:39:24,532 INFO org.apache.hadoop.util.HostsFileReader: Refreshing hosts (include/exclude) list
2020-02-06 01:39:24,533 INFO org.apache.hadoop.conf.Configuration: found resource capacity-scheduler.xml at file:/home/hadoop/hadoop/etc/hadoop/capacity-scheduler.xml
2020-02-06 01:39:24,559 INFO org.apache.hadoop.yarn.server.resourcemanager.scheduler.capacity.CapacitySchedulerConfiguration: max alloc mb per queue for root is undefined
2020-02-06 01:39:24,559 INFO org.apache.hadoop.yarn.server.resourcemanager.scheduler.capacity.CapacitySchedulerConfiguration: max alloc vcore per queue for root is undefined
2020-02-06 01:39:24,562 INFO org.apache.hadoop.yarn.server.resourcemanager.scheduler.capacity.ParentQueue: root, capacity=1.0, asboluteCapacity=1.0, maxCapacity=1.0, asboluteMaxCapacity=1.0, state=RUNNING, acls=ADMINISTER_QUEUE:*SUBMIT_APP:*, labels=*,
, reservationsContinueLooking=true
2020-02-06 01:39:24,563 INFO org.apache.hadoop.yarn.server.resourcemanager.scheduler.capacity.ParentQueue: Initialized parent-queue root name=root, fullname=root
2020-02-06 01:39:24,567 INFO org.apache.hadoop.yarn.server.resourcemanager.scheduler.capacity.CapacitySchedulerConfiguration: max alloc mb per queue for root.default is undefined
2020-02-06 01:39:24,567 INFO org.apache.hadoop.yarn.server.resourcemanager.scheduler.capacity.CapacitySchedulerConfiguration: max alloc vcore per queue for root.default is undefined
2020-02-06 01:39:24,568 INFO org.apache.hadoop.yarn.server.resourcemanager.scheduler.capacity.LeafQueue: Initializing default
capacity = 1.0 [= (float) configuredCapacity / 100 ]
asboluteCapacity = 1.0 [= parentAbsoluteCapacity * capacity ]
maxCapacity = 1.0 [= configuredMaxCapacity ]
absoluteMaxCapacity = 1.0 [= 1.0 maximumCapacity undefined, (parentAbsoluteMaxCapacity * maximumCapacity) / 100 otherwise ]
userLimit = 100 [= configuredUserLimit ]
userLimitFactor = 1.0 [= configuredUserLimitFactor ]
maxApplications = 10000 [= configuredMaximumSystemApplicationsPerQueue or (int)(configuredMaximumSystemApplications * absoluteCapacity)]
maxApplicationsPerUser = 10000 [= (int)(maxApplications * (userLimit / 100.0f) * userLimitFactor) ]
usedCapacity = 0.0 [= usedResourcesMemory / (clusterResourceMemory * absoluteCapacity)]
absoluteUsedCapacity = 0.0 [= usedResourcesMemory / clusterResourceMemory]
maxAMResourcePerQueuePercent = 0.1 [= configuredMaximumAMResourcePercent ]
minimumAllocationFactor = 0.875 [= (float)(maximumAllocationMemory - minimumAllocationMemory) / maximumAllocationMemory ]
maximumAllocation = <memory:32768, vCores:10> [= configuredMaxAllocation ]
numContainers = 0 [= currentNumContainers ]
state = RUNNING [= configuredState ]
acls = ADMINISTER_QUEUE:*SUBMIT_APP:* [= configuredAcls ]
nodeLocalityDelay = 40
labels=*,
nodeLocalityDelay = 40
reservationsContinueLooking = true
preemptionDisabled = true

2020-02-06 01:39:24,568 INFO org.apache.hadoop.yarn.server.resourcemanager.scheduler.capacity.CapacityScheduler: Initialized queue: default: capacity=1.0, absoluteCapacity=1.0, usedResources=<memory:0, vCores:0>, usedCapacity=0.0, absoluteUsedCapacity=0.0, numApps=0, numContainers=0
2020-02-06 01:39:24,568 INFO org.apache.hadoop.yarn.server.resourcemanager.scheduler.capacity.CapacityScheduler: Initialized queue: root: numChildQueue= 1, capacity=1.0, absoluteCapacity=1.0, usedResources=<memory:0, vCores:0>usedCapacity=0.0, numApps=0, numContainers=0
2020-02-06 01:39:24,569 INFO org.apache.hadoop.yarn.server.resourcemanager.scheduler.capacity.CapacityScheduler: Initialized root queue root: numChildQueue= 1, capacity=1.0, absoluteCapacity=1.0, usedResources=<memory:0, vCores:0>usedCapacity=0.0, numApps=0, numContainers=0
2020-02-06 01:39:24,569 INFO org.apache.hadoop.yarn.server.resourcemanager.scheduler.capacity.CapacityScheduler: Initialized queue mappings, override: false
2020-02-06 01:39:24,569 INFO org.apache.hadoop.yarn.server.resourcemanager.scheduler.capacity.CapacityScheduler: Initialized CapacityScheduler with calculator=class org.apache.hadoop.yarn.util.resource.DefaultResourceCalculator, minimumAllocation=<<memory:4096, vCores:1>>, maximumAllocation=<<memory:32768, vCores:10>>, asynchronousScheduling=false, asyncScheduleInterval=5ms
2020-02-06 01:39:24,574 INFO org.apache.hadoop.yarn.server.resourcemanager.metrics.SystemMetricsPublisher: YARN system metrics publishing service is not enabled
2020-02-06 01:39:24,574 INFO org.apache.hadoop.yarn.server.resourcemanager.ResourceManager: Transitioning to active state
2020-02-06 01:39:24,580 INFO org.apache.hadoop.yarn.server.resourcemanager.recovery.RMStateStore: Updating AMRMToken
2020-02-06 01:39:24,580 INFO org.apache.hadoop.yarn.server.resourcemanager.security.RMContainerTokenSecretManager: Rolling master-key for container-tokens
2020-02-06 01:39:24,581 INFO org.apache.hadoop.yarn.server.resourcemanager.security.NMTokenSecretManagerInRM: Rolling master-key for nm-tokens
2020-02-06 01:39:24,581 INFO org.apache.hadoop.security.token.delegation.AbstractDelegationTokenSecretManager: Updating the current master key for generating delegation tokens
2020-02-06 01:39:24,581 INFO org.apache.hadoop.yarn.server.resourcemanager.security.RMDelegationTokenSecretManager: storing master key with keyID 1
2020-02-06 01:39:24,581 INFO org.apache.hadoop.yarn.server.resourcemanager.recovery.RMStateStore: Storing RMDTMasterKey.
2020-02-06 01:39:24,582 INFO org.apache.hadoop.security.token.delegation.AbstractDelegationTokenSecretManager: Starting expired delegation token remover thread, tokenRemoverScanInterval=60 min(s)
2020-02-06 01:39:24,582 INFO org.apache.hadoop.security.token.delegation.AbstractDelegationTokenSecretManager: Updating the current master key for generating delegation tokens
2020-02-06 01:39:24,582 INFO org.apache.hadoop.yarn.server.resourcemanager.security.RMDelegationTokenSecretManager: storing master key with keyID 2
2020-02-06 01:39:24,582 INFO org.apache.hadoop.yarn.server.resourcemanager.recovery.RMStateStore: Storing RMDTMasterKey.
2020-02-06 01:39:24,582 INFO org.apache.hadoop.yarn.event.AsyncDispatcher: Registering class org.apache.hadoop.yarn.nodelabels.event.NodeLabelsStoreEventType for class org.apache.hadoop.yarn.nodelabels.CommonNodeLabelsManager$ForwardingEventHandler
2020-02-06 01:39:24,595 INFO org.apache.hadoop.ipc.CallQueueManager: Using callQueue: class java.util.concurrent.LinkedBlockingQueue queueCapacity: 5000
2020-02-06 01:39:24,602 INFO org.apache.hadoop.ipc.Server: Starting Socket Reader #1 for port 8025
2020-02-06 01:39:24,681 INFO org.apache.hadoop.yarn.factories.impl.pb.RpcServerFactoryPBImpl: Adding protocol org.apache.hadoop.yarn.server.api.ResourceTrackerPB to the server
2020-02-06 01:39:24,682 INFO org.apache.hadoop.ipc.Server: IPC Server Responder: starting
2020-02-06 01:39:24,682 INFO org.apache.hadoop.ipc.Server: IPC Server listener on 8025: starting
2020-02-06 01:39:24,716 INFO org.apache.hadoop.ipc.CallQueueManager: Using callQueue: class java.util.concurrent.LinkedBlockingQueue queueCapacity: 5000
2020-02-06 01:39:24,719 INFO org.apache.hadoop.ipc.Server: Starting Socket Reader #1 for port 8030
2020-02-06 01:39:24,725 INFO org.apache.hadoop.yarn.factories.impl.pb.RpcServerFactoryPBImpl: Adding protocol org.apache.hadoop.yarn.api.ApplicationMasterProtocolPB to the server
2020-02-06 01:39:24,725 INFO org.apache.hadoop.ipc.Server: IPC Server Responder: starting
2020-02-06 01:39:24,725 INFO org.apache.hadoop.ipc.Server: IPC Server listener on 8030: starting
2020-02-06 01:39:24,746 INFO org.apache.hadoop.ipc.CallQueueManager: Using callQueue: class java.util.concurrent.LinkedBlockingQueue queueCapacity: 5000
2020-02-06 01:39:24,747 INFO org.apache.hadoop.ipc.Server: Starting Socket Reader #1 for port 8040
2020-02-06 01:39:24,749 INFO org.apache.hadoop.yarn.factories.impl.pb.RpcServerFactoryPBImpl: Adding protocol org.apache.hadoop.yarn.api.ApplicationClientProtocolPB to the server
2020-02-06 01:39:24,750 INFO org.apache.hadoop.ipc.Server: IPC Server Responder: starting
2020-02-06 01:39:24,750 INFO org.apache.hadoop.ipc.Server: IPC Server listener on 8040: starting
2020-02-06 01:39:24,753 INFO org.apache.hadoop.yarn.server.resourcemanager.ResourceManager: Transitioned to active state
2020-02-06 01:39:24,789 INFO org.mortbay.log: Logging to org.slf4j.impl.Log4jLoggerAdapter(org.mortbay.log) via org.mortbay.log.Slf4jLog
2020-02-06 01:39:24,792 INFO org.apache.hadoop.security.authentication.server.AuthenticationFilter: Unable to initialize FileSignerSecretProvider, falling back to use random secrets.
2020-02-06 01:39:24,795 INFO org.apache.hadoop.http.HttpRequestLog: Http request log for http.requests.resourcemanager is not defined
2020-02-06 01:39:24,799 INFO org.apache.hadoop.http.HttpServer2: Added global filter 'safety' (class=org.apache.hadoop.http.HttpServer2$QuotingInputFilter)
2020-02-06 01:39:24,801 INFO org.apache.hadoop.http.HttpServer2: Added filter RMAuthenticationFilter (class=org.apache.hadoop.yarn.server.security.http.RMAuthenticationFilter) to context cluster
2020-02-06 01:39:24,801 INFO org.apache.hadoop.http.HttpServer2: Added filter RMAuthenticationFilter (class=org.apache.hadoop.yarn.server.security.http.RMAuthenticationFilter) to context static
2020-02-06 01:39:24,801 INFO org.apache.hadoop.http.HttpServer2: Added filter RMAuthenticationFilter (class=org.apache.hadoop.yarn.server.security.http.RMAuthenticationFilter) to context logs
2020-02-06 01:39:24,801 INFO org.apache.hadoop.http.HttpServer2: Added filter static_user_filter (class=org.apache.hadoop.http.lib.StaticUserWebFilter$StaticUserFilter) to context cluster
2020-02-06 01:39:24,801 INFO org.apache.hadoop.http.HttpServer2: Added filter static_user_filter (class=org.apache.hadoop.http.lib.StaticUserWebFilter$StaticUserFilter) to context static
2020-02-06 01:39:24,801 INFO org.apache.hadoop.http.HttpServer2: Added filter static_user_filter (class=org.apache.hadoop.http.lib.StaticUserWebFilter$StaticUserFilter) to context logs
2020-02-06 01:39:24,803 INFO org.apache.hadoop.http.HttpServer2: adding path spec: /cluster/*
2020-02-06 01:39:24,803 INFO org.apache.hadoop.http.HttpServer2: adding path spec: /ws/*
2020-02-06 01:39:24,988 INFO org.apache.hadoop.yarn.webapp.WebApps: Registered webapp guice modules
2020-02-06 01:39:24,989 INFO org.apache.hadoop.http.HttpServer2: Jetty bound to port 8088
2020-02-06 01:39:24,989 INFO org.mortbay.log: jetty-6.1.26
2020-02-06 01:39:25,002 INFO org.mortbay.log: Extract jar:file:/home/hadoop/hadoop/share/hadoop/yarn/hadoop-yarn-common-2.7.4.jar!/webapps/cluster to /tmp/Jetty_nodemaster_8088_cluster____eps4aa/webapp
2020-02-06 01:39:25,100 INFO org.apache.hadoop.security.token.delegation.AbstractDelegationTokenSecretManager: Updating the current master key for generating delegation tokens
2020-02-06 01:39:25,100 INFO org.apache.hadoop.security.token.delegation.AbstractDelegationTokenSecretManager: Starting expired delegation token remover thread, tokenRemoverScanInterval=60 min(s)
2020-02-06 01:39:25,100 INFO org.apache.hadoop.security.token.delegation.AbstractDelegationTokenSecretManager: Updating the current master key for generating delegation tokens
2020-02-06 01:39:25,650 INFO org.mortbay.log: Started HttpServer2$SelectChannelConnectorWithSafeStartup@nodemaster:8088
2020-02-06 01:39:25,650 INFO org.apache.hadoop.yarn.webapp.WebApps: Web app cluster started at 8088
2020-02-06 01:39:25,669 INFO org.apache.hadoop.ipc.CallQueueManager: Using callQueue: class java.util.concurrent.LinkedBlockingQueue queueCapacity: 100
2020-02-06 01:39:25,670 INFO org.apache.hadoop.ipc.Server: Starting Socket Reader #1 for port 8033
2020-02-06 01:39:25,681 INFO org.apache.hadoop.yarn.factories.impl.pb.RpcServerFactoryPBImpl: Adding protocol org.apache.hadoop.yarn.server.api.ResourceManagerAdministrationProtocolPB to the server
2020-02-06 01:39:25,683 INFO org.apache.hadoop.ipc.Server: IPC Server Responder: starting
2020-02-06 01:39:25,687 INFO org.apache.hadoop.ipc.Server: IPC Server listener on 8033: starting
2020-02-06 01:39:26,816 INFO org.apache.hadoop.yarn.util.RackResolver: Resolved nodemaster to /default-rack
2020-02-06 01:39:26,818 INFO org.apache.hadoop.yarn.server.resourcemanager.ResourceTrackerService: NodeManager from node nodemaster(cmPort: 8050 httpPort: 8042) registered with capability: <memory:32768, vCores:10>, assigned nodeId nodemaster:8050
2020-02-06 01:39:26,819 INFO org.apache.hadoop.yarn.server.resourcemanager.rmnode.RMNodeImpl: nodemaster:8050 Node Transitioned from NEW to RUNNING
2020-02-06 01:39:26,822 INFO org.apache.hadoop.yarn.server.resourcemanager.scheduler.capacity.CapacityScheduler: Added node nodemaster:8050 clusterResource: <memory:32768, vCores:10>
2020-02-06 01:43:47,570 INFO org.apache.hadoop.yarn.server.resourcemanager.ClientRMService: Allocated new applicationId: 1
2020-02-06 01:43:50,768 WARN org.apache.hadoop.yarn.server.resourcemanager.rmapp.RMAppImpl: The specific max attempts: 0 for application: 1 is invalid, because it is out of the range [1, 2]. Use the global max attempts instead.
2020-02-06 01:43:50,769 INFO org.apache.hadoop.yarn.server.resourcemanager.ClientRMService: Application with id 1 submitted by user hadoop
2020-02-06 01:43:50,769 INFO org.apache.hadoop.yarn.server.resourcemanager.rmapp.RMAppImpl: Storing application with id application_1580953164575_0001
2020-02-06 01:43:50,770 INFO org.apache.hadoop.yarn.server.resourcemanager.RMAuditLogger: USER=hadoop	IP=172.28.1.15	OPERATION=Submit Application Request	TARGET=ClientRMService	RESULT=SUCCESS	APPID=application_1580953164575_0001
2020-02-06 01:43:50,773 INFO org.apache.hadoop.yarn.server.resourcemanager.rmapp.RMAppImpl: application_1580953164575_0001 State change from NEW to NEW_SAVING on event=START
2020-02-06 01:43:50,773 INFO org.apache.hadoop.yarn.server.resourcemanager.recovery.RMStateStore: Storing info for app: application_1580953164575_0001
2020-02-06 01:43:50,773 INFO org.apache.hadoop.yarn.server.resourcemanager.rmapp.RMAppImpl: application_1580953164575_0001 State change from NEW_SAVING to SUBMITTED on event=APP_NEW_SAVED
2020-02-06 01:43:50,774 INFO org.apache.hadoop.yarn.server.resourcemanager.scheduler.capacity.ParentQueue: Application added - appId: application_1580953164575_0001 user: hadoop leaf-queue of parent: root #applications: 1
2020-02-06 01:43:50,774 INFO org.apache.hadoop.yarn.server.resourcemanager.scheduler.capacity.CapacityScheduler: Accepted application application_1580953164575_0001 from user: hadoop, in queue: default
2020-02-06 01:43:50,778 INFO org.apache.hadoop.yarn.server.resourcemanager.rmapp.RMAppImpl: application_1580953164575_0001 State change from SUBMITTED to ACCEPTED on event=APP_ACCEPTED
2020-02-06 01:43:50,789 INFO org.apache.hadoop.yarn.server.resourcemanager.ApplicationMasterService: Registering app attempt : appattempt_1580953164575_0001_000001
2020-02-06 01:43:50,790 INFO org.apache.hadoop.yarn.server.resourcemanager.rmapp.attempt.RMAppAttemptImpl: appattempt_1580953164575_0001_000001 State change from NEW to SUBMITTED
2020-02-06 01:43:50,796 INFO org.apache.hadoop.yarn.server.resourcemanager.scheduler.capacity.LeafQueue: Application application_1580953164575_0001 from user: hadoop activated in queue: default
2020-02-06 01:43:50,796 INFO org.apache.hadoop.yarn.server.resourcemanager.scheduler.capacity.LeafQueue: Application added - appId: application_1580953164575_0001 user: org.apache.hadoop.yarn.server.resourcemanager.scheduler.capacity.LeafQueue$User@73372e3d, leaf-queue: default #user-pending-applications: 0 #user-active-applications: 1 #queue-pending-applications: 0 #queue-active-applications: 1
2020-02-06 01:43:50,796 INFO org.apache.hadoop.yarn.server.resourcemanager.scheduler.capacity.CapacityScheduler: Added Application Attempt appattempt_1580953164575_0001_000001 to scheduler from user hadoop in queue default
2020-02-06 01:43:50,822 INFO org.apache.hadoop.yarn.server.resourcemanager.rmapp.attempt.RMAppAttemptImpl: appattempt_1580953164575_0001_000001 State change from SUBMITTED to SCHEDULED
2020-02-06 01:43:51,509 INFO org.apache.hadoop.yarn.server.resourcemanager.rmcontainer.RMContainerImpl: container_1580953164575_0001_01_000001 Container Transitioned from NEW to ALLOCATED
2020-02-06 01:43:51,509 INFO org.apache.hadoop.yarn.server.resourcemanager.RMAuditLogger: USER=hadoop	OPERATION=AM Allocated Container	TARGET=SchedulerApp	RESULT=SUCCESS	APPID=application_1580953164575_0001	CONTAINERID=container_1580953164575_0001_01_000001
2020-02-06 01:43:51,509 INFO org.apache.hadoop.yarn.server.resourcemanager.scheduler.SchedulerNode: Assigned container container_1580953164575_0001_01_000001 of capacity <memory:4096, vCores:1> on host nodemaster:8050, which has 1 containers, <memory:4096, vCores:1> used and <memory:28672, vCores:9> available after allocation
2020-02-06 01:43:51,509 INFO org.apache.hadoop.yarn.server.resourcemanager.scheduler.capacity.LeafQueue: assignedContainer application attempt=appattempt_1580953164575_0001_000001 container=Container: [ContainerId: container_1580953164575_0001_01_000001, NodeId: nodemaster:8050, NodeHttpAddress: nodemaster:8042, Resource: <memory:4096, vCores:1>, Priority: 0, Token: null, ] queue=default: capacity=1.0, absoluteCapacity=1.0, usedResources=<memory:0, vCores:0>, usedCapacity=0.0, absoluteUsedCapacity=0.0, numApps=1, numContainers=0 clusterResource=<memory:32768, vCores:10> type=OFF_SWITCH requestedPartition=
2020-02-06 01:43:51,509 INFO org.apache.hadoop.yarn.server.resourcemanager.scheduler.capacity.ParentQueue: Re-sorting assigned queue: root.default stats: default: capacity=1.0, absoluteCapacity=1.0, usedResources=<memory:4096, vCores:1>, usedCapacity=0.125, absoluteUsedCapacity=0.125, numApps=1, numContainers=1
2020-02-06 01:43:51,509 INFO org.apache.hadoop.yarn.server.resourcemanager.scheduler.capacity.ParentQueue: assignedContainer queue=root usedCapacity=0.125 absoluteUsedCapacity=0.125 used=<memory:4096, vCores:1> cluster=<memory:32768, vCores:10>
2020-02-06 01:43:51,519 INFO org.apache.hadoop.yarn.server.resourcemanager.security.NMTokenSecretManagerInRM: Sending NMToken for nodeId : nodemaster:8050 for container : container_1580953164575_0001_01_000001
2020-02-06 01:43:51,524 INFO org.apache.hadoop.yarn.server.resourcemanager.rmcontainer.RMContainerImpl: container_1580953164575_0001_01_000001 Container Transitioned from ALLOCATED to ACQUIRED
2020-02-06 01:43:51,524 INFO org.apache.hadoop.yarn.server.resourcemanager.security.NMTokenSecretManagerInRM: Clear node set for appattempt_1580953164575_0001_000001
2020-02-06 01:43:51,526 INFO org.apache.hadoop.yarn.server.resourcemanager.rmapp.attempt.RMAppAttemptImpl: Storing attempt: AppId: application_1580953164575_0001 AttemptId: appattempt_1580953164575_0001_000001 MasterContainer: Container: [ContainerId: container_1580953164575_0001_01_000001, NodeId: nodemaster:8050, NodeHttpAddress: nodemaster:8042, Resource: <memory:4096, vCores:1>, Priority: 0, Token: Token { kind: ContainerToken, service: 172.28.1.15:8050 }, ]
2020-02-06 01:43:51,531 INFO org.apache.hadoop.yarn.server.resourcemanager.rmapp.attempt.RMAppAttemptImpl: appattempt_1580953164575_0001_000001 State change from SCHEDULED to ALLOCATED_SAVING
2020-02-06 01:43:51,532 INFO org.apache.hadoop.yarn.server.resourcemanager.rmapp.attempt.RMAppAttemptImpl: appattempt_1580953164575_0001_000001 State change from ALLOCATED_SAVING to ALLOCATED
2020-02-06 01:43:51,533 INFO org.apache.hadoop.yarn.server.resourcemanager.amlauncher.AMLauncher: Launching masterappattempt_1580953164575_0001_000001
2020-02-06 01:43:51,549 INFO org.apache.hadoop.yarn.server.resourcemanager.amlauncher.AMLauncher: Setting up container Container: [ContainerId: container_1580953164575_0001_01_000001, NodeId: nodemaster:8050, NodeHttpAddress: nodemaster:8042, Resource: <memory:4096, vCores:1>, Priority: 0, Token: Token { kind: ContainerToken, service: 172.28.1.15:8050 }, ] for AM appattempt_1580953164575_0001_000001
2020-02-06 01:43:51,549 INFO org.apache.hadoop.yarn.server.resourcemanager.amlauncher.AMLauncher: Command to launch container container_1580953164575_0001_01_000001 : {{JAVA_HOME}}/bin/java,-server,-Xmx512m,-Djava.io.tmpdir={{PWD}}/tmp,-Dspark.yarn.app.container.log.dir=<LOG_DIR>,org.apache.spark.deploy.yarn.ExecutorLauncher,--arg,'nodemaster:41435',--properties-file,{{PWD}}/__spark_conf__/__spark_conf__.properties,1>,<LOG_DIR>/stdout,2>,<LOG_DIR>/stderr
2020-02-06 01:43:51,550 INFO org.apache.hadoop.yarn.server.resourcemanager.security.AMRMTokenSecretManager: Create AMRMToken for ApplicationAttempt: appattempt_1580953164575_0001_000001
2020-02-06 01:43:51,551 INFO org.apache.hadoop.yarn.server.resourcemanager.security.AMRMTokenSecretManager: Creating password for appattempt_1580953164575_0001_000001
2020-02-06 01:43:51,703 INFO org.apache.hadoop.yarn.server.resourcemanager.amlauncher.AMLauncher: Done launching container Container: [ContainerId: container_1580953164575_0001_01_000001, NodeId: nodemaster:8050, NodeHttpAddress: nodemaster:8042, Resource: <memory:4096, vCores:1>, Priority: 0, Token: Token { kind: ContainerToken, service: 172.28.1.15:8050 }, ] for AM appattempt_1580953164575_0001_000001
2020-02-06 01:43:51,703 INFO org.apache.hadoop.yarn.server.resourcemanager.rmapp.attempt.RMAppAttemptImpl: appattempt_1580953164575_0001_000001 State change from ALLOCATED to LAUNCHED
2020-02-06 01:43:52,507 INFO org.apache.hadoop.yarn.server.resourcemanager.rmcontainer.RMContainerImpl: container_1580953164575_0001_01_000001 Container Transitioned from ACQUIRED to RUNNING
2020-02-06 01:43:54,631 INFO SecurityLogger.org.apache.hadoop.ipc.Server: Auth successful for appattempt_1580953164575_0001_000001 (auth:SIMPLE)
2020-02-06 01:43:54,637 INFO org.apache.hadoop.yarn.server.resourcemanager.ApplicationMasterService: AM registration appattempt_1580953164575_0001_000001
2020-02-06 01:43:54,637 INFO org.apache.hadoop.yarn.server.resourcemanager.RMAuditLogger: USER=hadoop	IP=172.28.1.15	OPERATION=Register App Master	TARGET=ApplicationMasterService	RESULT=SUCCESS	APPID=application_1580953164575_0001	APPATTEMPTID=appattempt_1580953164575_0001_000001
2020-02-06 01:43:54,637 INFO org.apache.hadoop.yarn.server.resourcemanager.rmapp.attempt.RMAppAttemptImpl: appattempt_1580953164575_0001_000001 State change from LAUNCHED to RUNNING
2020-02-06 01:43:54,637 INFO org.apache.hadoop.yarn.server.resourcemanager.rmapp.RMAppImpl: application_1580953164575_0001 State change from ACCEPTED to RUNNING on event=ATTEMPT_REGISTERED
2020-02-06 01:43:55,510 INFO org.apache.hadoop.yarn.server.resourcemanager.rmcontainer.RMContainerImpl: container_1580953164575_0001_01_000002 Container Transitioned from NEW to ALLOCATED
2020-02-06 01:43:55,510 INFO org.apache.hadoop.yarn.server.resourcemanager.RMAuditLogger: USER=hadoop	OPERATION=AM Allocated Container	TARGET=SchedulerApp	RESULT=SUCCESS	APPID=application_1580953164575_0001	CONTAINERID=container_1580953164575_0001_01_000002
2020-02-06 01:43:55,510 INFO org.apache.hadoop.yarn.server.resourcemanager.scheduler.SchedulerNode: Assigned container container_1580953164575_0001_01_000002 of capacity <memory:12288, vCores:1> on host nodemaster:8050, which has 2 containers, <memory:16384, vCores:2> used and <memory:16384, vCores:8> available after allocation
2020-02-06 01:43:55,510 INFO org.apache.hadoop.yarn.server.resourcemanager.scheduler.capacity.LeafQueue: assignedContainer application attempt=appattempt_1580953164575_0001_000001 container=Container: [ContainerId: container_1580953164575_0001_01_000002, NodeId: nodemaster:8050, NodeHttpAddress: nodemaster:8042, Resource: <memory:12288, vCores:1>, Priority: 1, Token: null, ] queue=default: capacity=1.0, absoluteCapacity=1.0, usedResources=<memory:4096, vCores:1>, usedCapacity=0.125, absoluteUsedCapacity=0.125, numApps=1, numContainers=1 clusterResource=<memory:32768, vCores:10> type=OFF_SWITCH requestedPartition=
2020-02-06 01:43:55,510 INFO org.apache.hadoop.yarn.server.resourcemanager.scheduler.capacity.ParentQueue: Re-sorting assigned queue: root.default stats: default: capacity=1.0, absoluteCapacity=1.0, usedResources=<memory:16384, vCores:2>, usedCapacity=0.5, absoluteUsedCapacity=0.5, numApps=1, numContainers=2
2020-02-06 01:43:55,510 INFO org.apache.hadoop.yarn.server.resourcemanager.scheduler.capacity.ParentQueue: assignedContainer queue=root usedCapacity=0.5 absoluteUsedCapacity=0.5 used=<memory:16384, vCores:2> cluster=<memory:32768, vCores:10>
2020-02-06 01:43:56,114 INFO org.apache.hadoop.yarn.server.resourcemanager.security.NMTokenSecretManagerInRM: Sending NMToken for nodeId : nodemaster:8050 for container : container_1580953164575_0001_01_000002
2020-02-06 01:43:56,115 INFO org.apache.hadoop.yarn.server.resourcemanager.rmcontainer.RMContainerImpl: container_1580953164575_0001_01_000002 Container Transitioned from ALLOCATED to ACQUIRED
2020-02-06 01:43:56,511 INFO org.apache.hadoop.yarn.server.resourcemanager.rmcontainer.RMContainerImpl: container_1580953164575_0001_01_000002 Container Transitioned from ACQUIRED to RUNNING
2020-02-06 01:43:56,512 INFO org.apache.hadoop.yarn.server.resourcemanager.rmcontainer.RMContainerImpl: container_1580953164575_0001_01_000003 Container Transitioned from NEW to ALLOCATED
2020-02-06 01:43:56,512 INFO org.apache.hadoop.yarn.server.resourcemanager.RMAuditLogger: USER=hadoop	OPERATION=AM Allocated Container	TARGET=SchedulerApp	RESULT=SUCCESS	APPID=application_1580953164575_0001	CONTAINERID=container_1580953164575_0001_01_000003
2020-02-06 01:43:56,512 INFO org.apache.hadoop.yarn.server.resourcemanager.scheduler.SchedulerNode: Assigned container container_1580953164575_0001_01_000003 of capacity <memory:12288, vCores:1> on host nodemaster:8050, which has 3 containers, <memory:28672, vCores:3> used and <memory:4096, vCores:7> available after allocation
2020-02-06 01:43:56,512 INFO org.apache.hadoop.yarn.server.resourcemanager.scheduler.capacity.LeafQueue: assignedContainer application attempt=appattempt_1580953164575_0001_000001 container=Container: [ContainerId: container_1580953164575_0001_01_000003, NodeId: nodemaster:8050, NodeHttpAddress: nodemaster:8042, Resource: <memory:12288, vCores:1>, Priority: 1, Token: null, ] queue=default: capacity=1.0, absoluteCapacity=1.0, usedResources=<memory:16384, vCores:2>, usedCapacity=0.5, absoluteUsedCapacity=0.5, numApps=1, numContainers=2 clusterResource=<memory:32768, vCores:10> type=OFF_SWITCH requestedPartition=
2020-02-06 01:43:56,512 INFO org.apache.hadoop.yarn.server.resourcemanager.scheduler.capacity.ParentQueue: Re-sorting assigned queue: root.default stats: default: capacity=1.0, absoluteCapacity=1.0, usedResources=<memory:28672, vCores:3>, usedCapacity=0.875, absoluteUsedCapacity=0.875, numApps=1, numContainers=3
2020-02-06 01:43:56,512 INFO org.apache.hadoop.yarn.server.resourcemanager.scheduler.capacity.ParentQueue: assignedContainer queue=root usedCapacity=0.875 absoluteUsedCapacity=0.875 used=<memory:28672, vCores:3> cluster=<memory:32768, vCores:10>
2020-02-06 01:43:57,725 INFO org.apache.hadoop.yarn.server.resourcemanager.rmcontainer.RMContainerImpl: container_1580953164575_0001_01_000003 Container Transitioned from ALLOCATED to ACQUIRED
2020-02-06 01:43:58,514 INFO org.apache.hadoop.yarn.server.resourcemanager.rmcontainer.RMContainerImpl: container_1580953164575_0001_01_000003 Container Transitioned from ACQUIRED to RUNNING
2020-02-06 01:44:00,736 INFO org.apache.hadoop.yarn.server.resourcemanager.scheduler.AppSchedulingInfo: checking for deactivate of application :application_1580953164575_0001
2020-02-06 01:44:01,398 INFO org.apache.hadoop.yarn.server.resourcemanager.rmapp.attempt.RMAppAttemptImpl: Updating application attempt appattempt_1580953164575_0001_000001 with final state: FINISHING, and exit status: -1000
2020-02-06 01:44:01,398 INFO org.apache.hadoop.yarn.server.resourcemanager.rmapp.attempt.RMAppAttemptImpl: appattempt_1580953164575_0001_000001 State change from RUNNING to FINAL_SAVING
2020-02-06 01:44:01,398 INFO org.apache.hadoop.yarn.server.resourcemanager.rmapp.RMAppImpl: Updating application application_1580953164575_0001 with final state: FINISHING
2020-02-06 01:44:01,399 INFO org.apache.hadoop.yarn.server.resourcemanager.rmapp.RMAppImpl: application_1580953164575_0001 State change from RUNNING to FINAL_SAVING on event=ATTEMPT_UNREGISTERED
2020-02-06 01:44:01,399 INFO org.apache.hadoop.yarn.server.resourcemanager.recovery.RMStateStore: Updating info for app: application_1580953164575_0001
2020-02-06 01:44:01,399 INFO org.apache.hadoop.yarn.server.resourcemanager.rmapp.attempt.RMAppAttemptImpl: appattempt_1580953164575_0001_000001 State change from FINAL_SAVING to FINISHING
2020-02-06 01:44:01,399 INFO org.apache.hadoop.yarn.server.resourcemanager.rmapp.RMAppImpl: application_1580953164575_0001 State change from FINAL_SAVING to FINISHING on event=APP_UPDATE_SAVED
2020-02-06 01:44:01,426 INFO org.apache.hadoop.yarn.server.resourcemanager.rmcontainer.RMContainerImpl: container_1580953164575_0001_01_000003 Container Transitioned from RUNNING to COMPLETED
2020-02-06 01:44:01,426 INFO org.apache.hadoop.yarn.server.resourcemanager.scheduler.common.fica.FiCaSchedulerApp: Completed container: container_1580953164575_0001_01_000003 in state: COMPLETED event:FINISHED
2020-02-06 01:44:01,426 INFO org.apache.hadoop.yarn.server.resourcemanager.RMAuditLogger: USER=hadoop	OPERATION=AM Released Container	TARGET=SchedulerApp	RESULT=SUCCESS	APPID=application_1580953164575_0001	CONTAINERID=container_1580953164575_0001_01_000003
2020-02-06 01:44:01,426 INFO org.apache.hadoop.yarn.server.resourcemanager.scheduler.SchedulerNode: Released container container_1580953164575_0001_01_000003 of capacity <memory:12288, vCores:1> on host nodemaster:8050, which currently has 2 containers, <memory:16384, vCores:2> used and <memory:16384, vCores:8> available, release resources=true
2020-02-06 01:44:01,426 INFO org.apache.hadoop.yarn.server.resourcemanager.scheduler.capacity.LeafQueue: default used=<memory:16384, vCores:2> numContainers=2 user=hadoop user-resources=<memory:16384, vCores:2>
2020-02-06 01:44:01,427 INFO org.apache.hadoop.yarn.server.resourcemanager.scheduler.capacity.LeafQueue: completedContainer container=Container: [ContainerId: container_1580953164575_0001_01_000003, NodeId: nodemaster:8050, NodeHttpAddress: nodemaster:8042, Resource: <memory:12288, vCores:1>, Priority: 1, Token: Token { kind: ContainerToken, service: 172.28.1.15:8050 }, ] queue=default: capacity=1.0, absoluteCapacity=1.0, usedResources=<memory:16384, vCores:2>, usedCapacity=0.5, absoluteUsedCapacity=0.5, numApps=1, numContainers=2 cluster=<memory:32768, vCores:10>
2020-02-06 01:44:01,427 INFO org.apache.hadoop.yarn.server.resourcemanager.scheduler.capacity.ParentQueue: completedContainer queue=root usedCapacity=0.5 absoluteUsedCapacity=0.5 used=<memory:16384, vCores:2> cluster=<memory:32768, vCores:10>
2020-02-06 01:44:01,427 INFO org.apache.hadoop.yarn.server.resourcemanager.scheduler.capacity.ParentQueue: Re-sorting completed queue: root.default stats: default: capacity=1.0, absoluteCapacity=1.0, usedResources=<memory:16384, vCores:2>, usedCapacity=0.5, absoluteUsedCapacity=0.5, numApps=1, numContainers=2
2020-02-06 01:44:01,427 INFO org.apache.hadoop.yarn.server.resourcemanager.scheduler.capacity.CapacityScheduler: Application attempt appattempt_1580953164575_0001_000001 released container container_1580953164575_0001_01_000003 on node: host: nodemaster:8050 #containers=2 available=<memory:16384, vCores:8> used=<memory:16384, vCores:2> with event: FINISHED
2020-02-06 01:44:01,427 INFO org.apache.hadoop.yarn.server.resourcemanager.rmcontainer.RMContainerImpl: container_1580953164575_0001_01_000002 Container Transitioned from RUNNING to COMPLETED
2020-02-06 01:44:01,427 INFO org.apache.hadoop.yarn.server.resourcemanager.scheduler.common.fica.FiCaSchedulerApp: Completed container: container_1580953164575_0001_01_000002 in state: COMPLETED event:FINISHED
2020-02-06 01:44:01,427 INFO org.apache.hadoop.yarn.server.resourcemanager.RMAuditLogger: USER=hadoop	OPERATION=AM Released Container	TARGET=SchedulerApp	RESULT=SUCCESS	APPID=application_1580953164575_0001	CONTAINERID=container_1580953164575_0001_01_000002
2020-02-06 01:44:01,427 INFO org.apache.hadoop.yarn.server.resourcemanager.scheduler.SchedulerNode: Released container container_1580953164575_0001_01_000002 of capacity <memory:12288, vCores:1> on host nodemaster:8050, which currently has 1 containers, <memory:4096, vCores:1> used and <memory:28672, vCores:9> available, release resources=true
2020-02-06 01:44:01,427 INFO org.apache.hadoop.yarn.server.resourcemanager.scheduler.capacity.LeafQueue: default used=<memory:4096, vCores:1> numContainers=1 user=hadoop user-resources=<memory:4096, vCores:1>
2020-02-06 01:44:01,427 INFO org.apache.hadoop.yarn.server.resourcemanager.scheduler.capacity.LeafQueue: completedContainer container=Container: [ContainerId: container_1580953164575_0001_01_000002, NodeId: nodemaster:8050, NodeHttpAddress: nodemaster:8042, Resource: <memory:12288, vCores:1>, Priority: 1, Token: Token { kind: ContainerToken, service: 172.28.1.15:8050 }, ] queue=default: capacity=1.0, absoluteCapacity=1.0, usedResources=<memory:4096, vCores:1>, usedCapacity=0.125, absoluteUsedCapacity=0.125, numApps=1, numContainers=1 cluster=<memory:32768, vCores:10>
2020-02-06 01:44:01,427 INFO org.apache.hadoop.yarn.server.resourcemanager.scheduler.capacity.ParentQueue: completedContainer queue=root usedCapacity=0.125 absoluteUsedCapacity=0.125 used=<memory:4096, vCores:1> cluster=<memory:32768, vCores:10>
2020-02-06 01:44:01,427 INFO org.apache.hadoop.yarn.server.resourcemanager.scheduler.capacity.ParentQueue: Re-sorting completed queue: root.default stats: default: capacity=1.0, absoluteCapacity=1.0, usedResources=<memory:4096, vCores:1>, usedCapacity=0.125, absoluteUsedCapacity=0.125, numApps=1, numContainers=1
2020-02-06 01:44:01,427 INFO org.apache.hadoop.yarn.server.resourcemanager.scheduler.capacity.CapacityScheduler: Application attempt appattempt_1580953164575_0001_000001 released container container_1580953164575_0001_01_000002 on node: host: nodemaster:8050 #containers=1 available=<memory:28672, vCores:9> used=<memory:4096, vCores:1> with event: FINISHED
2020-02-06 01:44:01,501 INFO org.apache.hadoop.yarn.server.resourcemanager.ApplicationMasterService: application_1580953164575_0001 unregistered successfully. 
2020-02-06 01:44:01,882 INFO org.apache.hadoop.yarn.server.resourcemanager.rmcontainer.RMContainerImpl: container_1580953164575_0001_01_000001 Container Transitioned from RUNNING to COMPLETED
2020-02-06 01:44:01,882 INFO org.apache.hadoop.yarn.server.resourcemanager.scheduler.common.fica.FiCaSchedulerApp: Completed container: container_1580953164575_0001_01_000001 in state: COMPLETED event:FINISHED
2020-02-06 01:44:01,882 INFO org.apache.hadoop.yarn.server.resourcemanager.ApplicationMasterService: Unregistering app attempt : appattempt_1580953164575_0001_000001
2020-02-06 01:44:01,882 INFO org.apache.hadoop.yarn.server.resourcemanager.RMAuditLogger: USER=hadoop	OPERATION=AM Released Container	TARGET=SchedulerApp	RESULT=SUCCESS	APPID=application_1580953164575_0001	CONTAINERID=container_1580953164575_0001_01_000001
2020-02-06 01:44:01,882 INFO org.apache.hadoop.yarn.server.resourcemanager.scheduler.SchedulerNode: Released container container_1580953164575_0001_01_000001 of capacity <memory:4096, vCores:1> on host nodemaster:8050, which currently has 0 containers, <memory:0, vCores:0> used and <memory:32768, vCores:10> available, release resources=true
2020-02-06 01:44:01,882 INFO org.apache.hadoop.yarn.server.resourcemanager.scheduler.capacity.LeafQueue: default used=<memory:0, vCores:0> numContainers=0 user=hadoop user-resources=<memory:0, vCores:0>
2020-02-06 01:44:01,882 INFO org.apache.hadoop.yarn.server.resourcemanager.scheduler.capacity.LeafQueue: completedContainer container=Container: [ContainerId: container_1580953164575_0001_01_000001, NodeId: nodemaster:8050, NodeHttpAddress: nodemaster:8042, Resource: <memory:4096, vCores:1>, Priority: 0, Token: Token { kind: ContainerToken, service: 172.28.1.15:8050 }, ] queue=default: capacity=1.0, absoluteCapacity=1.0, usedResources=<memory:0, vCores:0>, usedCapacity=0.0, absoluteUsedCapacity=0.0, numApps=1, numContainers=0 cluster=<memory:32768, vCores:10>
2020-02-06 01:44:01,882 INFO org.apache.hadoop.yarn.server.resourcemanager.scheduler.capacity.ParentQueue: completedContainer queue=root usedCapacity=0.0 absoluteUsedCapacity=0.0 used=<memory:0, vCores:0> cluster=<memory:32768, vCores:10>
2020-02-06 01:44:01,883 INFO org.apache.hadoop.yarn.server.resourcemanager.scheduler.capacity.ParentQueue: Re-sorting completed queue: root.default stats: default: capacity=1.0, absoluteCapacity=1.0, usedResources=<memory:0, vCores:0>, usedCapacity=0.0, absoluteUsedCapacity=0.0, numApps=1, numContainers=0
2020-02-06 01:44:01,883 INFO org.apache.hadoop.yarn.server.resourcemanager.scheduler.capacity.CapacityScheduler: Application attempt appattempt_1580953164575_0001_000001 released container container_1580953164575_0001_01_000001 on node: host: nodemaster:8050 #containers=0 available=<memory:32768, vCores:10> used=<memory:0, vCores:0> with event: FINISHED
2020-02-06 01:44:01,883 INFO org.apache.hadoop.yarn.server.resourcemanager.security.AMRMTokenSecretManager: Application finished, removing password for appattempt_1580953164575_0001_000001
2020-02-06 01:44:01,884 INFO org.apache.hadoop.yarn.server.resourcemanager.rmapp.attempt.RMAppAttemptImpl: appattempt_1580953164575_0001_000001 State change from FINISHING to FINISHED
2020-02-06 01:44:01,885 INFO org.apache.hadoop.yarn.server.resourcemanager.rmapp.RMAppImpl: application_1580953164575_0001 State change from FINISHING to FINISHED on event=ATTEMPT_FINISHED
2020-02-06 01:44:01,885 INFO org.apache.hadoop.yarn.server.resourcemanager.scheduler.capacity.CapacityScheduler: Application Attempt appattempt_1580953164575_0001_000001 is done. finalState=FINISHED
2020-02-06 01:44:01,886 INFO org.apache.hadoop.yarn.server.resourcemanager.scheduler.AppSchedulingInfo: Application application_1580953164575_0001 requests cleared
2020-02-06 01:44:01,886 INFO org.apache.hadoop.yarn.server.resourcemanager.scheduler.capacity.LeafQueue: Application removed - appId: application_1580953164575_0001 user: hadoop queue: default #user-pending-applications: 0 #user-active-applications: 0 #queue-pending-applications: 0 #queue-active-applications: 0
2020-02-06 01:44:01,886 INFO org.apache.hadoop.yarn.server.resourcemanager.amlauncher.AMLauncher: Cleaning master appattempt_1580953164575_0001_000001
2020-02-06 01:44:01,887 INFO org.apache.hadoop.yarn.server.resourcemanager.scheduler.capacity.ParentQueue: Application removed - appId: application_1580953164575_0001 user: hadoop leaf-queue of parent: root #applications: 0
2020-02-06 01:44:01,887 INFO org.apache.hadoop.yarn.server.resourcemanager.RMAuditLogger: USER=hadoop	OPERATION=Application Finished - Succeeded	TARGET=RMAppManager	RESULT=SUCCESS	APPID=application_1580953164575_0001
2020-02-06 01:44:01,889 INFO org.apache.hadoop.yarn.server.resourcemanager.RMAppManager$ApplicationSummary: appId=application_1580953164575_0001,name=gen,user=hadoop,queue=default,state=FINISHED,trackingUrl=http://nodemaster:8088/proxy/application_1580953164575_0001/,appMasterHost=172.28.1.15,startTime=1580953430768,finishTime=1580953441398,finalStatus=SUCCEEDED,memorySeconds=175594,vcoreSeconds=19,preemptedAMContainers=0,preemptedNonAMContainers=0,preemptedResources=<memory:0\, vCores:0>,applicationType=SPARK
2020-02-06 01:44:03,891 INFO org.apache.hadoop.yarn.server.resourcemanager.scheduler.capacity.CapacityScheduler: Null container completed...
2020-02-06 01:44:03,891 INFO org.apache.hadoop.yarn.server.resourcemanager.scheduler.capacity.CapacityScheduler: Null container completed...
2020-02-06 01:49:24,533 INFO org.apache.hadoop.yarn.server.resourcemanager.scheduler.AbstractYarnScheduler: Release request cache is cleaned up
2020-02-06 01:52:06,030 INFO org.apache.hadoop.yarn.server.resourcemanager.ClientRMService: Allocated new applicationId: 2
2020-02-06 01:52:09,008 WARN org.apache.hadoop.yarn.server.resourcemanager.rmapp.RMAppImpl: The specific max attempts: 0 for application: 2 is invalid, because it is out of the range [1, 2]. Use the global max attempts instead.
2020-02-06 01:52:09,008 INFO org.apache.hadoop.yarn.server.resourcemanager.ClientRMService: Application with id 2 submitted by user hadoop
2020-02-06 01:52:09,008 INFO org.apache.hadoop.yarn.server.resourcemanager.rmapp.RMAppImpl: Storing application with id application_1580953164575_0002
2020-02-06 01:52:09,008 INFO org.apache.hadoop.yarn.server.resourcemanager.RMAuditLogger: USER=hadoop	IP=172.28.1.15	OPERATION=Submit Application Request	TARGET=ClientRMService	RESULT=SUCCESS	APPID=application_1580953164575_0002
2020-02-06 01:52:09,008 INFO org.apache.hadoop.yarn.server.resourcemanager.rmapp.RMAppImpl: application_1580953164575_0002 State change from NEW to NEW_SAVING on event=START
2020-02-06 01:52:09,008 INFO org.apache.hadoop.yarn.server.resourcemanager.recovery.RMStateStore: Storing info for app: application_1580953164575_0002
2020-02-06 01:52:09,008 INFO org.apache.hadoop.yarn.server.resourcemanager.rmapp.RMAppImpl: application_1580953164575_0002 State change from NEW_SAVING to SUBMITTED on event=APP_NEW_SAVED
2020-02-06 01:52:09,008 INFO org.apache.hadoop.yarn.server.resourcemanager.scheduler.capacity.ParentQueue: Application added - appId: application_1580953164575_0002 user: hadoop leaf-queue of parent: root #applications: 1
2020-02-06 01:52:09,008 INFO org.apache.hadoop.yarn.server.resourcemanager.scheduler.capacity.CapacityScheduler: Accepted application application_1580953164575_0002 from user: hadoop, in queue: default
2020-02-06 01:52:09,009 INFO org.apache.hadoop.yarn.server.resourcemanager.rmapp.RMAppImpl: application_1580953164575_0002 State change from SUBMITTED to ACCEPTED on event=APP_ACCEPTED
2020-02-06 01:52:09,009 INFO org.apache.hadoop.yarn.server.resourcemanager.ApplicationMasterService: Registering app attempt : appattempt_1580953164575_0002_000001
2020-02-06 01:52:09,009 INFO org.apache.hadoop.yarn.server.resourcemanager.rmapp.attempt.RMAppAttemptImpl: appattempt_1580953164575_0002_000001 State change from NEW to SUBMITTED
2020-02-06 01:52:09,009 INFO org.apache.hadoop.yarn.server.resourcemanager.scheduler.capacity.LeafQueue: Application application_1580953164575_0002 from user: hadoop activated in queue: default
2020-02-06 01:52:09,009 INFO org.apache.hadoop.yarn.server.resourcemanager.scheduler.capacity.LeafQueue: Application added - appId: application_1580953164575_0002 user: org.apache.hadoop.yarn.server.resourcemanager.scheduler.capacity.LeafQueue$User@5f1ebefe, leaf-queue: default #user-pending-applications: 0 #user-active-applications: 1 #queue-pending-applications: 0 #queue-active-applications: 1
2020-02-06 01:52:09,009 INFO org.apache.hadoop.yarn.server.resourcemanager.scheduler.capacity.CapacityScheduler: Added Application Attempt appattempt_1580953164575_0002_000001 to scheduler from user hadoop in queue default
2020-02-06 01:52:09,009 INFO org.apache.hadoop.yarn.server.resourcemanager.rmapp.attempt.RMAppAttemptImpl: appattempt_1580953164575_0002_000001 State change from SUBMITTED to SCHEDULED
2020-02-06 01:52:09,755 INFO org.apache.hadoop.yarn.server.resourcemanager.rmcontainer.RMContainerImpl: container_1580953164575_0002_01_000001 Container Transitioned from NEW to ALLOCATED
2020-02-06 01:52:09,755 INFO org.apache.hadoop.yarn.server.resourcemanager.RMAuditLogger: USER=hadoop	OPERATION=AM Allocated Container	TARGET=SchedulerApp	RESULT=SUCCESS	APPID=application_1580953164575_0002	CONTAINERID=container_1580953164575_0002_01_000001
2020-02-06 01:52:09,755 INFO org.apache.hadoop.yarn.server.resourcemanager.scheduler.SchedulerNode: Assigned container container_1580953164575_0002_01_000001 of capacity <memory:4096, vCores:1> on host nodemaster:8050, which has 1 containers, <memory:4096, vCores:1> used and <memory:28672, vCores:9> available after allocation
2020-02-06 01:52:09,755 INFO org.apache.hadoop.yarn.server.resourcemanager.scheduler.capacity.LeafQueue: assignedContainer application attempt=appattempt_1580953164575_0002_000001 container=Container: [ContainerId: container_1580953164575_0002_01_000001, NodeId: nodemaster:8050, NodeHttpAddress: nodemaster:8042, Resource: <memory:4096, vCores:1>, Priority: 0, Token: null, ] queue=default: capacity=1.0, absoluteCapacity=1.0, usedResources=<memory:0, vCores:0>, usedCapacity=0.0, absoluteUsedCapacity=0.0, numApps=1, numContainers=0 clusterResource=<memory:32768, vCores:10> type=OFF_SWITCH requestedPartition=
2020-02-06 01:52:09,756 INFO org.apache.hadoop.yarn.server.resourcemanager.scheduler.capacity.ParentQueue: Re-sorting assigned queue: root.default stats: default: capacity=1.0, absoluteCapacity=1.0, usedResources=<memory:4096, vCores:1>, usedCapacity=0.125, absoluteUsedCapacity=0.125, numApps=1, numContainers=1
2020-02-06 01:52:09,756 INFO org.apache.hadoop.yarn.server.resourcemanager.scheduler.capacity.ParentQueue: assignedContainer queue=root usedCapacity=0.125 absoluteUsedCapacity=0.125 used=<memory:4096, vCores:1> cluster=<memory:32768, vCores:10>
2020-02-06 01:52:09,757 INFO org.apache.hadoop.yarn.server.resourcemanager.security.NMTokenSecretManagerInRM: Sending NMToken for nodeId : nodemaster:8050 for container : container_1580953164575_0002_01_000001
2020-02-06 01:52:09,758 INFO org.apache.hadoop.yarn.server.resourcemanager.rmcontainer.RMContainerImpl: container_1580953164575_0002_01_000001 Container Transitioned from ALLOCATED to ACQUIRED
2020-02-06 01:52:09,758 INFO org.apache.hadoop.yarn.server.resourcemanager.security.NMTokenSecretManagerInRM: Clear node set for appattempt_1580953164575_0002_000001
2020-02-06 01:52:09,758 INFO org.apache.hadoop.yarn.server.resourcemanager.rmapp.attempt.RMAppAttemptImpl: Storing attempt: AppId: application_1580953164575_0002 AttemptId: appattempt_1580953164575_0002_000001 MasterContainer: Container: [ContainerId: container_1580953164575_0002_01_000001, NodeId: nodemaster:8050, NodeHttpAddress: nodemaster:8042, Resource: <memory:4096, vCores:1>, Priority: 0, Token: Token { kind: ContainerToken, service: 172.28.1.15:8050 }, ]
2020-02-06 01:52:09,758 INFO org.apache.hadoop.yarn.server.resourcemanager.rmapp.attempt.RMAppAttemptImpl: appattempt_1580953164575_0002_000001 State change from SCHEDULED to ALLOCATED_SAVING
2020-02-06 01:52:09,758 INFO org.apache.hadoop.yarn.server.resourcemanager.rmapp.attempt.RMAppAttemptImpl: appattempt_1580953164575_0002_000001 State change from ALLOCATED_SAVING to ALLOCATED
2020-02-06 01:52:09,758 INFO org.apache.hadoop.yarn.server.resourcemanager.amlauncher.AMLauncher: Launching masterappattempt_1580953164575_0002_000001
2020-02-06 01:52:09,760 INFO org.apache.hadoop.yarn.server.resourcemanager.amlauncher.AMLauncher: Setting up container Container: [ContainerId: container_1580953164575_0002_01_000001, NodeId: nodemaster:8050, NodeHttpAddress: nodemaster:8042, Resource: <memory:4096, vCores:1>, Priority: 0, Token: Token { kind: ContainerToken, service: 172.28.1.15:8050 }, ] for AM appattempt_1580953164575_0002_000001
2020-02-06 01:52:09,760 INFO org.apache.hadoop.yarn.server.resourcemanager.amlauncher.AMLauncher: Command to launch container container_1580953164575_0002_01_000001 : {{JAVA_HOME}}/bin/java,-server,-Xmx512m,-Djava.io.tmpdir={{PWD}}/tmp,-Dspark.yarn.app.container.log.dir=<LOG_DIR>,org.apache.spark.deploy.yarn.ExecutorLauncher,--arg,'nodemaster:39353',--properties-file,{{PWD}}/__spark_conf__/__spark_conf__.properties,1>,<LOG_DIR>/stdout,2>,<LOG_DIR>/stderr
2020-02-06 01:52:09,760 INFO org.apache.hadoop.yarn.server.resourcemanager.security.AMRMTokenSecretManager: Create AMRMToken for ApplicationAttempt: appattempt_1580953164575_0002_000001
2020-02-06 01:52:09,760 INFO org.apache.hadoop.yarn.server.resourcemanager.security.AMRMTokenSecretManager: Creating password for appattempt_1580953164575_0002_000001
2020-02-06 01:52:09,767 INFO org.apache.hadoop.yarn.server.resourcemanager.amlauncher.AMLauncher: Done launching container Container: [ContainerId: container_1580953164575_0002_01_000001, NodeId: nodemaster:8050, NodeHttpAddress: nodemaster:8042, Resource: <memory:4096, vCores:1>, Priority: 0, Token: Token { kind: ContainerToken, service: 172.28.1.15:8050 }, ] for AM appattempt_1580953164575_0002_000001
2020-02-06 01:52:09,767 INFO org.apache.hadoop.yarn.server.resourcemanager.rmapp.attempt.RMAppAttemptImpl: appattempt_1580953164575_0002_000001 State change from ALLOCATED to LAUNCHED
2020-02-06 01:52:10,756 INFO org.apache.hadoop.yarn.server.resourcemanager.rmcontainer.RMContainerImpl: container_1580953164575_0002_01_000001 Container Transitioned from ACQUIRED to RUNNING
2020-02-06 01:52:12,181 INFO SecurityLogger.org.apache.hadoop.ipc.Server: Auth successful for appattempt_1580953164575_0002_000001 (auth:SIMPLE)
2020-02-06 01:52:12,183 INFO org.apache.hadoop.yarn.server.resourcemanager.ApplicationMasterService: AM registration appattempt_1580953164575_0002_000001
2020-02-06 01:52:12,183 INFO org.apache.hadoop.yarn.server.resourcemanager.RMAuditLogger: USER=hadoop	IP=172.28.1.15	OPERATION=Register App Master	TARGET=ApplicationMasterService	RESULT=SUCCESS	APPID=application_1580953164575_0002	APPATTEMPTID=appattempt_1580953164575_0002_000001
2020-02-06 01:52:12,183 INFO org.apache.hadoop.yarn.server.resourcemanager.rmapp.attempt.RMAppAttemptImpl: appattempt_1580953164575_0002_000001 State change from LAUNCHED to RUNNING
2020-02-06 01:52:12,183 INFO org.apache.hadoop.yarn.server.resourcemanager.rmapp.RMAppImpl: application_1580953164575_0002 State change from ACCEPTED to RUNNING on event=ATTEMPT_REGISTERED
2020-02-06 01:52:12,758 INFO org.apache.hadoop.yarn.server.resourcemanager.rmcontainer.RMContainerImpl: container_1580953164575_0002_01_000002 Container Transitioned from NEW to ALLOCATED
2020-02-06 01:52:12,758 INFO org.apache.hadoop.yarn.server.resourcemanager.RMAuditLogger: USER=hadoop	OPERATION=AM Allocated Container	TARGET=SchedulerApp	RESULT=SUCCESS	APPID=application_1580953164575_0002	CONTAINERID=container_1580953164575_0002_01_000002
2020-02-06 01:52:12,758 INFO org.apache.hadoop.yarn.server.resourcemanager.scheduler.SchedulerNode: Assigned container container_1580953164575_0002_01_000002 of capacity <memory:12288, vCores:1> on host nodemaster:8050, which has 2 containers, <memory:16384, vCores:2> used and <memory:16384, vCores:8> available after allocation
2020-02-06 01:52:12,758 INFO org.apache.hadoop.yarn.server.resourcemanager.scheduler.capacity.LeafQueue: assignedContainer application attempt=appattempt_1580953164575_0002_000001 container=Container: [ContainerId: container_1580953164575_0002_01_000002, NodeId: nodemaster:8050, NodeHttpAddress: nodemaster:8042, Resource: <memory:12288, vCores:1>, Priority: 1, Token: null, ] queue=default: capacity=1.0, absoluteCapacity=1.0, usedResources=<memory:4096, vCores:1>, usedCapacity=0.125, absoluteUsedCapacity=0.125, numApps=1, numContainers=1 clusterResource=<memory:32768, vCores:10> type=OFF_SWITCH requestedPartition=
2020-02-06 01:52:12,758 INFO org.apache.hadoop.yarn.server.resourcemanager.scheduler.capacity.ParentQueue: Re-sorting assigned queue: root.default stats: default: capacity=1.0, absoluteCapacity=1.0, usedResources=<memory:16384, vCores:2>, usedCapacity=0.5, absoluteUsedCapacity=0.5, numApps=1, numContainers=2
2020-02-06 01:52:12,758 INFO org.apache.hadoop.yarn.server.resourcemanager.scheduler.capacity.ParentQueue: assignedContainer queue=root usedCapacity=0.5 absoluteUsedCapacity=0.5 used=<memory:16384, vCores:2> cluster=<memory:32768, vCores:10>
2020-02-06 01:52:12,850 INFO org.apache.hadoop.yarn.server.resourcemanager.security.NMTokenSecretManagerInRM: Sending NMToken for nodeId : nodemaster:8050 for container : container_1580953164575_0002_01_000002
2020-02-06 01:52:12,850 INFO org.apache.hadoop.yarn.server.resourcemanager.rmcontainer.RMContainerImpl: container_1580953164575_0002_01_000002 Container Transitioned from ALLOCATED to ACQUIRED
2020-02-06 01:52:13,758 INFO org.apache.hadoop.yarn.server.resourcemanager.rmcontainer.RMContainerImpl: container_1580953164575_0002_01_000002 Container Transitioned from ACQUIRED to RUNNING
2020-02-06 01:52:13,759 INFO org.apache.hadoop.yarn.server.resourcemanager.rmcontainer.RMContainerImpl: container_1580953164575_0002_01_000003 Container Transitioned from NEW to ALLOCATED
2020-02-06 01:52:13,759 INFO org.apache.hadoop.yarn.server.resourcemanager.RMAuditLogger: USER=hadoop	OPERATION=AM Allocated Container	TARGET=SchedulerApp	RESULT=SUCCESS	APPID=application_1580953164575_0002	CONTAINERID=container_1580953164575_0002_01_000003
2020-02-06 01:52:13,759 INFO org.apache.hadoop.yarn.server.resourcemanager.scheduler.SchedulerNode: Assigned container container_1580953164575_0002_01_000003 of capacity <memory:12288, vCores:1> on host nodemaster:8050, which has 3 containers, <memory:28672, vCores:3> used and <memory:4096, vCores:7> available after allocation
2020-02-06 01:52:13,759 INFO org.apache.hadoop.yarn.server.resourcemanager.scheduler.capacity.LeafQueue: assignedContainer application attempt=appattempt_1580953164575_0002_000001 container=Container: [ContainerId: container_1580953164575_0002_01_000003, NodeId: nodemaster:8050, NodeHttpAddress: nodemaster:8042, Resource: <memory:12288, vCores:1>, Priority: 1, Token: null, ] queue=default: capacity=1.0, absoluteCapacity=1.0, usedResources=<memory:16384, vCores:2>, usedCapacity=0.5, absoluteUsedCapacity=0.5, numApps=1, numContainers=2 clusterResource=<memory:32768, vCores:10> type=OFF_SWITCH requestedPartition=
2020-02-06 01:52:13,759 INFO org.apache.hadoop.yarn.server.resourcemanager.scheduler.capacity.ParentQueue: Re-sorting assigned queue: root.default stats: default: capacity=1.0, absoluteCapacity=1.0, usedResources=<memory:28672, vCores:3>, usedCapacity=0.875, absoluteUsedCapacity=0.875, numApps=1, numContainers=3
2020-02-06 01:52:13,759 INFO org.apache.hadoop.yarn.server.resourcemanager.scheduler.capacity.ParentQueue: assignedContainer queue=root usedCapacity=0.875 absoluteUsedCapacity=0.875 used=<memory:28672, vCores:3> cluster=<memory:32768, vCores:10>
2020-02-06 01:52:15,261 INFO org.apache.hadoop.yarn.server.resourcemanager.rmcontainer.RMContainerImpl: container_1580953164575_0002_01_000003 Container Transitioned from ALLOCATED to ACQUIRED
2020-02-06 01:52:15,760 INFO org.apache.hadoop.yarn.server.resourcemanager.rmcontainer.RMContainerImpl: container_1580953164575_0002_01_000003 Container Transitioned from ACQUIRED to RUNNING
2020-02-06 01:52:18,249 INFO org.apache.hadoop.yarn.server.resourcemanager.scheduler.AppSchedulingInfo: checking for deactivate of application :application_1580953164575_0002
2020-02-06 01:52:18,279 INFO org.apache.hadoop.yarn.server.resourcemanager.rmapp.attempt.RMAppAttemptImpl: Updating application attempt appattempt_1580953164575_0002_000001 with final state: FINISHING, and exit status: -1000
2020-02-06 01:52:18,279 INFO org.apache.hadoop.yarn.server.resourcemanager.rmapp.attempt.RMAppAttemptImpl: appattempt_1580953164575_0002_000001 State change from RUNNING to FINAL_SAVING
2020-02-06 01:52:18,279 INFO org.apache.hadoop.yarn.server.resourcemanager.rmapp.RMAppImpl: Updating application application_1580953164575_0002 with final state: FINISHING
2020-02-06 01:52:18,279 INFO org.apache.hadoop.yarn.server.resourcemanager.rmapp.RMAppImpl: application_1580953164575_0002 State change from RUNNING to FINAL_SAVING on event=ATTEMPT_UNREGISTERED
2020-02-06 01:52:18,279 INFO org.apache.hadoop.yarn.server.resourcemanager.rmapp.attempt.RMAppAttemptImpl: appattempt_1580953164575_0002_000001 State change from FINAL_SAVING to FINISHING
2020-02-06 01:52:18,279 INFO org.apache.hadoop.yarn.server.resourcemanager.recovery.RMStateStore: Updating info for app: application_1580953164575_0002
2020-02-06 01:52:18,279 INFO org.apache.hadoop.yarn.server.resourcemanager.rmapp.RMAppImpl: application_1580953164575_0002 State change from FINAL_SAVING to FINISHING on event=APP_UPDATE_SAVED
2020-02-06 01:52:18,301 INFO org.apache.hadoop.yarn.server.resourcemanager.rmcontainer.RMContainerImpl: container_1580953164575_0002_01_000002 Container Transitioned from RUNNING to COMPLETED
2020-02-06 01:52:18,301 INFO org.apache.hadoop.yarn.server.resourcemanager.scheduler.common.fica.FiCaSchedulerApp: Completed container: container_1580953164575_0002_01_000002 in state: COMPLETED event:FINISHED
2020-02-06 01:52:18,301 INFO org.apache.hadoop.yarn.server.resourcemanager.RMAuditLogger: USER=hadoop	OPERATION=AM Released Container	TARGET=SchedulerApp	RESULT=SUCCESS	APPID=application_1580953164575_0002	CONTAINERID=container_1580953164575_0002_01_000002
2020-02-06 01:52:18,302 INFO org.apache.hadoop.yarn.server.resourcemanager.scheduler.SchedulerNode: Released container container_1580953164575_0002_01_000002 of capacity <memory:12288, vCores:1> on host nodemaster:8050, which currently has 2 containers, <memory:16384, vCores:2> used and <memory:16384, vCores:8> available, release resources=true
2020-02-06 01:52:18,302 INFO org.apache.hadoop.yarn.server.resourcemanager.scheduler.capacity.LeafQueue: default used=<memory:16384, vCores:2> numContainers=2 user=hadoop user-resources=<memory:16384, vCores:2>
2020-02-06 01:52:18,302 INFO org.apache.hadoop.yarn.server.resourcemanager.scheduler.capacity.LeafQueue: completedContainer container=Container: [ContainerId: container_1580953164575_0002_01_000002, NodeId: nodemaster:8050, NodeHttpAddress: nodemaster:8042, Resource: <memory:12288, vCores:1>, Priority: 1, Token: Token { kind: ContainerToken, service: 172.28.1.15:8050 }, ] queue=default: capacity=1.0, absoluteCapacity=1.0, usedResources=<memory:16384, vCores:2>, usedCapacity=0.5, absoluteUsedCapacity=0.5, numApps=1, numContainers=2 cluster=<memory:32768, vCores:10>
2020-02-06 01:52:18,302 INFO org.apache.hadoop.yarn.server.resourcemanager.scheduler.capacity.ParentQueue: completedContainer queue=root usedCapacity=0.5 absoluteUsedCapacity=0.5 used=<memory:16384, vCores:2> cluster=<memory:32768, vCores:10>
2020-02-06 01:52:18,302 INFO org.apache.hadoop.yarn.server.resourcemanager.scheduler.capacity.ParentQueue: Re-sorting completed queue: root.default stats: default: capacity=1.0, absoluteCapacity=1.0, usedResources=<memory:16384, vCores:2>, usedCapacity=0.5, absoluteUsedCapacity=0.5, numApps=1, numContainers=2
2020-02-06 01:52:18,302 INFO org.apache.hadoop.yarn.server.resourcemanager.scheduler.capacity.CapacityScheduler: Application attempt appattempt_1580953164575_0002_000001 released container container_1580953164575_0002_01_000002 on node: host: nodemaster:8050 #containers=2 available=<memory:16384, vCores:8> used=<memory:16384, vCores:2> with event: FINISHED
2020-02-06 01:52:18,381 INFO org.apache.hadoop.yarn.server.resourcemanager.ApplicationMasterService: application_1580953164575_0002 unregistered successfully. 
2020-02-06 01:52:18,645 INFO org.apache.hadoop.yarn.server.resourcemanager.rmcontainer.RMContainerImpl: container_1580953164575_0002_01_000003 Container Transitioned from RUNNING to COMPLETED
2020-02-06 01:52:18,645 INFO org.apache.hadoop.yarn.server.resourcemanager.scheduler.common.fica.FiCaSchedulerApp: Completed container: container_1580953164575_0002_01_000003 in state: COMPLETED event:FINISHED
2020-02-06 01:52:18,645 INFO org.apache.hadoop.yarn.server.resourcemanager.RMAuditLogger: USER=hadoop	OPERATION=AM Released Container	TARGET=SchedulerApp	RESULT=SUCCESS	APPID=application_1580953164575_0002	CONTAINERID=container_1580953164575_0002_01_000003
2020-02-06 01:52:18,645 INFO org.apache.hadoop.yarn.server.resourcemanager.scheduler.SchedulerNode: Released container container_1580953164575_0002_01_000003 of capacity <memory:12288, vCores:1> on host nodemaster:8050, which currently has 1 containers, <memory:4096, vCores:1> used and <memory:28672, vCores:9> available, release resources=true
2020-02-06 01:52:18,645 INFO org.apache.hadoop.yarn.server.resourcemanager.scheduler.capacity.LeafQueue: default used=<memory:4096, vCores:1> numContainers=1 user=hadoop user-resources=<memory:4096, vCores:1>
2020-02-06 01:52:18,646 INFO org.apache.hadoop.yarn.server.resourcemanager.scheduler.capacity.LeafQueue: completedContainer container=Container: [ContainerId: container_1580953164575_0002_01_000003, NodeId: nodemaster:8050, NodeHttpAddress: nodemaster:8042, Resource: <memory:12288, vCores:1>, Priority: 1, Token: Token { kind: ContainerToken, service: 172.28.1.15:8050 }, ] queue=default: capacity=1.0, absoluteCapacity=1.0, usedResources=<memory:4096, vCores:1>, usedCapacity=0.125, absoluteUsedCapacity=0.125, numApps=1, numContainers=1 cluster=<memory:32768, vCores:10>
2020-02-06 01:52:18,646 INFO org.apache.hadoop.yarn.server.resourcemanager.scheduler.capacity.ParentQueue: completedContainer queue=root usedCapacity=0.125 absoluteUsedCapacity=0.125 used=<memory:4096, vCores:1> cluster=<memory:32768, vCores:10>
2020-02-06 01:52:18,646 INFO org.apache.hadoop.yarn.server.resourcemanager.scheduler.capacity.ParentQueue: Re-sorting completed queue: root.default stats: default: capacity=1.0, absoluteCapacity=1.0, usedResources=<memory:4096, vCores:1>, usedCapacity=0.125, absoluteUsedCapacity=0.125, numApps=1, numContainers=1
2020-02-06 01:52:18,646 INFO org.apache.hadoop.yarn.server.resourcemanager.scheduler.capacity.CapacityScheduler: Application attempt appattempt_1580953164575_0002_000001 released container container_1580953164575_0002_01_000003 on node: host: nodemaster:8050 #containers=1 available=<memory:28672, vCores:9> used=<memory:4096, vCores:1> with event: FINISHED
2020-02-06 01:52:18,751 INFO org.apache.hadoop.yarn.server.resourcemanager.rmcontainer.RMContainerImpl: container_1580953164575_0002_01_000001 Container Transitioned from RUNNING to COMPLETED
2020-02-06 01:52:18,751 INFO org.apache.hadoop.yarn.server.resourcemanager.scheduler.common.fica.FiCaSchedulerApp: Completed container: container_1580953164575_0002_01_000001 in state: COMPLETED event:FINISHED
2020-02-06 01:52:18,751 INFO org.apache.hadoop.yarn.server.resourcemanager.ApplicationMasterService: Unregistering app attempt : appattempt_1580953164575_0002_000001
2020-02-06 01:52:18,751 INFO org.apache.hadoop.yarn.server.resourcemanager.RMAuditLogger: USER=hadoop	OPERATION=AM Released Container	TARGET=SchedulerApp	RESULT=SUCCESS	APPID=application_1580953164575_0002	CONTAINERID=container_1580953164575_0002_01_000001
2020-02-06 01:52:18,752 INFO org.apache.hadoop.yarn.server.resourcemanager.security.AMRMTokenSecretManager: Application finished, removing password for appattempt_1580953164575_0002_000001
2020-02-06 01:52:18,752 INFO org.apache.hadoop.yarn.server.resourcemanager.scheduler.SchedulerNode: Released container container_1580953164575_0002_01_000001 of capacity <memory:4096, vCores:1> on host nodemaster:8050, which currently has 0 containers, <memory:0, vCores:0> used and <memory:32768, vCores:10> available, release resources=true
2020-02-06 01:52:18,752 INFO org.apache.hadoop.yarn.server.resourcemanager.rmapp.attempt.RMAppAttemptImpl: appattempt_1580953164575_0002_000001 State change from FINISHING to FINISHED
2020-02-06 01:52:18,752 INFO org.apache.hadoop.yarn.server.resourcemanager.rmapp.RMAppImpl: application_1580953164575_0002 State change from FINISHING to FINISHED on event=ATTEMPT_FINISHED
2020-02-06 01:52:18,752 INFO org.apache.hadoop.yarn.server.resourcemanager.scheduler.capacity.LeafQueue: default used=<memory:0, vCores:0> numContainers=0 user=hadoop user-resources=<memory:0, vCores:0>
2020-02-06 01:52:18,752 INFO org.apache.hadoop.yarn.server.resourcemanager.RMAuditLogger: USER=hadoop	OPERATION=Application Finished - Succeeded	TARGET=RMAppManager	RESULT=SUCCESS	APPID=application_1580953164575_0002
2020-02-06 01:52:18,752 INFO org.apache.hadoop.yarn.server.resourcemanager.scheduler.capacity.LeafQueue: completedContainer container=Container: [ContainerId: container_1580953164575_0002_01_000001, NodeId: nodemaster:8050, NodeHttpAddress: nodemaster:8042, Resource: <memory:4096, vCores:1>, Priority: 0, Token: Token { kind: ContainerToken, service: 172.28.1.15:8050 }, ] queue=default: capacity=1.0, absoluteCapacity=1.0, usedResources=<memory:0, vCores:0>, usedCapacity=0.0, absoluteUsedCapacity=0.0, numApps=1, numContainers=0 cluster=<memory:32768, vCores:10>
2020-02-06 01:52:18,752 INFO org.apache.hadoop.yarn.server.resourcemanager.scheduler.capacity.ParentQueue: completedContainer queue=root usedCapacity=0.0 absoluteUsedCapacity=0.0 used=<memory:0, vCores:0> cluster=<memory:32768, vCores:10>
2020-02-06 01:52:18,752 INFO org.apache.hadoop.yarn.server.resourcemanager.scheduler.capacity.ParentQueue: Re-sorting completed queue: root.default stats: default: capacity=1.0, absoluteCapacity=1.0, usedResources=<memory:0, vCores:0>, usedCapacity=0.0, absoluteUsedCapacity=0.0, numApps=1, numContainers=0
2020-02-06 01:52:18,752 INFO org.apache.hadoop.yarn.server.resourcemanager.scheduler.capacity.CapacityScheduler: Application attempt appattempt_1580953164575_0002_000001 released container container_1580953164575_0002_01_000001 on node: host: nodemaster:8050 #containers=0 available=<memory:32768, vCores:10> used=<memory:0, vCores:0> with event: FINISHED
2020-02-06 01:52:18,752 INFO org.apache.hadoop.yarn.server.resourcemanager.scheduler.capacity.CapacityScheduler: Application Attempt appattempt_1580953164575_0002_000001 is done. finalState=FINISHED
2020-02-06 01:52:18,752 INFO org.apache.hadoop.yarn.server.resourcemanager.RMAppManager$ApplicationSummary: appId=application_1580953164575_0002,name=gen,user=hadoop,queue=default,state=FINISHED,trackingUrl=http://nodemaster:8088/proxy/application_1580953164575_0002/,appMasterHost=172.28.1.15,startTime=1580953929008,finishTime=1580953938279,finalStatus=SUCCEEDED,memorySeconds=165022,vcoreSeconds=17,preemptedAMContainers=0,preemptedNonAMContainers=0,preemptedResources=<memory:0\, vCores:0>,applicationType=SPARK
2020-02-06 01:52:18,753 INFO org.apache.hadoop.yarn.server.resourcemanager.scheduler.AppSchedulingInfo: Application application_1580953164575_0002 requests cleared
2020-02-06 01:52:18,753 INFO org.apache.hadoop.yarn.server.resourcemanager.amlauncher.AMLauncher: Cleaning master appattempt_1580953164575_0002_000001
2020-02-06 01:52:18,753 INFO org.apache.hadoop.yarn.server.resourcemanager.scheduler.capacity.LeafQueue: Application removed - appId: application_1580953164575_0002 user: hadoop queue: default #user-pending-applications: 0 #user-active-applications: 0 #queue-pending-applications: 0 #queue-active-applications: 0
2020-02-06 01:52:18,753 INFO org.apache.hadoop.yarn.server.resourcemanager.scheduler.capacity.ParentQueue: Application removed - appId: application_1580953164575_0002 user: hadoop leaf-queue of parent: root #applications: 0
2020-02-06 01:52:20,756 INFO org.apache.hadoop.yarn.server.resourcemanager.scheduler.capacity.CapacityScheduler: Null container completed...
2020-02-06 01:52:20,757 INFO org.apache.hadoop.yarn.server.resourcemanager.scheduler.capacity.CapacityScheduler: Null container completed...
2020-02-06 01:53:55,101 INFO org.apache.hadoop.yarn.server.resourcemanager.ClientRMService: Allocated new applicationId: 3
2020-02-06 01:53:58,075 WARN org.apache.hadoop.yarn.server.resourcemanager.rmapp.RMAppImpl: The specific max attempts: 0 for application: 3 is invalid, because it is out of the range [1, 2]. Use the global max attempts instead.
2020-02-06 01:53:58,075 INFO org.apache.hadoop.yarn.server.resourcemanager.ClientRMService: Application with id 3 submitted by user hadoop
2020-02-06 01:53:58,075 INFO org.apache.hadoop.yarn.server.resourcemanager.rmapp.RMAppImpl: Storing application with id application_1580953164575_0003
2020-02-06 01:53:58,075 INFO org.apache.hadoop.yarn.server.resourcemanager.RMAuditLogger: USER=hadoop	IP=172.28.1.15	OPERATION=Submit Application Request	TARGET=ClientRMService	RESULT=SUCCESS	APPID=application_1580953164575_0003
2020-02-06 01:53:58,075 INFO org.apache.hadoop.yarn.server.resourcemanager.rmapp.RMAppImpl: application_1580953164575_0003 State change from NEW to NEW_SAVING on event=START
2020-02-06 01:53:58,075 INFO org.apache.hadoop.yarn.server.resourcemanager.recovery.RMStateStore: Storing info for app: application_1580953164575_0003
2020-02-06 01:53:58,075 INFO org.apache.hadoop.yarn.server.resourcemanager.rmapp.RMAppImpl: application_1580953164575_0003 State change from NEW_SAVING to SUBMITTED on event=APP_NEW_SAVED
2020-02-06 01:53:58,075 INFO org.apache.hadoop.yarn.server.resourcemanager.scheduler.capacity.ParentQueue: Application added - appId: application_1580953164575_0003 user: hadoop leaf-queue of parent: root #applications: 1
2020-02-06 01:53:58,075 INFO org.apache.hadoop.yarn.server.resourcemanager.scheduler.capacity.CapacityScheduler: Accepted application application_1580953164575_0003 from user: hadoop, in queue: default
2020-02-06 01:53:58,075 INFO org.apache.hadoop.yarn.server.resourcemanager.rmapp.RMAppImpl: application_1580953164575_0003 State change from SUBMITTED to ACCEPTED on event=APP_ACCEPTED
2020-02-06 01:53:58,075 INFO org.apache.hadoop.yarn.server.resourcemanager.ApplicationMasterService: Registering app attempt : appattempt_1580953164575_0003_000001
2020-02-06 01:53:58,075 INFO org.apache.hadoop.yarn.server.resourcemanager.rmapp.attempt.RMAppAttemptImpl: appattempt_1580953164575_0003_000001 State change from NEW to SUBMITTED
2020-02-06 01:53:58,075 INFO org.apache.hadoop.yarn.server.resourcemanager.scheduler.capacity.LeafQueue: Application application_1580953164575_0003 from user: hadoop activated in queue: default
2020-02-06 01:53:58,075 INFO org.apache.hadoop.yarn.server.resourcemanager.scheduler.capacity.LeafQueue: Application added - appId: application_1580953164575_0003 user: org.apache.hadoop.yarn.server.resourcemanager.scheduler.capacity.LeafQueue$User@6b019631, leaf-queue: default #user-pending-applications: 0 #user-active-applications: 1 #queue-pending-applications: 0 #queue-active-applications: 1
2020-02-06 01:53:58,075 INFO org.apache.hadoop.yarn.server.resourcemanager.scheduler.capacity.CapacityScheduler: Added Application Attempt appattempt_1580953164575_0003_000001 to scheduler from user hadoop in queue default
2020-02-06 01:53:58,076 INFO org.apache.hadoop.yarn.server.resourcemanager.rmapp.attempt.RMAppAttemptImpl: appattempt_1580953164575_0003_000001 State change from SUBMITTED to SCHEDULED
2020-02-06 01:53:58,904 INFO org.apache.hadoop.yarn.server.resourcemanager.rmcontainer.RMContainerImpl: container_1580953164575_0003_01_000001 Container Transitioned from NEW to ALLOCATED
2020-02-06 01:53:58,904 INFO org.apache.hadoop.yarn.server.resourcemanager.RMAuditLogger: USER=hadoop	OPERATION=AM Allocated Container	TARGET=SchedulerApp	RESULT=SUCCESS	APPID=application_1580953164575_0003	CONTAINERID=container_1580953164575_0003_01_000001
2020-02-06 01:53:58,904 INFO org.apache.hadoop.yarn.server.resourcemanager.scheduler.SchedulerNode: Assigned container container_1580953164575_0003_01_000001 of capacity <memory:4096, vCores:1> on host nodemaster:8050, which has 1 containers, <memory:4096, vCores:1> used and <memory:28672, vCores:9> available after allocation
2020-02-06 01:53:58,904 INFO org.apache.hadoop.yarn.server.resourcemanager.scheduler.capacity.LeafQueue: assignedContainer application attempt=appattempt_1580953164575_0003_000001 container=Container: [ContainerId: container_1580953164575_0003_01_000001, NodeId: nodemaster:8050, NodeHttpAddress: nodemaster:8042, Resource: <memory:4096, vCores:1>, Priority: 0, Token: null, ] queue=default: capacity=1.0, absoluteCapacity=1.0, usedResources=<memory:0, vCores:0>, usedCapacity=0.0, absoluteUsedCapacity=0.0, numApps=1, numContainers=0 clusterResource=<memory:32768, vCores:10> type=OFF_SWITCH requestedPartition=
2020-02-06 01:53:58,904 INFO org.apache.hadoop.yarn.server.resourcemanager.scheduler.capacity.ParentQueue: Re-sorting assigned queue: root.default stats: default: capacity=1.0, absoluteCapacity=1.0, usedResources=<memory:4096, vCores:1>, usedCapacity=0.125, absoluteUsedCapacity=0.125, numApps=1, numContainers=1
2020-02-06 01:53:58,904 INFO org.apache.hadoop.yarn.server.resourcemanager.scheduler.capacity.ParentQueue: assignedContainer queue=root usedCapacity=0.125 absoluteUsedCapacity=0.125 used=<memory:4096, vCores:1> cluster=<memory:32768, vCores:10>
2020-02-06 01:53:58,904 INFO org.apache.hadoop.yarn.server.resourcemanager.security.NMTokenSecretManagerInRM: Sending NMToken for nodeId : nodemaster:8050 for container : container_1580953164575_0003_01_000001
2020-02-06 01:53:58,906 INFO org.apache.hadoop.yarn.server.resourcemanager.rmcontainer.RMContainerImpl: container_1580953164575_0003_01_000001 Container Transitioned from ALLOCATED to ACQUIRED
2020-02-06 01:53:58,906 INFO org.apache.hadoop.yarn.server.resourcemanager.security.NMTokenSecretManagerInRM: Clear node set for appattempt_1580953164575_0003_000001
2020-02-06 01:53:58,906 INFO org.apache.hadoop.yarn.server.resourcemanager.rmapp.attempt.RMAppAttemptImpl: Storing attempt: AppId: application_1580953164575_0003 AttemptId: appattempt_1580953164575_0003_000001 MasterContainer: Container: [ContainerId: container_1580953164575_0003_01_000001, NodeId: nodemaster:8050, NodeHttpAddress: nodemaster:8042, Resource: <memory:4096, vCores:1>, Priority: 0, Token: Token { kind: ContainerToken, service: 172.28.1.15:8050 }, ]
2020-02-06 01:53:58,906 INFO org.apache.hadoop.yarn.server.resourcemanager.rmapp.attempt.RMAppAttemptImpl: appattempt_1580953164575_0003_000001 State change from SCHEDULED to ALLOCATED_SAVING
2020-02-06 01:53:58,906 INFO org.apache.hadoop.yarn.server.resourcemanager.rmapp.attempt.RMAppAttemptImpl: appattempt_1580953164575_0003_000001 State change from ALLOCATED_SAVING to ALLOCATED
2020-02-06 01:53:58,906 INFO org.apache.hadoop.yarn.server.resourcemanager.amlauncher.AMLauncher: Launching masterappattempt_1580953164575_0003_000001
2020-02-06 01:53:58,907 INFO org.apache.hadoop.yarn.server.resourcemanager.amlauncher.AMLauncher: Setting up container Container: [ContainerId: container_1580953164575_0003_01_000001, NodeId: nodemaster:8050, NodeHttpAddress: nodemaster:8042, Resource: <memory:4096, vCores:1>, Priority: 0, Token: Token { kind: ContainerToken, service: 172.28.1.15:8050 }, ] for AM appattempt_1580953164575_0003_000001
2020-02-06 01:53:58,907 INFO org.apache.hadoop.yarn.server.resourcemanager.amlauncher.AMLauncher: Command to launch container container_1580953164575_0003_01_000001 : {{JAVA_HOME}}/bin/java,-server,-Xmx512m,-Djava.io.tmpdir={{PWD}}/tmp,-Dspark.yarn.app.container.log.dir=<LOG_DIR>,org.apache.spark.deploy.yarn.ExecutorLauncher,--arg,'nodemaster:36839',--properties-file,{{PWD}}/__spark_conf__/__spark_conf__.properties,1>,<LOG_DIR>/stdout,2>,<LOG_DIR>/stderr
2020-02-06 01:53:58,907 INFO org.apache.hadoop.yarn.server.resourcemanager.security.AMRMTokenSecretManager: Create AMRMToken for ApplicationAttempt: appattempt_1580953164575_0003_000001
2020-02-06 01:53:58,908 INFO org.apache.hadoop.yarn.server.resourcemanager.security.AMRMTokenSecretManager: Creating password for appattempt_1580953164575_0003_000001
2020-02-06 01:53:58,915 INFO org.apache.hadoop.yarn.server.resourcemanager.amlauncher.AMLauncher: Done launching container Container: [ContainerId: container_1580953164575_0003_01_000001, NodeId: nodemaster:8050, NodeHttpAddress: nodemaster:8042, Resource: <memory:4096, vCores:1>, Priority: 0, Token: Token { kind: ContainerToken, service: 172.28.1.15:8050 }, ] for AM appattempt_1580953164575_0003_000001
2020-02-06 01:53:58,916 INFO org.apache.hadoop.yarn.server.resourcemanager.rmapp.attempt.RMAppAttemptImpl: appattempt_1580953164575_0003_000001 State change from ALLOCATED to LAUNCHED
2020-02-06 01:53:59,904 INFO org.apache.hadoop.yarn.server.resourcemanager.rmcontainer.RMContainerImpl: container_1580953164575_0003_01_000001 Container Transitioned from ACQUIRED to RUNNING
2020-02-06 01:54:01,311 INFO SecurityLogger.org.apache.hadoop.ipc.Server: Auth successful for appattempt_1580953164575_0003_000001 (auth:SIMPLE)
2020-02-06 01:54:01,313 INFO org.apache.hadoop.yarn.server.resourcemanager.ApplicationMasterService: AM registration appattempt_1580953164575_0003_000001
2020-02-06 01:54:01,313 INFO org.apache.hadoop.yarn.server.resourcemanager.RMAuditLogger: USER=hadoop	IP=172.28.1.15	OPERATION=Register App Master	TARGET=ApplicationMasterService	RESULT=SUCCESS	APPID=application_1580953164575_0003	APPATTEMPTID=appattempt_1580953164575_0003_000001
2020-02-06 01:54:01,313 INFO org.apache.hadoop.yarn.server.resourcemanager.rmapp.attempt.RMAppAttemptImpl: appattempt_1580953164575_0003_000001 State change from LAUNCHED to RUNNING
2020-02-06 01:54:01,313 INFO org.apache.hadoop.yarn.server.resourcemanager.rmapp.RMAppImpl: application_1580953164575_0003 State change from ACCEPTED to RUNNING on event=ATTEMPT_REGISTERED
2020-02-06 01:54:01,906 INFO org.apache.hadoop.yarn.server.resourcemanager.rmcontainer.RMContainerImpl: container_1580953164575_0003_01_000002 Container Transitioned from NEW to ALLOCATED
2020-02-06 01:54:01,906 INFO org.apache.hadoop.yarn.server.resourcemanager.RMAuditLogger: USER=hadoop	OPERATION=AM Allocated Container	TARGET=SchedulerApp	RESULT=SUCCESS	APPID=application_1580953164575_0003	CONTAINERID=container_1580953164575_0003_01_000002
2020-02-06 01:54:01,906 INFO org.apache.hadoop.yarn.server.resourcemanager.scheduler.SchedulerNode: Assigned container container_1580953164575_0003_01_000002 of capacity <memory:12288, vCores:1> on host nodemaster:8050, which has 2 containers, <memory:16384, vCores:2> used and <memory:16384, vCores:8> available after allocation
2020-02-06 01:54:01,906 INFO org.apache.hadoop.yarn.server.resourcemanager.scheduler.capacity.LeafQueue: assignedContainer application attempt=appattempt_1580953164575_0003_000001 container=Container: [ContainerId: container_1580953164575_0003_01_000002, NodeId: nodemaster:8050, NodeHttpAddress: nodemaster:8042, Resource: <memory:12288, vCores:1>, Priority: 1, Token: null, ] queue=default: capacity=1.0, absoluteCapacity=1.0, usedResources=<memory:4096, vCores:1>, usedCapacity=0.125, absoluteUsedCapacity=0.125, numApps=1, numContainers=1 clusterResource=<memory:32768, vCores:10> type=OFF_SWITCH requestedPartition=
2020-02-06 01:54:01,906 INFO org.apache.hadoop.yarn.server.resourcemanager.scheduler.capacity.ParentQueue: Re-sorting assigned queue: root.default stats: default: capacity=1.0, absoluteCapacity=1.0, usedResources=<memory:16384, vCores:2>, usedCapacity=0.5, absoluteUsedCapacity=0.5, numApps=1, numContainers=2
2020-02-06 01:54:01,906 INFO org.apache.hadoop.yarn.server.resourcemanager.scheduler.capacity.ParentQueue: assignedContainer queue=root usedCapacity=0.5 absoluteUsedCapacity=0.5 used=<memory:16384, vCores:2> cluster=<memory:32768, vCores:10>
2020-02-06 01:54:01,984 INFO org.apache.hadoop.yarn.server.resourcemanager.security.NMTokenSecretManagerInRM: Sending NMToken for nodeId : nodemaster:8050 for container : container_1580953164575_0003_01_000002
2020-02-06 01:54:01,984 INFO org.apache.hadoop.yarn.server.resourcemanager.rmcontainer.RMContainerImpl: container_1580953164575_0003_01_000002 Container Transitioned from ALLOCATED to ACQUIRED
2020-02-06 01:54:02,906 INFO org.apache.hadoop.yarn.server.resourcemanager.rmcontainer.RMContainerImpl: container_1580953164575_0003_01_000002 Container Transitioned from ACQUIRED to RUNNING
2020-02-06 01:54:02,907 INFO org.apache.hadoop.yarn.server.resourcemanager.rmcontainer.RMContainerImpl: container_1580953164575_0003_01_000003 Container Transitioned from NEW to ALLOCATED
2020-02-06 01:54:02,907 INFO org.apache.hadoop.yarn.server.resourcemanager.RMAuditLogger: USER=hadoop	OPERATION=AM Allocated Container	TARGET=SchedulerApp	RESULT=SUCCESS	APPID=application_1580953164575_0003	CONTAINERID=container_1580953164575_0003_01_000003
2020-02-06 01:54:02,907 INFO org.apache.hadoop.yarn.server.resourcemanager.scheduler.SchedulerNode: Assigned container container_1580953164575_0003_01_000003 of capacity <memory:12288, vCores:1> on host nodemaster:8050, which has 3 containers, <memory:28672, vCores:3> used and <memory:4096, vCores:7> available after allocation
2020-02-06 01:54:02,907 INFO org.apache.hadoop.yarn.server.resourcemanager.scheduler.capacity.LeafQueue: assignedContainer application attempt=appattempt_1580953164575_0003_000001 container=Container: [ContainerId: container_1580953164575_0003_01_000003, NodeId: nodemaster:8050, NodeHttpAddress: nodemaster:8042, Resource: <memory:12288, vCores:1>, Priority: 1, Token: null, ] queue=default: capacity=1.0, absoluteCapacity=1.0, usedResources=<memory:16384, vCores:2>, usedCapacity=0.5, absoluteUsedCapacity=0.5, numApps=1, numContainers=2 clusterResource=<memory:32768, vCores:10> type=OFF_SWITCH requestedPartition=
2020-02-06 01:54:02,907 INFO org.apache.hadoop.yarn.server.resourcemanager.scheduler.capacity.ParentQueue: Re-sorting assigned queue: root.default stats: default: capacity=1.0, absoluteCapacity=1.0, usedResources=<memory:28672, vCores:3>, usedCapacity=0.875, absoluteUsedCapacity=0.875, numApps=1, numContainers=3
2020-02-06 01:54:02,907 INFO org.apache.hadoop.yarn.server.resourcemanager.scheduler.capacity.ParentQueue: assignedContainer queue=root usedCapacity=0.875 absoluteUsedCapacity=0.875 used=<memory:28672, vCores:3> cluster=<memory:32768, vCores:10>
2020-02-06 01:54:04,395 INFO org.apache.hadoop.yarn.server.resourcemanager.rmcontainer.RMContainerImpl: container_1580953164575_0003_01_000003 Container Transitioned from ALLOCATED to ACQUIRED
2020-02-06 01:54:04,908 INFO org.apache.hadoop.yarn.server.resourcemanager.rmcontainer.RMContainerImpl: container_1580953164575_0003_01_000003 Container Transitioned from ACQUIRED to RUNNING
2020-02-06 01:54:07,383 INFO org.apache.hadoop.yarn.server.resourcemanager.scheduler.AppSchedulingInfo: checking for deactivate of application :application_1580953164575_0003
2020-02-06 01:54:07,431 INFO org.apache.hadoop.yarn.server.resourcemanager.rmapp.attempt.RMAppAttemptImpl: Updating application attempt appattempt_1580953164575_0003_000001 with final state: FINISHING, and exit status: -1000
2020-02-06 01:54:07,431 INFO org.apache.hadoop.yarn.server.resourcemanager.rmapp.attempt.RMAppAttemptImpl: appattempt_1580953164575_0003_000001 State change from RUNNING to FINAL_SAVING
2020-02-06 01:54:07,431 INFO org.apache.hadoop.yarn.server.resourcemanager.rmapp.RMAppImpl: Updating application application_1580953164575_0003 with final state: FINISHING
2020-02-06 01:54:07,431 INFO org.apache.hadoop.yarn.server.resourcemanager.rmapp.RMAppImpl: application_1580953164575_0003 State change from RUNNING to FINAL_SAVING on event=ATTEMPT_UNREGISTERED
2020-02-06 01:54:07,431 INFO org.apache.hadoop.yarn.server.resourcemanager.recovery.RMStateStore: Updating info for app: application_1580953164575_0003
2020-02-06 01:54:07,431 INFO org.apache.hadoop.yarn.server.resourcemanager.rmapp.attempt.RMAppAttemptImpl: appattempt_1580953164575_0003_000001 State change from FINAL_SAVING to FINISHING
2020-02-06 01:54:07,431 INFO org.apache.hadoop.yarn.server.resourcemanager.rmapp.RMAppImpl: application_1580953164575_0003 State change from FINAL_SAVING to FINISHING on event=APP_UPDATE_SAVED
2020-02-06 01:54:07,449 INFO org.apache.hadoop.yarn.server.resourcemanager.rmcontainer.RMContainerImpl: container_1580953164575_0003_01_000002 Container Transitioned from RUNNING to COMPLETED
2020-02-06 01:54:07,449 INFO org.apache.hadoop.yarn.server.resourcemanager.scheduler.common.fica.FiCaSchedulerApp: Completed container: container_1580953164575_0003_01_000002 in state: COMPLETED event:FINISHED
2020-02-06 01:54:07,449 INFO org.apache.hadoop.yarn.server.resourcemanager.RMAuditLogger: USER=hadoop	OPERATION=AM Released Container	TARGET=SchedulerApp	RESULT=SUCCESS	APPID=application_1580953164575_0003	CONTAINERID=container_1580953164575_0003_01_000002
2020-02-06 01:54:07,449 INFO org.apache.hadoop.yarn.server.resourcemanager.scheduler.SchedulerNode: Released container container_1580953164575_0003_01_000002 of capacity <memory:12288, vCores:1> on host nodemaster:8050, which currently has 2 containers, <memory:16384, vCores:2> used and <memory:16384, vCores:8> available, release resources=true
2020-02-06 01:54:07,449 INFO org.apache.hadoop.yarn.server.resourcemanager.scheduler.capacity.LeafQueue: default used=<memory:16384, vCores:2> numContainers=2 user=hadoop user-resources=<memory:16384, vCores:2>
2020-02-06 01:54:07,449 INFO org.apache.hadoop.yarn.server.resourcemanager.scheduler.capacity.LeafQueue: completedContainer container=Container: [ContainerId: container_1580953164575_0003_01_000002, NodeId: nodemaster:8050, NodeHttpAddress: nodemaster:8042, Resource: <memory:12288, vCores:1>, Priority: 1, Token: Token { kind: ContainerToken, service: 172.28.1.15:8050 }, ] queue=default: capacity=1.0, absoluteCapacity=1.0, usedResources=<memory:16384, vCores:2>, usedCapacity=0.5, absoluteUsedCapacity=0.5, numApps=1, numContainers=2 cluster=<memory:32768, vCores:10>
2020-02-06 01:54:07,449 INFO org.apache.hadoop.yarn.server.resourcemanager.scheduler.capacity.ParentQueue: completedContainer queue=root usedCapacity=0.5 absoluteUsedCapacity=0.5 used=<memory:16384, vCores:2> cluster=<memory:32768, vCores:10>
2020-02-06 01:54:07,449 INFO org.apache.hadoop.yarn.server.resourcemanager.scheduler.capacity.ParentQueue: Re-sorting completed queue: root.default stats: default: capacity=1.0, absoluteCapacity=1.0, usedResources=<memory:16384, vCores:2>, usedCapacity=0.5, absoluteUsedCapacity=0.5, numApps=1, numContainers=2
2020-02-06 01:54:07,449 INFO org.apache.hadoop.yarn.server.resourcemanager.scheduler.capacity.CapacityScheduler: Application attempt appattempt_1580953164575_0003_000001 released container container_1580953164575_0003_01_000002 on node: host: nodemaster:8050 #containers=2 available=<memory:16384, vCores:8> used=<memory:16384, vCores:2> with event: FINISHED
2020-02-06 01:54:07,534 INFO org.apache.hadoop.yarn.server.resourcemanager.ApplicationMasterService: application_1580953164575_0003 unregistered successfully. 
2020-02-06 01:54:07,763 INFO org.apache.hadoop.yarn.server.resourcemanager.rmcontainer.RMContainerImpl: container_1580953164575_0003_01_000003 Container Transitioned from RUNNING to COMPLETED
2020-02-06 01:54:07,763 INFO org.apache.hadoop.yarn.server.resourcemanager.scheduler.common.fica.FiCaSchedulerApp: Completed container: container_1580953164575_0003_01_000003 in state: COMPLETED event:FINISHED
2020-02-06 01:54:07,763 INFO org.apache.hadoop.yarn.server.resourcemanager.RMAuditLogger: USER=hadoop	OPERATION=AM Released Container	TARGET=SchedulerApp	RESULT=SUCCESS	APPID=application_1580953164575_0003	CONTAINERID=container_1580953164575_0003_01_000003
2020-02-06 01:54:07,763 INFO org.apache.hadoop.yarn.server.resourcemanager.scheduler.SchedulerNode: Released container container_1580953164575_0003_01_000003 of capacity <memory:12288, vCores:1> on host nodemaster:8050, which currently has 1 containers, <memory:4096, vCores:1> used and <memory:28672, vCores:9> available, release resources=true
2020-02-06 01:54:07,763 INFO org.apache.hadoop.yarn.server.resourcemanager.scheduler.capacity.LeafQueue: default used=<memory:4096, vCores:1> numContainers=1 user=hadoop user-resources=<memory:4096, vCores:1>
2020-02-06 01:54:07,764 INFO org.apache.hadoop.yarn.server.resourcemanager.scheduler.capacity.LeafQueue: completedContainer container=Container: [ContainerId: container_1580953164575_0003_01_000003, NodeId: nodemaster:8050, NodeHttpAddress: nodemaster:8042, Resource: <memory:12288, vCores:1>, Priority: 1, Token: Token { kind: ContainerToken, service: 172.28.1.15:8050 }, ] queue=default: capacity=1.0, absoluteCapacity=1.0, usedResources=<memory:4096, vCores:1>, usedCapacity=0.125, absoluteUsedCapacity=0.125, numApps=1, numContainers=1 cluster=<memory:32768, vCores:10>
2020-02-06 01:54:07,764 INFO org.apache.hadoop.yarn.server.resourcemanager.scheduler.capacity.ParentQueue: completedContainer queue=root usedCapacity=0.125 absoluteUsedCapacity=0.125 used=<memory:4096, vCores:1> cluster=<memory:32768, vCores:10>
2020-02-06 01:54:07,764 INFO org.apache.hadoop.yarn.server.resourcemanager.scheduler.capacity.ParentQueue: Re-sorting completed queue: root.default stats: default: capacity=1.0, absoluteCapacity=1.0, usedResources=<memory:4096, vCores:1>, usedCapacity=0.125, absoluteUsedCapacity=0.125, numApps=1, numContainers=1
2020-02-06 01:54:07,764 INFO org.apache.hadoop.yarn.server.resourcemanager.scheduler.capacity.CapacityScheduler: Application attempt appattempt_1580953164575_0003_000001 released container container_1580953164575_0003_01_000003 on node: host: nodemaster:8050 #containers=1 available=<memory:28672, vCores:9> used=<memory:4096, vCores:1> with event: FINISHED
2020-02-06 01:54:08,139 INFO org.apache.hadoop.yarn.server.resourcemanager.rmcontainer.RMContainerImpl: container_1580953164575_0003_01_000001 Container Transitioned from RUNNING to COMPLETED
2020-02-06 01:54:08,140 INFO org.apache.hadoop.yarn.server.resourcemanager.ApplicationMasterService: Unregistering app attempt : appattempt_1580953164575_0003_000001
2020-02-06 01:54:08,140 INFO org.apache.hadoop.yarn.server.resourcemanager.security.AMRMTokenSecretManager: Application finished, removing password for appattempt_1580953164575_0003_000001
2020-02-06 01:54:08,140 INFO org.apache.hadoop.yarn.server.resourcemanager.scheduler.common.fica.FiCaSchedulerApp: Completed container: container_1580953164575_0003_01_000001 in state: COMPLETED event:FINISHED
2020-02-06 01:54:08,140 INFO org.apache.hadoop.yarn.server.resourcemanager.rmapp.attempt.RMAppAttemptImpl: appattempt_1580953164575_0003_000001 State change from FINISHING to FINISHED
2020-02-06 01:54:08,140 INFO org.apache.hadoop.yarn.server.resourcemanager.rmapp.RMAppImpl: application_1580953164575_0003 State change from FINISHING to FINISHED on event=ATTEMPT_FINISHED
2020-02-06 01:54:08,140 INFO org.apache.hadoop.yarn.server.resourcemanager.RMAuditLogger: USER=hadoop	OPERATION=AM Released Container	TARGET=SchedulerApp	RESULT=SUCCESS	APPID=application_1580953164575_0003	CONTAINERID=container_1580953164575_0003_01_000001
2020-02-06 01:54:08,140 INFO org.apache.hadoop.yarn.server.resourcemanager.RMAuditLogger: USER=hadoop	OPERATION=Application Finished - Succeeded	TARGET=RMAppManager	RESULT=SUCCESS	APPID=application_1580953164575_0003
2020-02-06 01:54:08,140 INFO org.apache.hadoop.yarn.server.resourcemanager.scheduler.SchedulerNode: Released container container_1580953164575_0003_01_000001 of capacity <memory:4096, vCores:1> on host nodemaster:8050, which currently has 0 containers, <memory:0, vCores:0> used and <memory:32768, vCores:10> available, release resources=true
2020-02-06 01:54:08,140 INFO org.apache.hadoop.yarn.server.resourcemanager.scheduler.capacity.LeafQueue: default used=<memory:0, vCores:0> numContainers=0 user=hadoop user-resources=<memory:0, vCores:0>
2020-02-06 01:54:08,140 INFO org.apache.hadoop.yarn.server.resourcemanager.scheduler.capacity.LeafQueue: completedContainer container=Container: [ContainerId: container_1580953164575_0003_01_000001, NodeId: nodemaster:8050, NodeHttpAddress: nodemaster:8042, Resource: <memory:4096, vCores:1>, Priority: 0, Token: Token { kind: ContainerToken, service: 172.28.1.15:8050 }, ] queue=default: capacity=1.0, absoluteCapacity=1.0, usedResources=<memory:0, vCores:0>, usedCapacity=0.0, absoluteUsedCapacity=0.0, numApps=1, numContainers=0 cluster=<memory:32768, vCores:10>
2020-02-06 01:54:08,140 INFO org.apache.hadoop.yarn.server.resourcemanager.scheduler.capacity.ParentQueue: completedContainer queue=root usedCapacity=0.0 absoluteUsedCapacity=0.0 used=<memory:0, vCores:0> cluster=<memory:32768, vCores:10>
2020-02-06 01:54:08,140 INFO org.apache.hadoop.yarn.server.resourcemanager.scheduler.capacity.ParentQueue: Re-sorting completed queue: root.default stats: default: capacity=1.0, absoluteCapacity=1.0, usedResources=<memory:0, vCores:0>, usedCapacity=0.0, absoluteUsedCapacity=0.0, numApps=1, numContainers=0
2020-02-06 01:54:08,140 INFO org.apache.hadoop.yarn.server.resourcemanager.scheduler.capacity.CapacityScheduler: Application attempt appattempt_1580953164575_0003_000001 released container container_1580953164575_0003_01_000001 on node: host: nodemaster:8050 #containers=0 available=<memory:32768, vCores:10> used=<memory:0, vCores:0> with event: FINISHED
2020-02-06 01:54:08,140 INFO org.apache.hadoop.yarn.server.resourcemanager.amlauncher.AMLauncher: Cleaning master appattempt_1580953164575_0003_000001
2020-02-06 01:54:08,140 INFO org.apache.hadoop.yarn.server.resourcemanager.scheduler.capacity.CapacityScheduler: Application Attempt appattempt_1580953164575_0003_000001 is done. finalState=FINISHED
2020-02-06 01:54:08,141 INFO org.apache.hadoop.yarn.server.resourcemanager.scheduler.AppSchedulingInfo: Application application_1580953164575_0003 requests cleared
2020-02-06 01:54:08,141 INFO org.apache.hadoop.yarn.server.resourcemanager.RMAppManager$ApplicationSummary: appId=application_1580953164575_0003,name=gen,user=hadoop,queue=default,state=FINISHED,trackingUrl=http://nodemaster:8088/proxy/application_1580953164575_0003/,appMasterHost=172.28.1.15,startTime=1580954038075,finishTime=1580954047431,finalStatus=SUCCEEDED,memorySeconds=165608,vcoreSeconds=18,preemptedAMContainers=0,preemptedNonAMContainers=0,preemptedResources=<memory:0\, vCores:0>,applicationType=SPARK
2020-02-06 01:54:08,141 INFO org.apache.hadoop.yarn.server.resourcemanager.scheduler.capacity.LeafQueue: Application removed - appId: application_1580953164575_0003 user: hadoop queue: default #user-pending-applications: 0 #user-active-applications: 0 #queue-pending-applications: 0 #queue-active-applications: 0
2020-02-06 01:54:08,141 INFO org.apache.hadoop.yarn.server.resourcemanager.scheduler.capacity.ParentQueue: Application removed - appId: application_1580953164575_0003 user: hadoop leaf-queue of parent: root #applications: 0
2020-02-06 01:54:10,144 INFO org.apache.hadoop.yarn.server.resourcemanager.scheduler.capacity.CapacityScheduler: Null container completed...
2020-02-06 01:54:10,145 INFO org.apache.hadoop.yarn.server.resourcemanager.scheduler.capacity.CapacityScheduler: Null container completed...
2020-02-06 01:55:17,300 INFO org.apache.hadoop.yarn.server.resourcemanager.ClientRMService: Allocated new applicationId: 4
2020-02-06 01:55:21,128 WARN org.apache.hadoop.yarn.server.resourcemanager.rmapp.RMAppImpl: The specific max attempts: 0 for application: 4 is invalid, because it is out of the range [1, 2]. Use the global max attempts instead.
2020-02-06 01:55:21,128 INFO org.apache.hadoop.yarn.server.resourcemanager.ClientRMService: Application with id 4 submitted by user hadoop
2020-02-06 01:55:21,128 INFO org.apache.hadoop.yarn.server.resourcemanager.rmapp.RMAppImpl: Storing application with id application_1580953164575_0004
2020-02-06 01:55:21,128 INFO org.apache.hadoop.yarn.server.resourcemanager.RMAuditLogger: USER=hadoop	IP=172.28.1.15	OPERATION=Submit Application Request	TARGET=ClientRMService	RESULT=SUCCESS	APPID=application_1580953164575_0004
2020-02-06 01:55:21,128 INFO org.apache.hadoop.yarn.server.resourcemanager.rmapp.RMAppImpl: application_1580953164575_0004 State change from NEW to NEW_SAVING on event=START
2020-02-06 01:55:21,128 INFO org.apache.hadoop.yarn.server.resourcemanager.recovery.RMStateStore: Storing info for app: application_1580953164575_0004
2020-02-06 01:55:21,128 INFO org.apache.hadoop.yarn.server.resourcemanager.rmapp.RMAppImpl: application_1580953164575_0004 State change from NEW_SAVING to SUBMITTED on event=APP_NEW_SAVED
2020-02-06 01:55:21,128 INFO org.apache.hadoop.yarn.server.resourcemanager.scheduler.capacity.ParentQueue: Application added - appId: application_1580953164575_0004 user: hadoop leaf-queue of parent: root #applications: 1
2020-02-06 01:55:21,128 INFO org.apache.hadoop.yarn.server.resourcemanager.scheduler.capacity.CapacityScheduler: Accepted application application_1580953164575_0004 from user: hadoop, in queue: default
2020-02-06 01:55:21,129 INFO org.apache.hadoop.yarn.server.resourcemanager.rmapp.RMAppImpl: application_1580953164575_0004 State change from SUBMITTED to ACCEPTED on event=APP_ACCEPTED
2020-02-06 01:55:21,129 INFO org.apache.hadoop.yarn.server.resourcemanager.ApplicationMasterService: Registering app attempt : appattempt_1580953164575_0004_000001
2020-02-06 01:55:21,129 INFO org.apache.hadoop.yarn.server.resourcemanager.rmapp.attempt.RMAppAttemptImpl: appattempt_1580953164575_0004_000001 State change from NEW to SUBMITTED
2020-02-06 01:55:21,129 INFO org.apache.hadoop.yarn.server.resourcemanager.scheduler.capacity.LeafQueue: Application application_1580953164575_0004 from user: hadoop activated in queue: default
2020-02-06 01:55:21,129 INFO org.apache.hadoop.yarn.server.resourcemanager.scheduler.capacity.LeafQueue: Application added - appId: application_1580953164575_0004 user: org.apache.hadoop.yarn.server.resourcemanager.scheduler.capacity.LeafQueue$User@7b27dfb8, leaf-queue: default #user-pending-applications: 0 #user-active-applications: 1 #queue-pending-applications: 0 #queue-active-applications: 1
2020-02-06 01:55:21,129 INFO org.apache.hadoop.yarn.server.resourcemanager.scheduler.capacity.CapacityScheduler: Added Application Attempt appattempt_1580953164575_0004_000001 to scheduler from user hadoop in queue default
2020-02-06 01:55:21,129 INFO org.apache.hadoop.yarn.server.resourcemanager.rmapp.attempt.RMAppAttemptImpl: appattempt_1580953164575_0004_000001 State change from SUBMITTED to SCHEDULED
2020-02-06 01:55:21,239 INFO org.apache.hadoop.yarn.server.resourcemanager.rmcontainer.RMContainerImpl: container_1580953164575_0004_01_000001 Container Transitioned from NEW to ALLOCATED
2020-02-06 01:55:21,239 INFO org.apache.hadoop.yarn.server.resourcemanager.RMAuditLogger: USER=hadoop	OPERATION=AM Allocated Container	TARGET=SchedulerApp	RESULT=SUCCESS	APPID=application_1580953164575_0004	CONTAINERID=container_1580953164575_0004_01_000001
2020-02-06 01:55:21,239 INFO org.apache.hadoop.yarn.server.resourcemanager.scheduler.SchedulerNode: Assigned container container_1580953164575_0004_01_000001 of capacity <memory:4096, vCores:1> on host nodemaster:8050, which has 1 containers, <memory:4096, vCores:1> used and <memory:28672, vCores:9> available after allocation
2020-02-06 01:55:21,239 INFO org.apache.hadoop.yarn.server.resourcemanager.scheduler.capacity.LeafQueue: assignedContainer application attempt=appattempt_1580953164575_0004_000001 container=Container: [ContainerId: container_1580953164575_0004_01_000001, NodeId: nodemaster:8050, NodeHttpAddress: nodemaster:8042, Resource: <memory:4096, vCores:1>, Priority: 0, Token: null, ] queue=default: capacity=1.0, absoluteCapacity=1.0, usedResources=<memory:0, vCores:0>, usedCapacity=0.0, absoluteUsedCapacity=0.0, numApps=1, numContainers=0 clusterResource=<memory:32768, vCores:10> type=OFF_SWITCH requestedPartition=
2020-02-06 01:55:21,239 INFO org.apache.hadoop.yarn.server.resourcemanager.scheduler.capacity.ParentQueue: Re-sorting assigned queue: root.default stats: default: capacity=1.0, absoluteCapacity=1.0, usedResources=<memory:4096, vCores:1>, usedCapacity=0.125, absoluteUsedCapacity=0.125, numApps=1, numContainers=1
2020-02-06 01:55:21,239 INFO org.apache.hadoop.yarn.server.resourcemanager.scheduler.capacity.ParentQueue: assignedContainer queue=root usedCapacity=0.125 absoluteUsedCapacity=0.125 used=<memory:4096, vCores:1> cluster=<memory:32768, vCores:10>
2020-02-06 01:55:21,240 INFO org.apache.hadoop.yarn.server.resourcemanager.security.NMTokenSecretManagerInRM: Sending NMToken for nodeId : nodemaster:8050 for container : container_1580953164575_0004_01_000001
2020-02-06 01:55:21,241 INFO org.apache.hadoop.yarn.server.resourcemanager.rmcontainer.RMContainerImpl: container_1580953164575_0004_01_000001 Container Transitioned from ALLOCATED to ACQUIRED
2020-02-06 01:55:21,241 INFO org.apache.hadoop.yarn.server.resourcemanager.security.NMTokenSecretManagerInRM: Clear node set for appattempt_1580953164575_0004_000001
2020-02-06 01:55:21,241 INFO org.apache.hadoop.yarn.server.resourcemanager.rmapp.attempt.RMAppAttemptImpl: Storing attempt: AppId: application_1580953164575_0004 AttemptId: appattempt_1580953164575_0004_000001 MasterContainer: Container: [ContainerId: container_1580953164575_0004_01_000001, NodeId: nodemaster:8050, NodeHttpAddress: nodemaster:8042, Resource: <memory:4096, vCores:1>, Priority: 0, Token: Token { kind: ContainerToken, service: 172.28.1.15:8050 }, ]
2020-02-06 01:55:21,241 INFO org.apache.hadoop.yarn.server.resourcemanager.rmapp.attempt.RMAppAttemptImpl: appattempt_1580953164575_0004_000001 State change from SCHEDULED to ALLOCATED_SAVING
2020-02-06 01:55:21,241 INFO org.apache.hadoop.yarn.server.resourcemanager.rmapp.attempt.RMAppAttemptImpl: appattempt_1580953164575_0004_000001 State change from ALLOCATED_SAVING to ALLOCATED
2020-02-06 01:55:21,247 INFO org.apache.hadoop.yarn.server.resourcemanager.amlauncher.AMLauncher: Launching masterappattempt_1580953164575_0004_000001
2020-02-06 01:55:21,250 INFO org.apache.hadoop.yarn.server.resourcemanager.amlauncher.AMLauncher: Setting up container Container: [ContainerId: container_1580953164575_0004_01_000001, NodeId: nodemaster:8050, NodeHttpAddress: nodemaster:8042, Resource: <memory:4096, vCores:1>, Priority: 0, Token: Token { kind: ContainerToken, service: 172.28.1.15:8050 }, ] for AM appattempt_1580953164575_0004_000001
2020-02-06 01:55:21,250 INFO org.apache.hadoop.yarn.server.resourcemanager.amlauncher.AMLauncher: Command to launch container container_1580953164575_0004_01_000001 : {{JAVA_HOME}}/bin/java,-server,-Xmx512m,-Djava.io.tmpdir={{PWD}}/tmp,-Dspark.yarn.app.container.log.dir=<LOG_DIR>,org.apache.spark.deploy.yarn.ExecutorLauncher,--arg,'nodemaster:43979',--properties-file,{{PWD}}/__spark_conf__/__spark_conf__.properties,1>,<LOG_DIR>/stdout,2>,<LOG_DIR>/stderr
2020-02-06 01:55:21,250 INFO org.apache.hadoop.yarn.server.resourcemanager.security.AMRMTokenSecretManager: Create AMRMToken for ApplicationAttempt: appattempt_1580953164575_0004_000001
2020-02-06 01:55:21,250 INFO org.apache.hadoop.yarn.server.resourcemanager.security.AMRMTokenSecretManager: Creating password for appattempt_1580953164575_0004_000001
2020-02-06 01:55:21,261 INFO org.apache.hadoop.yarn.server.resourcemanager.amlauncher.AMLauncher: Done launching container Container: [ContainerId: container_1580953164575_0004_01_000001, NodeId: nodemaster:8050, NodeHttpAddress: nodemaster:8042, Resource: <memory:4096, vCores:1>, Priority: 0, Token: Token { kind: ContainerToken, service: 172.28.1.15:8050 }, ] for AM appattempt_1580953164575_0004_000001
2020-02-06 01:55:21,261 INFO org.apache.hadoop.yarn.server.resourcemanager.rmapp.attempt.RMAppAttemptImpl: appattempt_1580953164575_0004_000001 State change from ALLOCATED to LAUNCHED
2020-02-06 01:55:22,237 INFO org.apache.hadoop.yarn.server.resourcemanager.rmcontainer.RMContainerImpl: container_1580953164575_0004_01_000001 Container Transitioned from ACQUIRED to RUNNING
2020-02-06 01:55:23,709 INFO SecurityLogger.org.apache.hadoop.ipc.Server: Auth successful for appattempt_1580953164575_0004_000001 (auth:SIMPLE)
2020-02-06 01:55:23,711 INFO org.apache.hadoop.yarn.server.resourcemanager.ApplicationMasterService: AM registration appattempt_1580953164575_0004_000001
2020-02-06 01:55:23,711 INFO org.apache.hadoop.yarn.server.resourcemanager.RMAuditLogger: USER=hadoop	IP=172.28.1.15	OPERATION=Register App Master	TARGET=ApplicationMasterService	RESULT=SUCCESS	APPID=application_1580953164575_0004	APPATTEMPTID=appattempt_1580953164575_0004_000001
2020-02-06 01:55:23,711 INFO org.apache.hadoop.yarn.server.resourcemanager.rmapp.attempt.RMAppAttemptImpl: appattempt_1580953164575_0004_000001 State change from LAUNCHED to RUNNING
2020-02-06 01:55:23,711 INFO org.apache.hadoop.yarn.server.resourcemanager.rmapp.RMAppImpl: application_1580953164575_0004 State change from ACCEPTED to RUNNING on event=ATTEMPT_REGISTERED
2020-02-06 01:55:24,239 INFO org.apache.hadoop.yarn.server.resourcemanager.rmcontainer.RMContainerImpl: container_1580953164575_0004_01_000002 Container Transitioned from NEW to ALLOCATED
2020-02-06 01:55:24,239 INFO org.apache.hadoop.yarn.server.resourcemanager.RMAuditLogger: USER=hadoop	OPERATION=AM Allocated Container	TARGET=SchedulerApp	RESULT=SUCCESS	APPID=application_1580953164575_0004	CONTAINERID=container_1580953164575_0004_01_000002
2020-02-06 01:55:24,239 INFO org.apache.hadoop.yarn.server.resourcemanager.scheduler.SchedulerNode: Assigned container container_1580953164575_0004_01_000002 of capacity <memory:12288, vCores:1> on host nodemaster:8050, which has 2 containers, <memory:16384, vCores:2> used and <memory:16384, vCores:8> available after allocation
2020-02-06 01:55:24,239 INFO org.apache.hadoop.yarn.server.resourcemanager.scheduler.capacity.LeafQueue: assignedContainer application attempt=appattempt_1580953164575_0004_000001 container=Container: [ContainerId: container_1580953164575_0004_01_000002, NodeId: nodemaster:8050, NodeHttpAddress: nodemaster:8042, Resource: <memory:12288, vCores:1>, Priority: 1, Token: null, ] queue=default: capacity=1.0, absoluteCapacity=1.0, usedResources=<memory:4096, vCores:1>, usedCapacity=0.125, absoluteUsedCapacity=0.125, numApps=1, numContainers=1 clusterResource=<memory:32768, vCores:10> type=OFF_SWITCH requestedPartition=
2020-02-06 01:55:24,239 INFO org.apache.hadoop.yarn.server.resourcemanager.scheduler.capacity.ParentQueue: Re-sorting assigned queue: root.default stats: default: capacity=1.0, absoluteCapacity=1.0, usedResources=<memory:16384, vCores:2>, usedCapacity=0.5, absoluteUsedCapacity=0.5, numApps=1, numContainers=2
2020-02-06 01:55:24,239 INFO org.apache.hadoop.yarn.server.resourcemanager.scheduler.capacity.ParentQueue: assignedContainer queue=root usedCapacity=0.5 absoluteUsedCapacity=0.5 used=<memory:16384, vCores:2> cluster=<memory:32768, vCores:10>
2020-02-06 01:55:24,384 INFO org.apache.hadoop.yarn.server.resourcemanager.security.NMTokenSecretManagerInRM: Sending NMToken for nodeId : nodemaster:8050 for container : container_1580953164575_0004_01_000002
2020-02-06 01:55:24,384 INFO org.apache.hadoop.yarn.server.resourcemanager.rmcontainer.RMContainerImpl: container_1580953164575_0004_01_000002 Container Transitioned from ALLOCATED to ACQUIRED
2020-02-06 01:55:25,239 INFO org.apache.hadoop.yarn.server.resourcemanager.rmcontainer.RMContainerImpl: container_1580953164575_0004_01_000002 Container Transitioned from ACQUIRED to RUNNING
2020-02-06 01:55:25,240 INFO org.apache.hadoop.yarn.server.resourcemanager.rmcontainer.RMContainerImpl: container_1580953164575_0004_01_000003 Container Transitioned from NEW to ALLOCATED
2020-02-06 01:55:25,240 INFO org.apache.hadoop.yarn.server.resourcemanager.RMAuditLogger: USER=hadoop	OPERATION=AM Allocated Container	TARGET=SchedulerApp	RESULT=SUCCESS	APPID=application_1580953164575_0004	CONTAINERID=container_1580953164575_0004_01_000003
2020-02-06 01:55:25,240 INFO org.apache.hadoop.yarn.server.resourcemanager.scheduler.SchedulerNode: Assigned container container_1580953164575_0004_01_000003 of capacity <memory:12288, vCores:1> on host nodemaster:8050, which has 3 containers, <memory:28672, vCores:3> used and <memory:4096, vCores:7> available after allocation
2020-02-06 01:55:25,240 INFO org.apache.hadoop.yarn.server.resourcemanager.scheduler.capacity.LeafQueue: assignedContainer application attempt=appattempt_1580953164575_0004_000001 container=Container: [ContainerId: container_1580953164575_0004_01_000003, NodeId: nodemaster:8050, NodeHttpAddress: nodemaster:8042, Resource: <memory:12288, vCores:1>, Priority: 1, Token: null, ] queue=default: capacity=1.0, absoluteCapacity=1.0, usedResources=<memory:16384, vCores:2>, usedCapacity=0.5, absoluteUsedCapacity=0.5, numApps=1, numContainers=2 clusterResource=<memory:32768, vCores:10> type=OFF_SWITCH requestedPartition=
2020-02-06 01:55:25,240 INFO org.apache.hadoop.yarn.server.resourcemanager.scheduler.capacity.ParentQueue: Re-sorting assigned queue: root.default stats: default: capacity=1.0, absoluteCapacity=1.0, usedResources=<memory:28672, vCores:3>, usedCapacity=0.875, absoluteUsedCapacity=0.875, numApps=1, numContainers=3
2020-02-06 01:55:25,240 INFO org.apache.hadoop.yarn.server.resourcemanager.scheduler.capacity.ParentQueue: assignedContainer queue=root usedCapacity=0.875 absoluteUsedCapacity=0.875 used=<memory:28672, vCores:3> cluster=<memory:32768, vCores:10>
2020-02-06 01:55:26,796 INFO org.apache.hadoop.yarn.server.resourcemanager.rmcontainer.RMContainerImpl: container_1580953164575_0004_01_000003 Container Transitioned from ALLOCATED to ACQUIRED
2020-02-06 01:55:27,241 INFO org.apache.hadoop.yarn.server.resourcemanager.rmcontainer.RMContainerImpl: container_1580953164575_0004_01_000003 Container Transitioned from ACQUIRED to RUNNING
2020-02-06 01:55:29,744 INFO org.apache.hadoop.yarn.server.resourcemanager.scheduler.AppSchedulingInfo: checking for deactivate of application :application_1580953164575_0004
2020-02-06 01:55:29,776 INFO org.apache.hadoop.yarn.server.resourcemanager.rmapp.attempt.RMAppAttemptImpl: Updating application attempt appattempt_1580953164575_0004_000001 with final state: FINISHING, and exit status: -1000
2020-02-06 01:55:29,776 INFO org.apache.hadoop.yarn.server.resourcemanager.rmapp.attempt.RMAppAttemptImpl: appattempt_1580953164575_0004_000001 State change from RUNNING to FINAL_SAVING
2020-02-06 01:55:29,776 INFO org.apache.hadoop.yarn.server.resourcemanager.rmapp.RMAppImpl: Updating application application_1580953164575_0004 with final state: FINISHING
2020-02-06 01:55:29,776 INFO org.apache.hadoop.yarn.server.resourcemanager.rmapp.RMAppImpl: application_1580953164575_0004 State change from RUNNING to FINAL_SAVING on event=ATTEMPT_UNREGISTERED
2020-02-06 01:55:29,776 INFO org.apache.hadoop.yarn.server.resourcemanager.recovery.RMStateStore: Updating info for app: application_1580953164575_0004
2020-02-06 01:55:29,776 INFO org.apache.hadoop.yarn.server.resourcemanager.rmapp.attempt.RMAppAttemptImpl: appattempt_1580953164575_0004_000001 State change from FINAL_SAVING to FINISHING
2020-02-06 01:55:29,776 INFO org.apache.hadoop.yarn.server.resourcemanager.rmapp.RMAppImpl: application_1580953164575_0004 State change from FINAL_SAVING to FINISHING on event=APP_UPDATE_SAVED
2020-02-06 01:55:29,789 INFO org.apache.hadoop.yarn.server.resourcemanager.rmcontainer.RMContainerImpl: container_1580953164575_0004_01_000002 Container Transitioned from RUNNING to COMPLETED
2020-02-06 01:55:29,789 INFO org.apache.hadoop.yarn.server.resourcemanager.scheduler.common.fica.FiCaSchedulerApp: Completed container: container_1580953164575_0004_01_000002 in state: COMPLETED event:FINISHED
2020-02-06 01:55:29,790 INFO org.apache.hadoop.yarn.server.resourcemanager.RMAuditLogger: USER=hadoop	OPERATION=AM Released Container	TARGET=SchedulerApp	RESULT=SUCCESS	APPID=application_1580953164575_0004	CONTAINERID=container_1580953164575_0004_01_000002
2020-02-06 01:55:29,790 INFO org.apache.hadoop.yarn.server.resourcemanager.scheduler.SchedulerNode: Released container container_1580953164575_0004_01_000002 of capacity <memory:12288, vCores:1> on host nodemaster:8050, which currently has 2 containers, <memory:16384, vCores:2> used and <memory:16384, vCores:8> available, release resources=true
2020-02-06 01:55:29,790 INFO org.apache.hadoop.yarn.server.resourcemanager.scheduler.capacity.LeafQueue: default used=<memory:16384, vCores:2> numContainers=2 user=hadoop user-resources=<memory:16384, vCores:2>
2020-02-06 01:55:29,790 INFO org.apache.hadoop.yarn.server.resourcemanager.scheduler.capacity.LeafQueue: completedContainer container=Container: [ContainerId: container_1580953164575_0004_01_000002, NodeId: nodemaster:8050, NodeHttpAddress: nodemaster:8042, Resource: <memory:12288, vCores:1>, Priority: 1, Token: Token { kind: ContainerToken, service: 172.28.1.15:8050 }, ] queue=default: capacity=1.0, absoluteCapacity=1.0, usedResources=<memory:16384, vCores:2>, usedCapacity=0.5, absoluteUsedCapacity=0.5, numApps=1, numContainers=2 cluster=<memory:32768, vCores:10>
2020-02-06 01:55:29,790 INFO org.apache.hadoop.yarn.server.resourcemanager.scheduler.capacity.ParentQueue: completedContainer queue=root usedCapacity=0.5 absoluteUsedCapacity=0.5 used=<memory:16384, vCores:2> cluster=<memory:32768, vCores:10>
2020-02-06 01:55:29,790 INFO org.apache.hadoop.yarn.server.resourcemanager.scheduler.capacity.ParentQueue: Re-sorting completed queue: root.default stats: default: capacity=1.0, absoluteCapacity=1.0, usedResources=<memory:16384, vCores:2>, usedCapacity=0.5, absoluteUsedCapacity=0.5, numApps=1, numContainers=2
2020-02-06 01:55:29,790 INFO org.apache.hadoop.yarn.server.resourcemanager.scheduler.capacity.CapacityScheduler: Application attempt appattempt_1580953164575_0004_000001 released container container_1580953164575_0004_01_000002 on node: host: nodemaster:8050 #containers=2 available=<memory:16384, vCores:8> used=<memory:16384, vCores:2> with event: FINISHED
2020-02-06 01:55:29,878 INFO org.apache.hadoop.yarn.server.resourcemanager.ApplicationMasterService: application_1580953164575_0004 unregistered successfully. 
2020-02-06 01:55:30,161 INFO org.apache.hadoop.yarn.server.resourcemanager.rmcontainer.RMContainerImpl: container_1580953164575_0004_01_000003 Container Transitioned from RUNNING to COMPLETED
2020-02-06 01:55:30,161 INFO org.apache.hadoop.yarn.server.resourcemanager.scheduler.common.fica.FiCaSchedulerApp: Completed container: container_1580953164575_0004_01_000003 in state: COMPLETED event:FINISHED
2020-02-06 01:55:30,161 INFO org.apache.hadoop.yarn.server.resourcemanager.RMAuditLogger: USER=hadoop	OPERATION=AM Released Container	TARGET=SchedulerApp	RESULT=SUCCESS	APPID=application_1580953164575_0004	CONTAINERID=container_1580953164575_0004_01_000003
2020-02-06 01:55:30,161 INFO org.apache.hadoop.yarn.server.resourcemanager.scheduler.SchedulerNode: Released container container_1580953164575_0004_01_000003 of capacity <memory:12288, vCores:1> on host nodemaster:8050, which currently has 1 containers, <memory:4096, vCores:1> used and <memory:28672, vCores:9> available, release resources=true
2020-02-06 01:55:30,161 INFO org.apache.hadoop.yarn.server.resourcemanager.scheduler.capacity.LeafQueue: default used=<memory:4096, vCores:1> numContainers=1 user=hadoop user-resources=<memory:4096, vCores:1>
2020-02-06 01:55:30,161 INFO org.apache.hadoop.yarn.server.resourcemanager.scheduler.capacity.LeafQueue: completedContainer container=Container: [ContainerId: container_1580953164575_0004_01_000003, NodeId: nodemaster:8050, NodeHttpAddress: nodemaster:8042, Resource: <memory:12288, vCores:1>, Priority: 1, Token: Token { kind: ContainerToken, service: 172.28.1.15:8050 }, ] queue=default: capacity=1.0, absoluteCapacity=1.0, usedResources=<memory:4096, vCores:1>, usedCapacity=0.125, absoluteUsedCapacity=0.125, numApps=1, numContainers=1 cluster=<memory:32768, vCores:10>
2020-02-06 01:55:30,161 INFO org.apache.hadoop.yarn.server.resourcemanager.scheduler.capacity.ParentQueue: completedContainer queue=root usedCapacity=0.125 absoluteUsedCapacity=0.125 used=<memory:4096, vCores:1> cluster=<memory:32768, vCores:10>
2020-02-06 01:55:30,162 INFO org.apache.hadoop.yarn.server.resourcemanager.scheduler.capacity.ParentQueue: Re-sorting completed queue: root.default stats: default: capacity=1.0, absoluteCapacity=1.0, usedResources=<memory:4096, vCores:1>, usedCapacity=0.125, absoluteUsedCapacity=0.125, numApps=1, numContainers=1
2020-02-06 01:55:30,162 INFO org.apache.hadoop.yarn.server.resourcemanager.scheduler.capacity.CapacityScheduler: Application attempt appattempt_1580953164575_0004_000001 released container container_1580953164575_0004_01_000003 on node: host: nodemaster:8050 #containers=1 available=<memory:28672, vCores:9> used=<memory:4096, vCores:1> with event: FINISHED
2020-02-06 01:55:30,243 INFO org.apache.hadoop.yarn.server.resourcemanager.rmcontainer.RMContainerImpl: container_1580953164575_0004_01_000001 Container Transitioned from RUNNING to COMPLETED
2020-02-06 01:55:30,243 INFO org.apache.hadoop.yarn.server.resourcemanager.scheduler.common.fica.FiCaSchedulerApp: Completed container: container_1580953164575_0004_01_000001 in state: COMPLETED event:FINISHED
2020-02-06 01:55:30,243 INFO org.apache.hadoop.yarn.server.resourcemanager.ApplicationMasterService: Unregistering app attempt : appattempt_1580953164575_0004_000001
2020-02-06 01:55:30,243 INFO org.apache.hadoop.yarn.server.resourcemanager.RMAuditLogger: USER=hadoop	OPERATION=AM Released Container	TARGET=SchedulerApp	RESULT=SUCCESS	APPID=application_1580953164575_0004	CONTAINERID=container_1580953164575_0004_01_000001
2020-02-06 01:55:30,243 INFO org.apache.hadoop.yarn.server.resourcemanager.security.AMRMTokenSecretManager: Application finished, removing password for appattempt_1580953164575_0004_000001
2020-02-06 01:55:30,243 INFO org.apache.hadoop.yarn.server.resourcemanager.scheduler.SchedulerNode: Released container container_1580953164575_0004_01_000001 of capacity <memory:4096, vCores:1> on host nodemaster:8050, which currently has 0 containers, <memory:0, vCores:0> used and <memory:32768, vCores:10> available, release resources=true
2020-02-06 01:55:30,243 INFO org.apache.hadoop.yarn.server.resourcemanager.rmapp.attempt.RMAppAttemptImpl: appattempt_1580953164575_0004_000001 State change from FINISHING to FINISHED
2020-02-06 01:55:30,243 INFO org.apache.hadoop.yarn.server.resourcemanager.scheduler.capacity.LeafQueue: default used=<memory:0, vCores:0> numContainers=0 user=hadoop user-resources=<memory:0, vCores:0>
2020-02-06 01:55:30,243 INFO org.apache.hadoop.yarn.server.resourcemanager.rmapp.RMAppImpl: application_1580953164575_0004 State change from FINISHING to FINISHED on event=ATTEMPT_FINISHED
2020-02-06 01:55:30,243 INFO org.apache.hadoop.yarn.server.resourcemanager.RMAuditLogger: USER=hadoop	OPERATION=Application Finished - Succeeded	TARGET=RMAppManager	RESULT=SUCCESS	APPID=application_1580953164575_0004
2020-02-06 01:55:30,243 INFO org.apache.hadoop.yarn.server.resourcemanager.scheduler.capacity.LeafQueue: completedContainer container=Container: [ContainerId: container_1580953164575_0004_01_000001, NodeId: nodemaster:8050, NodeHttpAddress: nodemaster:8042, Resource: <memory:4096, vCores:1>, Priority: 0, Token: Token { kind: ContainerToken, service: 172.28.1.15:8050 }, ] queue=default: capacity=1.0, absoluteCapacity=1.0, usedResources=<memory:0, vCores:0>, usedCapacity=0.0, absoluteUsedCapacity=0.0, numApps=1, numContainers=0 cluster=<memory:32768, vCores:10>
2020-02-06 01:55:30,243 INFO org.apache.hadoop.yarn.server.resourcemanager.scheduler.capacity.ParentQueue: completedContainer queue=root usedCapacity=0.0 absoluteUsedCapacity=0.0 used=<memory:0, vCores:0> cluster=<memory:32768, vCores:10>
2020-02-06 01:55:30,243 INFO org.apache.hadoop.yarn.server.resourcemanager.scheduler.capacity.ParentQueue: Re-sorting completed queue: root.default stats: default: capacity=1.0, absoluteCapacity=1.0, usedResources=<memory:0, vCores:0>, usedCapacity=0.0, absoluteUsedCapacity=0.0, numApps=1, numContainers=0
2020-02-06 01:55:30,243 INFO org.apache.hadoop.yarn.server.resourcemanager.scheduler.capacity.CapacityScheduler: Application attempt appattempt_1580953164575_0004_000001 released container container_1580953164575_0004_01_000001 on node: host: nodemaster:8050 #containers=0 available=<memory:32768, vCores:10> used=<memory:0, vCores:0> with event: FINISHED
2020-02-06 01:55:30,244 INFO org.apache.hadoop.yarn.server.resourcemanager.scheduler.capacity.CapacityScheduler: Application Attempt appattempt_1580953164575_0004_000001 is done. finalState=FINISHED
2020-02-06 01:55:30,244 INFO org.apache.hadoop.yarn.server.resourcemanager.RMAppManager$ApplicationSummary: appId=application_1580953164575_0004,name=gen,user=hadoop,queue=default,state=FINISHED,trackingUrl=http://nodemaster:8088/proxy/application_1580953164575_0004/,appMasterHost=172.28.1.15,startTime=1580954121128,finishTime=1580954129776,finalStatus=SUCCEEDED,memorySeconds=165547,vcoreSeconds=18,preemptedAMContainers=0,preemptedNonAMContainers=0,preemptedResources=<memory:0\, vCores:0>,applicationType=SPARK
2020-02-06 01:55:30,244 INFO org.apache.hadoop.yarn.server.resourcemanager.scheduler.AppSchedulingInfo: Application application_1580953164575_0004 requests cleared
2020-02-06 01:55:30,244 INFO org.apache.hadoop.yarn.server.resourcemanager.scheduler.capacity.LeafQueue: Application removed - appId: application_1580953164575_0004 user: hadoop queue: default #user-pending-applications: 0 #user-active-applications: 0 #queue-pending-applications: 0 #queue-active-applications: 0
2020-02-06 01:55:30,244 INFO org.apache.hadoop.yarn.server.resourcemanager.scheduler.capacity.ParentQueue: Application removed - appId: application_1580953164575_0004 user: hadoop leaf-queue of parent: root #applications: 0
2020-02-06 01:55:30,244 INFO org.apache.hadoop.yarn.server.resourcemanager.amlauncher.AMLauncher: Cleaning master appattempt_1580953164575_0004_000001
2020-02-06 01:55:32,246 INFO org.apache.hadoop.yarn.server.resourcemanager.scheduler.capacity.CapacityScheduler: Null container completed...
2020-02-06 01:55:32,246 INFO org.apache.hadoop.yarn.server.resourcemanager.scheduler.capacity.CapacityScheduler: Null container completed...
2020-02-06 02:00:50,029 INFO org.apache.hadoop.yarn.server.resourcemanager.ClientRMService: Allocated new applicationId: 5
2020-02-06 02:00:53,042 WARN org.apache.hadoop.yarn.server.resourcemanager.rmapp.RMAppImpl: The specific max attempts: 0 for application: 5 is invalid, because it is out of the range [1, 2]. Use the global max attempts instead.
2020-02-06 02:00:53,042 INFO org.apache.hadoop.yarn.server.resourcemanager.ClientRMService: Application with id 5 submitted by user hadoop
2020-02-06 02:00:53,042 INFO org.apache.hadoop.yarn.server.resourcemanager.RMAuditLogger: USER=hadoop	IP=172.28.1.15	OPERATION=Submit Application Request	TARGET=ClientRMService	RESULT=SUCCESS	APPID=application_1580953164575_0005
2020-02-06 02:00:53,042 INFO org.apache.hadoop.yarn.server.resourcemanager.rmapp.RMAppImpl: Storing application with id application_1580953164575_0005
2020-02-06 02:00:53,042 INFO org.apache.hadoop.yarn.server.resourcemanager.rmapp.RMAppImpl: application_1580953164575_0005 State change from NEW to NEW_SAVING on event=START
2020-02-06 02:00:53,042 INFO org.apache.hadoop.yarn.server.resourcemanager.recovery.RMStateStore: Storing info for app: application_1580953164575_0005
2020-02-06 02:00:53,042 INFO org.apache.hadoop.yarn.server.resourcemanager.rmapp.RMAppImpl: application_1580953164575_0005 State change from NEW_SAVING to SUBMITTED on event=APP_NEW_SAVED
2020-02-06 02:00:53,042 INFO org.apache.hadoop.yarn.server.resourcemanager.scheduler.capacity.ParentQueue: Application added - appId: application_1580953164575_0005 user: hadoop leaf-queue of parent: root #applications: 1
2020-02-06 02:00:53,042 INFO org.apache.hadoop.yarn.server.resourcemanager.scheduler.capacity.CapacityScheduler: Accepted application application_1580953164575_0005 from user: hadoop, in queue: default
2020-02-06 02:00:53,043 INFO org.apache.hadoop.yarn.server.resourcemanager.rmapp.RMAppImpl: application_1580953164575_0005 State change from SUBMITTED to ACCEPTED on event=APP_ACCEPTED
2020-02-06 02:00:53,043 INFO org.apache.hadoop.yarn.server.resourcemanager.ApplicationMasterService: Registering app attempt : appattempt_1580953164575_0005_000001
2020-02-06 02:00:53,043 INFO org.apache.hadoop.yarn.server.resourcemanager.rmapp.attempt.RMAppAttemptImpl: appattempt_1580953164575_0005_000001 State change from NEW to SUBMITTED
2020-02-06 02:00:53,043 INFO org.apache.hadoop.yarn.server.resourcemanager.scheduler.capacity.LeafQueue: Application application_1580953164575_0005 from user: hadoop activated in queue: default
2020-02-06 02:00:53,043 INFO org.apache.hadoop.yarn.server.resourcemanager.scheduler.capacity.LeafQueue: Application added - appId: application_1580953164575_0005 user: org.apache.hadoop.yarn.server.resourcemanager.scheduler.capacity.LeafQueue$User@2c1c8560, leaf-queue: default #user-pending-applications: 0 #user-active-applications: 1 #queue-pending-applications: 0 #queue-active-applications: 1
2020-02-06 02:00:53,043 INFO org.apache.hadoop.yarn.server.resourcemanager.scheduler.capacity.CapacityScheduler: Added Application Attempt appattempt_1580953164575_0005_000001 to scheduler from user hadoop in queue default
2020-02-06 02:00:53,043 INFO org.apache.hadoop.yarn.server.resourcemanager.rmapp.attempt.RMAppAttemptImpl: appattempt_1580953164575_0005_000001 State change from SUBMITTED to SCHEDULED
2020-02-06 02:00:53,673 INFO org.apache.hadoop.yarn.server.resourcemanager.rmcontainer.RMContainerImpl: container_1580953164575_0005_01_000001 Container Transitioned from NEW to ALLOCATED
2020-02-06 02:00:53,673 INFO org.apache.hadoop.yarn.server.resourcemanager.RMAuditLogger: USER=hadoop	OPERATION=AM Allocated Container	TARGET=SchedulerApp	RESULT=SUCCESS	APPID=application_1580953164575_0005	CONTAINERID=container_1580953164575_0005_01_000001
2020-02-06 02:00:53,673 INFO org.apache.hadoop.yarn.server.resourcemanager.scheduler.SchedulerNode: Assigned container container_1580953164575_0005_01_000001 of capacity <memory:4096, vCores:1> on host nodemaster:8050, which has 1 containers, <memory:4096, vCores:1> used and <memory:28672, vCores:9> available after allocation
2020-02-06 02:00:53,673 INFO org.apache.hadoop.yarn.server.resourcemanager.scheduler.capacity.LeafQueue: assignedContainer application attempt=appattempt_1580953164575_0005_000001 container=Container: [ContainerId: container_1580953164575_0005_01_000001, NodeId: nodemaster:8050, NodeHttpAddress: nodemaster:8042, Resource: <memory:4096, vCores:1>, Priority: 0, Token: null, ] queue=default: capacity=1.0, absoluteCapacity=1.0, usedResources=<memory:0, vCores:0>, usedCapacity=0.0, absoluteUsedCapacity=0.0, numApps=1, numContainers=0 clusterResource=<memory:32768, vCores:10> type=OFF_SWITCH requestedPartition=
2020-02-06 02:00:53,674 INFO org.apache.hadoop.yarn.server.resourcemanager.scheduler.capacity.ParentQueue: Re-sorting assigned queue: root.default stats: default: capacity=1.0, absoluteCapacity=1.0, usedResources=<memory:4096, vCores:1>, usedCapacity=0.125, absoluteUsedCapacity=0.125, numApps=1, numContainers=1
2020-02-06 02:00:53,674 INFO org.apache.hadoop.yarn.server.resourcemanager.scheduler.capacity.ParentQueue: assignedContainer queue=root usedCapacity=0.125 absoluteUsedCapacity=0.125 used=<memory:4096, vCores:1> cluster=<memory:32768, vCores:10>
2020-02-06 02:00:53,674 INFO org.apache.hadoop.yarn.server.resourcemanager.security.NMTokenSecretManagerInRM: Sending NMToken for nodeId : nodemaster:8050 for container : container_1580953164575_0005_01_000001
2020-02-06 02:00:53,674 INFO org.apache.hadoop.yarn.server.resourcemanager.rmcontainer.RMContainerImpl: container_1580953164575_0005_01_000001 Container Transitioned from ALLOCATED to ACQUIRED
2020-02-06 02:00:53,674 INFO org.apache.hadoop.yarn.server.resourcemanager.security.NMTokenSecretManagerInRM: Clear node set for appattempt_1580953164575_0005_000001
2020-02-06 02:00:53,674 INFO org.apache.hadoop.yarn.server.resourcemanager.rmapp.attempt.RMAppAttemptImpl: Storing attempt: AppId: application_1580953164575_0005 AttemptId: appattempt_1580953164575_0005_000001 MasterContainer: Container: [ContainerId: container_1580953164575_0005_01_000001, NodeId: nodemaster:8050, NodeHttpAddress: nodemaster:8042, Resource: <memory:4096, vCores:1>, Priority: 0, Token: Token { kind: ContainerToken, service: 172.28.1.15:8050 }, ]
2020-02-06 02:00:53,675 INFO org.apache.hadoop.yarn.server.resourcemanager.rmapp.attempt.RMAppAttemptImpl: appattempt_1580953164575_0005_000001 State change from SCHEDULED to ALLOCATED_SAVING
2020-02-06 02:00:53,675 INFO org.apache.hadoop.yarn.server.resourcemanager.rmapp.attempt.RMAppAttemptImpl: appattempt_1580953164575_0005_000001 State change from ALLOCATED_SAVING to ALLOCATED
2020-02-06 02:00:53,675 INFO org.apache.hadoop.yarn.server.resourcemanager.amlauncher.AMLauncher: Launching masterappattempt_1580953164575_0005_000001
2020-02-06 02:00:53,676 INFO org.apache.hadoop.yarn.server.resourcemanager.amlauncher.AMLauncher: Setting up container Container: [ContainerId: container_1580953164575_0005_01_000001, NodeId: nodemaster:8050, NodeHttpAddress: nodemaster:8042, Resource: <memory:4096, vCores:1>, Priority: 0, Token: Token { kind: ContainerToken, service: 172.28.1.15:8050 }, ] for AM appattempt_1580953164575_0005_000001
2020-02-06 02:00:53,676 INFO org.apache.hadoop.yarn.server.resourcemanager.amlauncher.AMLauncher: Command to launch container container_1580953164575_0005_01_000001 : {{JAVA_HOME}}/bin/java,-server,-Xmx512m,-Djava.io.tmpdir={{PWD}}/tmp,-Dspark.yarn.app.container.log.dir=<LOG_DIR>,org.apache.spark.deploy.yarn.ExecutorLauncher,--arg,'nodemaster:45893',--properties-file,{{PWD}}/__spark_conf__/__spark_conf__.properties,1>,<LOG_DIR>/stdout,2>,<LOG_DIR>/stderr
2020-02-06 02:00:53,676 INFO org.apache.hadoop.yarn.server.resourcemanager.security.AMRMTokenSecretManager: Create AMRMToken for ApplicationAttempt: appattempt_1580953164575_0005_000001
2020-02-06 02:00:53,676 INFO org.apache.hadoop.yarn.server.resourcemanager.security.AMRMTokenSecretManager: Creating password for appattempt_1580953164575_0005_000001
2020-02-06 02:00:53,681 INFO org.apache.hadoop.yarn.server.resourcemanager.amlauncher.AMLauncher: Done launching container Container: [ContainerId: container_1580953164575_0005_01_000001, NodeId: nodemaster:8050, NodeHttpAddress: nodemaster:8042, Resource: <memory:4096, vCores:1>, Priority: 0, Token: Token { kind: ContainerToken, service: 172.28.1.15:8050 }, ] for AM appattempt_1580953164575_0005_000001
2020-02-06 02:00:53,682 INFO org.apache.hadoop.yarn.server.resourcemanager.rmapp.attempt.RMAppAttemptImpl: appattempt_1580953164575_0005_000001 State change from ALLOCATED to LAUNCHED
2020-02-06 02:00:54,674 INFO org.apache.hadoop.yarn.server.resourcemanager.rmcontainer.RMContainerImpl: container_1580953164575_0005_01_000001 Container Transitioned from ACQUIRED to RUNNING
2020-02-06 02:00:56,047 INFO SecurityLogger.org.apache.hadoop.ipc.Server: Auth successful for appattempt_1580953164575_0005_000001 (auth:SIMPLE)
2020-02-06 02:00:56,049 INFO org.apache.hadoop.yarn.server.resourcemanager.ApplicationMasterService: AM registration appattempt_1580953164575_0005_000001
2020-02-06 02:00:56,049 INFO org.apache.hadoop.yarn.server.resourcemanager.RMAuditLogger: USER=hadoop	IP=172.28.1.15	OPERATION=Register App Master	TARGET=ApplicationMasterService	RESULT=SUCCESS	APPID=application_1580953164575_0005	APPATTEMPTID=appattempt_1580953164575_0005_000001
2020-02-06 02:00:56,049 INFO org.apache.hadoop.yarn.server.resourcemanager.rmapp.attempt.RMAppAttemptImpl: appattempt_1580953164575_0005_000001 State change from LAUNCHED to RUNNING
2020-02-06 02:00:56,049 INFO org.apache.hadoop.yarn.server.resourcemanager.rmapp.RMAppImpl: application_1580953164575_0005 State change from ACCEPTED to RUNNING on event=ATTEMPT_REGISTERED
2020-02-06 02:00:56,676 INFO org.apache.hadoop.yarn.server.resourcemanager.rmcontainer.RMContainerImpl: container_1580953164575_0005_01_000002 Container Transitioned from NEW to ALLOCATED
2020-02-06 02:00:56,676 INFO org.apache.hadoop.yarn.server.resourcemanager.RMAuditLogger: USER=hadoop	OPERATION=AM Allocated Container	TARGET=SchedulerApp	RESULT=SUCCESS	APPID=application_1580953164575_0005	CONTAINERID=container_1580953164575_0005_01_000002
2020-02-06 02:00:56,676 INFO org.apache.hadoop.yarn.server.resourcemanager.scheduler.SchedulerNode: Assigned container container_1580953164575_0005_01_000002 of capacity <memory:12288, vCores:1> on host nodemaster:8050, which has 2 containers, <memory:16384, vCores:2> used and <memory:16384, vCores:8> available after allocation
2020-02-06 02:00:56,676 INFO org.apache.hadoop.yarn.server.resourcemanager.scheduler.capacity.LeafQueue: assignedContainer application attempt=appattempt_1580953164575_0005_000001 container=Container: [ContainerId: container_1580953164575_0005_01_000002, NodeId: nodemaster:8050, NodeHttpAddress: nodemaster:8042, Resource: <memory:12288, vCores:1>, Priority: 1, Token: null, ] queue=default: capacity=1.0, absoluteCapacity=1.0, usedResources=<memory:4096, vCores:1>, usedCapacity=0.125, absoluteUsedCapacity=0.125, numApps=1, numContainers=1 clusterResource=<memory:32768, vCores:10> type=OFF_SWITCH requestedPartition=
2020-02-06 02:00:56,676 INFO org.apache.hadoop.yarn.server.resourcemanager.scheduler.capacity.ParentQueue: Re-sorting assigned queue: root.default stats: default: capacity=1.0, absoluteCapacity=1.0, usedResources=<memory:16384, vCores:2>, usedCapacity=0.5, absoluteUsedCapacity=0.5, numApps=1, numContainers=2
2020-02-06 02:00:56,676 INFO org.apache.hadoop.yarn.server.resourcemanager.scheduler.capacity.ParentQueue: assignedContainer queue=root usedCapacity=0.5 absoluteUsedCapacity=0.5 used=<memory:16384, vCores:2> cluster=<memory:32768, vCores:10>
2020-02-06 02:00:56,743 INFO org.apache.hadoop.yarn.server.resourcemanager.security.NMTokenSecretManagerInRM: Sending NMToken for nodeId : nodemaster:8050 for container : container_1580953164575_0005_01_000002
2020-02-06 02:00:56,743 INFO org.apache.hadoop.yarn.server.resourcemanager.rmcontainer.RMContainerImpl: container_1580953164575_0005_01_000002 Container Transitioned from ALLOCATED to ACQUIRED
2020-02-06 02:00:57,677 INFO org.apache.hadoop.yarn.server.resourcemanager.rmcontainer.RMContainerImpl: container_1580953164575_0005_01_000002 Container Transitioned from ACQUIRED to RUNNING
2020-02-06 02:00:57,677 INFO org.apache.hadoop.yarn.server.resourcemanager.rmcontainer.RMContainerImpl: container_1580953164575_0005_01_000003 Container Transitioned from NEW to ALLOCATED
2020-02-06 02:00:57,677 INFO org.apache.hadoop.yarn.server.resourcemanager.RMAuditLogger: USER=hadoop	OPERATION=AM Allocated Container	TARGET=SchedulerApp	RESULT=SUCCESS	APPID=application_1580953164575_0005	CONTAINERID=container_1580953164575_0005_01_000003
2020-02-06 02:00:57,677 INFO org.apache.hadoop.yarn.server.resourcemanager.scheduler.SchedulerNode: Assigned container container_1580953164575_0005_01_000003 of capacity <memory:12288, vCores:1> on host nodemaster:8050, which has 3 containers, <memory:28672, vCores:3> used and <memory:4096, vCores:7> available after allocation
2020-02-06 02:00:57,677 INFO org.apache.hadoop.yarn.server.resourcemanager.scheduler.capacity.LeafQueue: assignedContainer application attempt=appattempt_1580953164575_0005_000001 container=Container: [ContainerId: container_1580953164575_0005_01_000003, NodeId: nodemaster:8050, NodeHttpAddress: nodemaster:8042, Resource: <memory:12288, vCores:1>, Priority: 1, Token: null, ] queue=default: capacity=1.0, absoluteCapacity=1.0, usedResources=<memory:16384, vCores:2>, usedCapacity=0.5, absoluteUsedCapacity=0.5, numApps=1, numContainers=2 clusterResource=<memory:32768, vCores:10> type=OFF_SWITCH requestedPartition=
2020-02-06 02:00:57,677 INFO org.apache.hadoop.yarn.server.resourcemanager.scheduler.capacity.ParentQueue: Re-sorting assigned queue: root.default stats: default: capacity=1.0, absoluteCapacity=1.0, usedResources=<memory:28672, vCores:3>, usedCapacity=0.875, absoluteUsedCapacity=0.875, numApps=1, numContainers=3
2020-02-06 02:00:57,677 INFO org.apache.hadoop.yarn.server.resourcemanager.scheduler.capacity.ParentQueue: assignedContainer queue=root usedCapacity=0.875 absoluteUsedCapacity=0.875 used=<memory:28672, vCores:3> cluster=<memory:32768, vCores:10>
2020-02-06 02:00:59,156 INFO org.apache.hadoop.yarn.server.resourcemanager.rmcontainer.RMContainerImpl: container_1580953164575_0005_01_000003 Container Transitioned from ALLOCATED to ACQUIRED
2020-02-06 02:00:59,678 INFO org.apache.hadoop.yarn.server.resourcemanager.rmcontainer.RMContainerImpl: container_1580953164575_0005_01_000003 Container Transitioned from ACQUIRED to RUNNING
2020-02-06 02:01:02,159 INFO org.apache.hadoop.yarn.server.resourcemanager.scheduler.AppSchedulingInfo: checking for deactivate of application :application_1580953164575_0005
2020-02-06 02:01:02,207 INFO org.apache.hadoop.yarn.server.resourcemanager.rmapp.attempt.RMAppAttemptImpl: Updating application attempt appattempt_1580953164575_0005_000001 with final state: FINISHING, and exit status: -1000
2020-02-06 02:01:02,207 INFO org.apache.hadoop.yarn.server.resourcemanager.rmapp.attempt.RMAppAttemptImpl: appattempt_1580953164575_0005_000001 State change from RUNNING to FINAL_SAVING
2020-02-06 02:01:02,207 INFO org.apache.hadoop.yarn.server.resourcemanager.rmapp.RMAppImpl: Updating application application_1580953164575_0005 with final state: FINISHING
2020-02-06 02:01:02,207 INFO org.apache.hadoop.yarn.server.resourcemanager.rmapp.RMAppImpl: application_1580953164575_0005 State change from RUNNING to FINAL_SAVING on event=ATTEMPT_UNREGISTERED
2020-02-06 02:01:02,207 INFO org.apache.hadoop.yarn.server.resourcemanager.recovery.RMStateStore: Updating info for app: application_1580953164575_0005
2020-02-06 02:01:02,207 INFO org.apache.hadoop.yarn.server.resourcemanager.rmapp.attempt.RMAppAttemptImpl: appattempt_1580953164575_0005_000001 State change from FINAL_SAVING to FINISHING
2020-02-06 02:01:02,208 INFO org.apache.hadoop.yarn.server.resourcemanager.rmapp.RMAppImpl: application_1580953164575_0005 State change from FINAL_SAVING to FINISHING on event=APP_UPDATE_SAVED
2020-02-06 02:01:02,223 INFO org.apache.hadoop.yarn.server.resourcemanager.rmcontainer.RMContainerImpl: container_1580953164575_0005_01_000002 Container Transitioned from RUNNING to COMPLETED
2020-02-06 02:01:02,223 INFO org.apache.hadoop.yarn.server.resourcemanager.scheduler.common.fica.FiCaSchedulerApp: Completed container: container_1580953164575_0005_01_000002 in state: COMPLETED event:FINISHED
2020-02-06 02:01:02,223 INFO org.apache.hadoop.yarn.server.resourcemanager.RMAuditLogger: USER=hadoop	OPERATION=AM Released Container	TARGET=SchedulerApp	RESULT=SUCCESS	APPID=application_1580953164575_0005	CONTAINERID=container_1580953164575_0005_01_000002
2020-02-06 02:01:02,223 INFO org.apache.hadoop.yarn.server.resourcemanager.scheduler.SchedulerNode: Released container container_1580953164575_0005_01_000002 of capacity <memory:12288, vCores:1> on host nodemaster:8050, which currently has 2 containers, <memory:16384, vCores:2> used and <memory:16384, vCores:8> available, release resources=true
2020-02-06 02:01:02,223 INFO org.apache.hadoop.yarn.server.resourcemanager.scheduler.capacity.LeafQueue: default used=<memory:16384, vCores:2> numContainers=2 user=hadoop user-resources=<memory:16384, vCores:2>
2020-02-06 02:01:02,223 INFO org.apache.hadoop.yarn.server.resourcemanager.scheduler.capacity.LeafQueue: completedContainer container=Container: [ContainerId: container_1580953164575_0005_01_000002, NodeId: nodemaster:8050, NodeHttpAddress: nodemaster:8042, Resource: <memory:12288, vCores:1>, Priority: 1, Token: Token { kind: ContainerToken, service: 172.28.1.15:8050 }, ] queue=default: capacity=1.0, absoluteCapacity=1.0, usedResources=<memory:16384, vCores:2>, usedCapacity=0.5, absoluteUsedCapacity=0.5, numApps=1, numContainers=2 cluster=<memory:32768, vCores:10>
2020-02-06 02:01:02,223 INFO org.apache.hadoop.yarn.server.resourcemanager.scheduler.capacity.ParentQueue: completedContainer queue=root usedCapacity=0.5 absoluteUsedCapacity=0.5 used=<memory:16384, vCores:2> cluster=<memory:32768, vCores:10>
2020-02-06 02:01:02,223 INFO org.apache.hadoop.yarn.server.resourcemanager.scheduler.capacity.ParentQueue: Re-sorting completed queue: root.default stats: default: capacity=1.0, absoluteCapacity=1.0, usedResources=<memory:16384, vCores:2>, usedCapacity=0.5, absoluteUsedCapacity=0.5, numApps=1, numContainers=2
2020-02-06 02:01:02,223 INFO org.apache.hadoop.yarn.server.resourcemanager.scheduler.capacity.CapacityScheduler: Application attempt appattempt_1580953164575_0005_000001 released container container_1580953164575_0005_01_000002 on node: host: nodemaster:8050 #containers=2 available=<memory:16384, vCores:8> used=<memory:16384, vCores:2> with event: FINISHED
2020-02-06 02:01:02,310 INFO org.apache.hadoop.yarn.server.resourcemanager.ApplicationMasterService: application_1580953164575_0005 unregistered successfully. 
2020-02-06 02:01:02,561 INFO org.apache.hadoop.yarn.server.resourcemanager.rmcontainer.RMContainerImpl: container_1580953164575_0005_01_000003 Container Transitioned from RUNNING to COMPLETED
2020-02-06 02:01:02,561 INFO org.apache.hadoop.yarn.server.resourcemanager.scheduler.common.fica.FiCaSchedulerApp: Completed container: container_1580953164575_0005_01_000003 in state: COMPLETED event:FINISHED
2020-02-06 02:01:02,561 INFO org.apache.hadoop.yarn.server.resourcemanager.RMAuditLogger: USER=hadoop	OPERATION=AM Released Container	TARGET=SchedulerApp	RESULT=SUCCESS	APPID=application_1580953164575_0005	CONTAINERID=container_1580953164575_0005_01_000003
2020-02-06 02:01:02,561 INFO org.apache.hadoop.yarn.server.resourcemanager.scheduler.SchedulerNode: Released container container_1580953164575_0005_01_000003 of capacity <memory:12288, vCores:1> on host nodemaster:8050, which currently has 1 containers, <memory:4096, vCores:1> used and <memory:28672, vCores:9> available, release resources=true
2020-02-06 02:01:02,562 INFO org.apache.hadoop.yarn.server.resourcemanager.scheduler.capacity.LeafQueue: default used=<memory:4096, vCores:1> numContainers=1 user=hadoop user-resources=<memory:4096, vCores:1>
2020-02-06 02:01:02,562 INFO org.apache.hadoop.yarn.server.resourcemanager.scheduler.capacity.LeafQueue: completedContainer container=Container: [ContainerId: container_1580953164575_0005_01_000003, NodeId: nodemaster:8050, NodeHttpAddress: nodemaster:8042, Resource: <memory:12288, vCores:1>, Priority: 1, Token: Token { kind: ContainerToken, service: 172.28.1.15:8050 }, ] queue=default: capacity=1.0, absoluteCapacity=1.0, usedResources=<memory:4096, vCores:1>, usedCapacity=0.125, absoluteUsedCapacity=0.125, numApps=1, numContainers=1 cluster=<memory:32768, vCores:10>
2020-02-06 02:01:02,562 INFO org.apache.hadoop.yarn.server.resourcemanager.scheduler.capacity.ParentQueue: completedContainer queue=root usedCapacity=0.125 absoluteUsedCapacity=0.125 used=<memory:4096, vCores:1> cluster=<memory:32768, vCores:10>
2020-02-06 02:01:02,562 INFO org.apache.hadoop.yarn.server.resourcemanager.scheduler.capacity.ParentQueue: Re-sorting completed queue: root.default stats: default: capacity=1.0, absoluteCapacity=1.0, usedResources=<memory:4096, vCores:1>, usedCapacity=0.125, absoluteUsedCapacity=0.125, numApps=1, numContainers=1
2020-02-06 02:01:02,562 INFO org.apache.hadoop.yarn.server.resourcemanager.scheduler.capacity.CapacityScheduler: Application attempt appattempt_1580953164575_0005_000001 released container container_1580953164575_0005_01_000003 on node: host: nodemaster:8050 #containers=1 available=<memory:28672, vCores:9> used=<memory:4096, vCores:1> with event: FINISHED
2020-02-06 02:01:02,720 INFO org.apache.hadoop.yarn.server.resourcemanager.rmcontainer.RMContainerImpl: container_1580953164575_0005_01_000001 Container Transitioned from RUNNING to COMPLETED
2020-02-06 02:01:02,720 INFO org.apache.hadoop.yarn.server.resourcemanager.scheduler.common.fica.FiCaSchedulerApp: Completed container: container_1580953164575_0005_01_000001 in state: COMPLETED event:FINISHED
2020-02-06 02:01:02,720 INFO org.apache.hadoop.yarn.server.resourcemanager.ApplicationMasterService: Unregistering app attempt : appattempt_1580953164575_0005_000001
2020-02-06 02:01:02,720 INFO org.apache.hadoop.yarn.server.resourcemanager.RMAuditLogger: USER=hadoop	OPERATION=AM Released Container	TARGET=SchedulerApp	RESULT=SUCCESS	APPID=application_1580953164575_0005	CONTAINERID=container_1580953164575_0005_01_000001
2020-02-06 02:01:02,720 INFO org.apache.hadoop.yarn.server.resourcemanager.security.AMRMTokenSecretManager: Application finished, removing password for appattempt_1580953164575_0005_000001
2020-02-06 02:01:02,720 INFO org.apache.hadoop.yarn.server.resourcemanager.scheduler.SchedulerNode: Released container container_1580953164575_0005_01_000001 of capacity <memory:4096, vCores:1> on host nodemaster:8050, which currently has 0 containers, <memory:0, vCores:0> used and <memory:32768, vCores:10> available, release resources=true
2020-02-06 02:01:02,720 INFO org.apache.hadoop.yarn.server.resourcemanager.rmapp.attempt.RMAppAttemptImpl: appattempt_1580953164575_0005_000001 State change from FINISHING to FINISHED
2020-02-06 02:01:02,720 INFO org.apache.hadoop.yarn.server.resourcemanager.rmapp.RMAppImpl: application_1580953164575_0005 State change from FINISHING to FINISHED on event=ATTEMPT_FINISHED
2020-02-06 02:01:02,720 INFO org.apache.hadoop.yarn.server.resourcemanager.scheduler.capacity.LeafQueue: default used=<memory:0, vCores:0> numContainers=0 user=hadoop user-resources=<memory:0, vCores:0>
2020-02-06 02:01:02,720 INFO org.apache.hadoop.yarn.server.resourcemanager.RMAuditLogger: USER=hadoop	OPERATION=Application Finished - Succeeded	TARGET=RMAppManager	RESULT=SUCCESS	APPID=application_1580953164575_0005
2020-02-06 02:01:02,720 INFO org.apache.hadoop.yarn.server.resourcemanager.scheduler.capacity.LeafQueue: completedContainer container=Container: [ContainerId: container_1580953164575_0005_01_000001, NodeId: nodemaster:8050, NodeHttpAddress: nodemaster:8042, Resource: <memory:4096, vCores:1>, Priority: 0, Token: Token { kind: ContainerToken, service: 172.28.1.15:8050 }, ] queue=default: capacity=1.0, absoluteCapacity=1.0, usedResources=<memory:0, vCores:0>, usedCapacity=0.0, absoluteUsedCapacity=0.0, numApps=1, numContainers=0 cluster=<memory:32768, vCores:10>
2020-02-06 02:01:02,720 INFO org.apache.hadoop.yarn.server.resourcemanager.scheduler.capacity.ParentQueue: completedContainer queue=root usedCapacity=0.0 absoluteUsedCapacity=0.0 used=<memory:0, vCores:0> cluster=<memory:32768, vCores:10>
2020-02-06 02:01:02,720 INFO org.apache.hadoop.yarn.server.resourcemanager.scheduler.capacity.ParentQueue: Re-sorting completed queue: root.default stats: default: capacity=1.0, absoluteCapacity=1.0, usedResources=<memory:0, vCores:0>, usedCapacity=0.0, absoluteUsedCapacity=0.0, numApps=1, numContainers=0
2020-02-06 02:01:02,721 INFO org.apache.hadoop.yarn.server.resourcemanager.scheduler.capacity.CapacityScheduler: Application attempt appattempt_1580953164575_0005_000001 released container container_1580953164575_0005_01_000001 on node: host: nodemaster:8050 #containers=0 available=<memory:32768, vCores:10> used=<memory:0, vCores:0> with event: FINISHED
2020-02-06 02:01:02,721 INFO org.apache.hadoop.yarn.server.resourcemanager.scheduler.capacity.CapacityScheduler: Application Attempt appattempt_1580953164575_0005_000001 is done. finalState=FINISHED
2020-02-06 02:01:02,721 INFO org.apache.hadoop.yarn.server.resourcemanager.RMAppManager$ApplicationSummary: appId=application_1580953164575_0005,name=gen,user=hadoop,queue=default,state=FINISHED,trackingUrl=http://nodemaster:8088/proxy/application_1580953164575_0005/,appMasterHost=172.28.1.15,startTime=1580954453042,finishTime=1580954462207,finalStatus=SUCCEEDED,memorySeconds=165231,vcoreSeconds=18,preemptedAMContainers=0,preemptedNonAMContainers=0,preemptedResources=<memory:0\, vCores:0>,applicationType=SPARK
2020-02-06 02:01:02,721 INFO org.apache.hadoop.yarn.server.resourcemanager.scheduler.AppSchedulingInfo: Application application_1580953164575_0005 requests cleared
2020-02-06 02:01:02,721 INFO org.apache.hadoop.yarn.server.resourcemanager.scheduler.capacity.LeafQueue: Application removed - appId: application_1580953164575_0005 user: hadoop queue: default #user-pending-applications: 0 #user-active-applications: 0 #queue-pending-applications: 0 #queue-active-applications: 0
2020-02-06 02:01:02,722 INFO org.apache.hadoop.yarn.server.resourcemanager.scheduler.capacity.ParentQueue: Application removed - appId: application_1580953164575_0005 user: hadoop leaf-queue of parent: root #applications: 0
2020-02-06 02:01:02,722 INFO org.apache.hadoop.yarn.server.resourcemanager.amlauncher.AMLauncher: Cleaning master appattempt_1580953164575_0005_000001
2020-02-06 02:01:04,725 INFO org.apache.hadoop.yarn.server.resourcemanager.scheduler.capacity.CapacityScheduler: Null container completed...
2020-02-06 02:01:04,726 INFO org.apache.hadoop.yarn.server.resourcemanager.scheduler.capacity.CapacityScheduler: Null container completed...
2020-02-06 02:04:30,743 INFO org.apache.hadoop.yarn.server.resourcemanager.ClientRMService: Allocated new applicationId: 6
2020-02-06 02:04:33,678 WARN org.apache.hadoop.yarn.server.resourcemanager.rmapp.RMAppImpl: The specific max attempts: 0 for application: 6 is invalid, because it is out of the range [1, 2]. Use the global max attempts instead.
2020-02-06 02:04:33,678 INFO org.apache.hadoop.yarn.server.resourcemanager.ClientRMService: Application with id 6 submitted by user hadoop
2020-02-06 02:04:33,678 INFO org.apache.hadoop.yarn.server.resourcemanager.rmapp.RMAppImpl: Storing application with id application_1580953164575_0006
2020-02-06 02:04:33,678 INFO org.apache.hadoop.yarn.server.resourcemanager.RMAuditLogger: USER=hadoop	IP=172.28.1.15	OPERATION=Submit Application Request	TARGET=ClientRMService	RESULT=SUCCESS	APPID=application_1580953164575_0006
2020-02-06 02:04:33,678 INFO org.apache.hadoop.yarn.server.resourcemanager.rmapp.RMAppImpl: application_1580953164575_0006 State change from NEW to NEW_SAVING on event=START
2020-02-06 02:04:33,678 INFO org.apache.hadoop.yarn.server.resourcemanager.recovery.RMStateStore: Storing info for app: application_1580953164575_0006
2020-02-06 02:04:33,678 INFO org.apache.hadoop.yarn.server.resourcemanager.rmapp.RMAppImpl: application_1580953164575_0006 State change from NEW_SAVING to SUBMITTED on event=APP_NEW_SAVED
2020-02-06 02:04:33,678 INFO org.apache.hadoop.yarn.server.resourcemanager.scheduler.capacity.ParentQueue: Application added - appId: application_1580953164575_0006 user: hadoop leaf-queue of parent: root #applications: 1
2020-02-06 02:04:33,678 INFO org.apache.hadoop.yarn.server.resourcemanager.scheduler.capacity.CapacityScheduler: Accepted application application_1580953164575_0006 from user: hadoop, in queue: default
2020-02-06 02:04:33,678 INFO org.apache.hadoop.yarn.server.resourcemanager.rmapp.RMAppImpl: application_1580953164575_0006 State change from SUBMITTED to ACCEPTED on event=APP_ACCEPTED
2020-02-06 02:04:33,679 INFO org.apache.hadoop.yarn.server.resourcemanager.ApplicationMasterService: Registering app attempt : appattempt_1580953164575_0006_000001
2020-02-06 02:04:33,679 INFO org.apache.hadoop.yarn.server.resourcemanager.rmapp.attempt.RMAppAttemptImpl: appattempt_1580953164575_0006_000001 State change from NEW to SUBMITTED
2020-02-06 02:04:33,679 INFO org.apache.hadoop.yarn.server.resourcemanager.scheduler.capacity.LeafQueue: Application application_1580953164575_0006 from user: hadoop activated in queue: default
2020-02-06 02:04:33,679 INFO org.apache.hadoop.yarn.server.resourcemanager.scheduler.capacity.LeafQueue: Application added - appId: application_1580953164575_0006 user: org.apache.hadoop.yarn.server.resourcemanager.scheduler.capacity.LeafQueue$User@6df3753, leaf-queue: default #user-pending-applications: 0 #user-active-applications: 1 #queue-pending-applications: 0 #queue-active-applications: 1
2020-02-06 02:04:33,679 INFO org.apache.hadoop.yarn.server.resourcemanager.scheduler.capacity.CapacityScheduler: Added Application Attempt appattempt_1580953164575_0006_000001 to scheduler from user hadoop in queue default
2020-02-06 02:04:33,679 INFO org.apache.hadoop.yarn.server.resourcemanager.rmapp.attempt.RMAppAttemptImpl: appattempt_1580953164575_0006_000001 State change from SUBMITTED to SCHEDULED
2020-02-06 02:04:34,002 INFO org.apache.hadoop.yarn.server.resourcemanager.rmcontainer.RMContainerImpl: container_1580953164575_0006_01_000001 Container Transitioned from NEW to ALLOCATED
2020-02-06 02:04:34,002 INFO org.apache.hadoop.yarn.server.resourcemanager.RMAuditLogger: USER=hadoop	OPERATION=AM Allocated Container	TARGET=SchedulerApp	RESULT=SUCCESS	APPID=application_1580953164575_0006	CONTAINERID=container_1580953164575_0006_01_000001
2020-02-06 02:04:34,002 INFO org.apache.hadoop.yarn.server.resourcemanager.scheduler.SchedulerNode: Assigned container container_1580953164575_0006_01_000001 of capacity <memory:4096, vCores:1> on host nodemaster:8050, which has 1 containers, <memory:4096, vCores:1> used and <memory:28672, vCores:9> available after allocation
2020-02-06 02:04:34,002 INFO org.apache.hadoop.yarn.server.resourcemanager.scheduler.capacity.LeafQueue: assignedContainer application attempt=appattempt_1580953164575_0006_000001 container=Container: [ContainerId: container_1580953164575_0006_01_000001, NodeId: nodemaster:8050, NodeHttpAddress: nodemaster:8042, Resource: <memory:4096, vCores:1>, Priority: 0, Token: null, ] queue=default: capacity=1.0, absoluteCapacity=1.0, usedResources=<memory:0, vCores:0>, usedCapacity=0.0, absoluteUsedCapacity=0.0, numApps=1, numContainers=0 clusterResource=<memory:32768, vCores:10> type=OFF_SWITCH requestedPartition=
2020-02-06 02:04:34,002 INFO org.apache.hadoop.yarn.server.resourcemanager.scheduler.capacity.ParentQueue: Re-sorting assigned queue: root.default stats: default: capacity=1.0, absoluteCapacity=1.0, usedResources=<memory:4096, vCores:1>, usedCapacity=0.125, absoluteUsedCapacity=0.125, numApps=1, numContainers=1
2020-02-06 02:04:34,002 INFO org.apache.hadoop.yarn.server.resourcemanager.scheduler.capacity.ParentQueue: assignedContainer queue=root usedCapacity=0.125 absoluteUsedCapacity=0.125 used=<memory:4096, vCores:1> cluster=<memory:32768, vCores:10>
2020-02-06 02:04:34,003 INFO org.apache.hadoop.yarn.server.resourcemanager.security.NMTokenSecretManagerInRM: Sending NMToken for nodeId : nodemaster:8050 for container : container_1580953164575_0006_01_000001
2020-02-06 02:04:34,003 INFO org.apache.hadoop.yarn.server.resourcemanager.rmcontainer.RMContainerImpl: container_1580953164575_0006_01_000001 Container Transitioned from ALLOCATED to ACQUIRED
2020-02-06 02:04:34,003 INFO org.apache.hadoop.yarn.server.resourcemanager.security.NMTokenSecretManagerInRM: Clear node set for appattempt_1580953164575_0006_000001
2020-02-06 02:04:34,003 INFO org.apache.hadoop.yarn.server.resourcemanager.rmapp.attempt.RMAppAttemptImpl: Storing attempt: AppId: application_1580953164575_0006 AttemptId: appattempt_1580953164575_0006_000001 MasterContainer: Container: [ContainerId: container_1580953164575_0006_01_000001, NodeId: nodemaster:8050, NodeHttpAddress: nodemaster:8042, Resource: <memory:4096, vCores:1>, Priority: 0, Token: Token { kind: ContainerToken, service: 172.28.1.15:8050 }, ]
2020-02-06 02:04:34,003 INFO org.apache.hadoop.yarn.server.resourcemanager.rmapp.attempt.RMAppAttemptImpl: appattempt_1580953164575_0006_000001 State change from SCHEDULED to ALLOCATED_SAVING
2020-02-06 02:04:34,003 INFO org.apache.hadoop.yarn.server.resourcemanager.rmapp.attempt.RMAppAttemptImpl: appattempt_1580953164575_0006_000001 State change from ALLOCATED_SAVING to ALLOCATED
2020-02-06 02:04:34,004 INFO org.apache.hadoop.yarn.server.resourcemanager.amlauncher.AMLauncher: Launching masterappattempt_1580953164575_0006_000001
2020-02-06 02:04:34,005 INFO org.apache.hadoop.yarn.server.resourcemanager.amlauncher.AMLauncher: Setting up container Container: [ContainerId: container_1580953164575_0006_01_000001, NodeId: nodemaster:8050, NodeHttpAddress: nodemaster:8042, Resource: <memory:4096, vCores:1>, Priority: 0, Token: Token { kind: ContainerToken, service: 172.28.1.15:8050 }, ] for AM appattempt_1580953164575_0006_000001
2020-02-06 02:04:34,005 INFO org.apache.hadoop.yarn.server.resourcemanager.amlauncher.AMLauncher: Command to launch container container_1580953164575_0006_01_000001 : {{JAVA_HOME}}/bin/java,-server,-Xmx512m,-Djava.io.tmpdir={{PWD}}/tmp,-Dspark.yarn.app.container.log.dir=<LOG_DIR>,org.apache.spark.deploy.yarn.ExecutorLauncher,--arg,'nodemaster:41073',--properties-file,{{PWD}}/__spark_conf__/__spark_conf__.properties,1>,<LOG_DIR>/stdout,2>,<LOG_DIR>/stderr
2020-02-06 02:04:34,005 INFO org.apache.hadoop.yarn.server.resourcemanager.security.AMRMTokenSecretManager: Create AMRMToken for ApplicationAttempt: appattempt_1580953164575_0006_000001
2020-02-06 02:04:34,005 INFO org.apache.hadoop.yarn.server.resourcemanager.security.AMRMTokenSecretManager: Creating password for appattempt_1580953164575_0006_000001
2020-02-06 02:04:34,013 INFO org.apache.hadoop.yarn.server.resourcemanager.amlauncher.AMLauncher: Done launching container Container: [ContainerId: container_1580953164575_0006_01_000001, NodeId: nodemaster:8050, NodeHttpAddress: nodemaster:8042, Resource: <memory:4096, vCores:1>, Priority: 0, Token: Token { kind: ContainerToken, service: 172.28.1.15:8050 }, ] for AM appattempt_1580953164575_0006_000001
2020-02-06 02:04:34,013 INFO org.apache.hadoop.yarn.server.resourcemanager.rmapp.attempt.RMAppAttemptImpl: appattempt_1580953164575_0006_000001 State change from ALLOCATED to LAUNCHED
2020-02-06 02:04:35,003 INFO org.apache.hadoop.yarn.server.resourcemanager.rmcontainer.RMContainerImpl: container_1580953164575_0006_01_000001 Container Transitioned from ACQUIRED to RUNNING
2020-02-06 02:04:36,329 INFO SecurityLogger.org.apache.hadoop.ipc.Server: Auth successful for appattempt_1580953164575_0006_000001 (auth:SIMPLE)
2020-02-06 02:04:36,331 INFO org.apache.hadoop.yarn.server.resourcemanager.ApplicationMasterService: AM registration appattempt_1580953164575_0006_000001
2020-02-06 02:04:36,331 INFO org.apache.hadoop.yarn.server.resourcemanager.RMAuditLogger: USER=hadoop	IP=172.28.1.15	OPERATION=Register App Master	TARGET=ApplicationMasterService	RESULT=SUCCESS	APPID=application_1580953164575_0006	APPATTEMPTID=appattempt_1580953164575_0006_000001
2020-02-06 02:04:36,331 INFO org.apache.hadoop.yarn.server.resourcemanager.rmapp.attempt.RMAppAttemptImpl: appattempt_1580953164575_0006_000001 State change from LAUNCHED to RUNNING
2020-02-06 02:04:36,331 INFO org.apache.hadoop.yarn.server.resourcemanager.rmapp.RMAppImpl: application_1580953164575_0006 State change from ACCEPTED to RUNNING on event=ATTEMPT_REGISTERED
2020-02-06 02:04:37,004 INFO org.apache.hadoop.yarn.server.resourcemanager.rmcontainer.RMContainerImpl: container_1580953164575_0006_01_000002 Container Transitioned from NEW to ALLOCATED
2020-02-06 02:04:37,005 INFO org.apache.hadoop.yarn.server.resourcemanager.RMAuditLogger: USER=hadoop	OPERATION=AM Allocated Container	TARGET=SchedulerApp	RESULT=SUCCESS	APPID=application_1580953164575_0006	CONTAINERID=container_1580953164575_0006_01_000002
2020-02-06 02:04:37,005 INFO org.apache.hadoop.yarn.server.resourcemanager.scheduler.SchedulerNode: Assigned container container_1580953164575_0006_01_000002 of capacity <memory:12288, vCores:1> on host nodemaster:8050, which has 2 containers, <memory:16384, vCores:2> used and <memory:16384, vCores:8> available after allocation
2020-02-06 02:04:37,005 INFO org.apache.hadoop.yarn.server.resourcemanager.scheduler.capacity.LeafQueue: assignedContainer application attempt=appattempt_1580953164575_0006_000001 container=Container: [ContainerId: container_1580953164575_0006_01_000002, NodeId: nodemaster:8050, NodeHttpAddress: nodemaster:8042, Resource: <memory:12288, vCores:1>, Priority: 1, Token: null, ] queue=default: capacity=1.0, absoluteCapacity=1.0, usedResources=<memory:4096, vCores:1>, usedCapacity=0.125, absoluteUsedCapacity=0.125, numApps=1, numContainers=1 clusterResource=<memory:32768, vCores:10> type=OFF_SWITCH requestedPartition=
2020-02-06 02:04:37,005 INFO org.apache.hadoop.yarn.server.resourcemanager.scheduler.capacity.ParentQueue: Re-sorting assigned queue: root.default stats: default: capacity=1.0, absoluteCapacity=1.0, usedResources=<memory:16384, vCores:2>, usedCapacity=0.5, absoluteUsedCapacity=0.5, numApps=1, numContainers=2
2020-02-06 02:04:37,005 INFO org.apache.hadoop.yarn.server.resourcemanager.scheduler.capacity.ParentQueue: assignedContainer queue=root usedCapacity=0.5 absoluteUsedCapacity=0.5 used=<memory:16384, vCores:2> cluster=<memory:32768, vCores:10>
2020-02-06 02:04:37,008 INFO org.apache.hadoop.yarn.server.resourcemanager.security.NMTokenSecretManagerInRM: Sending NMToken for nodeId : nodemaster:8050 for container : container_1580953164575_0006_01_000002
2020-02-06 02:04:37,008 INFO org.apache.hadoop.yarn.server.resourcemanager.rmcontainer.RMContainerImpl: container_1580953164575_0006_01_000002 Container Transitioned from ALLOCATED to ACQUIRED
2020-02-06 02:04:38,004 INFO org.apache.hadoop.yarn.server.resourcemanager.rmcontainer.RMContainerImpl: container_1580953164575_0006_01_000002 Container Transitioned from ACQUIRED to RUNNING
2020-02-06 02:04:38,005 INFO org.apache.hadoop.yarn.server.resourcemanager.rmcontainer.RMContainerImpl: container_1580953164575_0006_01_000003 Container Transitioned from NEW to ALLOCATED
2020-02-06 02:04:38,005 INFO org.apache.hadoop.yarn.server.resourcemanager.RMAuditLogger: USER=hadoop	OPERATION=AM Allocated Container	TARGET=SchedulerApp	RESULT=SUCCESS	APPID=application_1580953164575_0006	CONTAINERID=container_1580953164575_0006_01_000003
2020-02-06 02:04:38,005 INFO org.apache.hadoop.yarn.server.resourcemanager.scheduler.SchedulerNode: Assigned container container_1580953164575_0006_01_000003 of capacity <memory:12288, vCores:1> on host nodemaster:8050, which has 3 containers, <memory:28672, vCores:3> used and <memory:4096, vCores:7> available after allocation
2020-02-06 02:04:38,005 INFO org.apache.hadoop.yarn.server.resourcemanager.scheduler.capacity.LeafQueue: assignedContainer application attempt=appattempt_1580953164575_0006_000001 container=Container: [ContainerId: container_1580953164575_0006_01_000003, NodeId: nodemaster:8050, NodeHttpAddress: nodemaster:8042, Resource: <memory:12288, vCores:1>, Priority: 1, Token: null, ] queue=default: capacity=1.0, absoluteCapacity=1.0, usedResources=<memory:16384, vCores:2>, usedCapacity=0.5, absoluteUsedCapacity=0.5, numApps=1, numContainers=2 clusterResource=<memory:32768, vCores:10> type=OFF_SWITCH requestedPartition=
2020-02-06 02:04:38,005 INFO org.apache.hadoop.yarn.server.resourcemanager.scheduler.capacity.ParentQueue: Re-sorting assigned queue: root.default stats: default: capacity=1.0, absoluteCapacity=1.0, usedResources=<memory:28672, vCores:3>, usedCapacity=0.875, absoluteUsedCapacity=0.875, numApps=1, numContainers=3
2020-02-06 02:04:38,005 INFO org.apache.hadoop.yarn.server.resourcemanager.scheduler.capacity.ParentQueue: assignedContainer queue=root usedCapacity=0.875 absoluteUsedCapacity=0.875 used=<memory:28672, vCores:3> cluster=<memory:32768, vCores:10>
2020-02-06 02:04:39,419 INFO org.apache.hadoop.yarn.server.resourcemanager.rmcontainer.RMContainerImpl: container_1580953164575_0006_01_000003 Container Transitioned from ALLOCATED to ACQUIRED
2020-02-06 02:04:40,006 INFO org.apache.hadoop.yarn.server.resourcemanager.rmcontainer.RMContainerImpl: container_1580953164575_0006_01_000003 Container Transitioned from ACQUIRED to RUNNING
2020-02-06 02:04:42,337 INFO org.apache.hadoop.yarn.server.resourcemanager.scheduler.AppSchedulingInfo: checking for deactivate of application :application_1580953164575_0006
2020-02-06 02:04:42,378 INFO org.apache.hadoop.yarn.server.resourcemanager.rmapp.attempt.RMAppAttemptImpl: Updating application attempt appattempt_1580953164575_0006_000001 with final state: FINISHING, and exit status: -1000
2020-02-06 02:04:42,378 INFO org.apache.hadoop.yarn.server.resourcemanager.rmapp.attempt.RMAppAttemptImpl: appattempt_1580953164575_0006_000001 State change from RUNNING to FINAL_SAVING
2020-02-06 02:04:42,378 INFO org.apache.hadoop.yarn.server.resourcemanager.rmapp.RMAppImpl: Updating application application_1580953164575_0006 with final state: FINISHING
2020-02-06 02:04:42,378 INFO org.apache.hadoop.yarn.server.resourcemanager.rmapp.RMAppImpl: application_1580953164575_0006 State change from RUNNING to FINAL_SAVING on event=ATTEMPT_UNREGISTERED
2020-02-06 02:04:42,378 INFO org.apache.hadoop.yarn.server.resourcemanager.recovery.RMStateStore: Updating info for app: application_1580953164575_0006
2020-02-06 02:04:42,378 INFO org.apache.hadoop.yarn.server.resourcemanager.rmapp.attempt.RMAppAttemptImpl: appattempt_1580953164575_0006_000001 State change from FINAL_SAVING to FINISHING
2020-02-06 02:04:42,378 INFO org.apache.hadoop.yarn.server.resourcemanager.rmapp.RMAppImpl: application_1580953164575_0006 State change from FINAL_SAVING to FINISHING on event=APP_UPDATE_SAVED
2020-02-06 02:04:42,401 INFO org.apache.hadoop.yarn.server.resourcemanager.rmcontainer.RMContainerImpl: container_1580953164575_0006_01_000002 Container Transitioned from RUNNING to COMPLETED
2020-02-06 02:04:42,401 INFO org.apache.hadoop.yarn.server.resourcemanager.scheduler.common.fica.FiCaSchedulerApp: Completed container: container_1580953164575_0006_01_000002 in state: COMPLETED event:FINISHED
2020-02-06 02:04:42,401 INFO org.apache.hadoop.yarn.server.resourcemanager.RMAuditLogger: USER=hadoop	OPERATION=AM Released Container	TARGET=SchedulerApp	RESULT=SUCCESS	APPID=application_1580953164575_0006	CONTAINERID=container_1580953164575_0006_01_000002
2020-02-06 02:04:42,401 INFO org.apache.hadoop.yarn.server.resourcemanager.scheduler.SchedulerNode: Released container container_1580953164575_0006_01_000002 of capacity <memory:12288, vCores:1> on host nodemaster:8050, which currently has 2 containers, <memory:16384, vCores:2> used and <memory:16384, vCores:8> available, release resources=true
2020-02-06 02:04:42,401 INFO org.apache.hadoop.yarn.server.resourcemanager.scheduler.capacity.LeafQueue: default used=<memory:16384, vCores:2> numContainers=2 user=hadoop user-resources=<memory:16384, vCores:2>
2020-02-06 02:04:42,402 INFO org.apache.hadoop.yarn.server.resourcemanager.scheduler.capacity.LeafQueue: completedContainer container=Container: [ContainerId: container_1580953164575_0006_01_000002, NodeId: nodemaster:8050, NodeHttpAddress: nodemaster:8042, Resource: <memory:12288, vCores:1>, Priority: 1, Token: Token { kind: ContainerToken, service: 172.28.1.15:8050 }, ] queue=default: capacity=1.0, absoluteCapacity=1.0, usedResources=<memory:16384, vCores:2>, usedCapacity=0.5, absoluteUsedCapacity=0.5, numApps=1, numContainers=2 cluster=<memory:32768, vCores:10>
2020-02-06 02:04:42,402 INFO org.apache.hadoop.yarn.server.resourcemanager.scheduler.capacity.ParentQueue: completedContainer queue=root usedCapacity=0.5 absoluteUsedCapacity=0.5 used=<memory:16384, vCores:2> cluster=<memory:32768, vCores:10>
2020-02-06 02:04:42,402 INFO org.apache.hadoop.yarn.server.resourcemanager.scheduler.capacity.ParentQueue: Re-sorting completed queue: root.default stats: default: capacity=1.0, absoluteCapacity=1.0, usedResources=<memory:16384, vCores:2>, usedCapacity=0.5, absoluteUsedCapacity=0.5, numApps=1, numContainers=2
2020-02-06 02:04:42,402 INFO org.apache.hadoop.yarn.server.resourcemanager.scheduler.capacity.CapacityScheduler: Application attempt appattempt_1580953164575_0006_000001 released container container_1580953164575_0006_01_000002 on node: host: nodemaster:8050 #containers=2 available=<memory:16384, vCores:8> used=<memory:16384, vCores:2> with event: FINISHED
2020-02-06 02:04:42,480 INFO org.apache.hadoop.yarn.server.resourcemanager.ApplicationMasterService: application_1580953164575_0006 unregistered successfully. 
2020-02-06 02:04:42,745 INFO org.apache.hadoop.yarn.server.resourcemanager.rmcontainer.RMContainerImpl: container_1580953164575_0006_01_000003 Container Transitioned from RUNNING to COMPLETED
2020-02-06 02:04:42,745 INFO org.apache.hadoop.yarn.server.resourcemanager.scheduler.common.fica.FiCaSchedulerApp: Completed container: container_1580953164575_0006_01_000003 in state: COMPLETED event:FINISHED
2020-02-06 02:04:42,745 INFO org.apache.hadoop.yarn.server.resourcemanager.RMAuditLogger: USER=hadoop	OPERATION=AM Released Container	TARGET=SchedulerApp	RESULT=SUCCESS	APPID=application_1580953164575_0006	CONTAINERID=container_1580953164575_0006_01_000003
2020-02-06 02:04:42,745 INFO org.apache.hadoop.yarn.server.resourcemanager.scheduler.SchedulerNode: Released container container_1580953164575_0006_01_000003 of capacity <memory:12288, vCores:1> on host nodemaster:8050, which currently has 1 containers, <memory:4096, vCores:1> used and <memory:28672, vCores:9> available, release resources=true
2020-02-06 02:04:42,745 INFO org.apache.hadoop.yarn.server.resourcemanager.scheduler.capacity.LeafQueue: default used=<memory:4096, vCores:1> numContainers=1 user=hadoop user-resources=<memory:4096, vCores:1>
2020-02-06 02:04:42,745 INFO org.apache.hadoop.yarn.server.resourcemanager.scheduler.capacity.LeafQueue: completedContainer container=Container: [ContainerId: container_1580953164575_0006_01_000003, NodeId: nodemaster:8050, NodeHttpAddress: nodemaster:8042, Resource: <memory:12288, vCores:1>, Priority: 1, Token: Token { kind: ContainerToken, service: 172.28.1.15:8050 }, ] queue=default: capacity=1.0, absoluteCapacity=1.0, usedResources=<memory:4096, vCores:1>, usedCapacity=0.125, absoluteUsedCapacity=0.125, numApps=1, numContainers=1 cluster=<memory:32768, vCores:10>
2020-02-06 02:04:42,745 INFO org.apache.hadoop.yarn.server.resourcemanager.scheduler.capacity.ParentQueue: completedContainer queue=root usedCapacity=0.125 absoluteUsedCapacity=0.125 used=<memory:4096, vCores:1> cluster=<memory:32768, vCores:10>
2020-02-06 02:04:42,745 INFO org.apache.hadoop.yarn.server.resourcemanager.scheduler.capacity.ParentQueue: Re-sorting completed queue: root.default stats: default: capacity=1.0, absoluteCapacity=1.0, usedResources=<memory:4096, vCores:1>, usedCapacity=0.125, absoluteUsedCapacity=0.125, numApps=1, numContainers=1
2020-02-06 02:04:42,745 INFO org.apache.hadoop.yarn.server.resourcemanager.scheduler.capacity.CapacityScheduler: Application attempt appattempt_1580953164575_0006_000001 released container container_1580953164575_0006_01_000003 on node: host: nodemaster:8050 #containers=1 available=<memory:28672, vCores:9> used=<memory:4096, vCores:1> with event: FINISHED
2020-02-06 02:04:42,958 INFO org.apache.hadoop.yarn.server.resourcemanager.rmcontainer.RMContainerImpl: container_1580953164575_0006_01_000001 Container Transitioned from RUNNING to COMPLETED
2020-02-06 02:04:42,958 INFO org.apache.hadoop.yarn.server.resourcemanager.ApplicationMasterService: Unregistering app attempt : appattempt_1580953164575_0006_000001
2020-02-06 02:04:42,958 INFO org.apache.hadoop.yarn.server.resourcemanager.scheduler.common.fica.FiCaSchedulerApp: Completed container: container_1580953164575_0006_01_000001 in state: COMPLETED event:FINISHED
2020-02-06 02:04:42,958 INFO org.apache.hadoop.yarn.server.resourcemanager.security.AMRMTokenSecretManager: Application finished, removing password for appattempt_1580953164575_0006_000001
2020-02-06 02:04:42,958 INFO org.apache.hadoop.yarn.server.resourcemanager.RMAuditLogger: USER=hadoop	OPERATION=AM Released Container	TARGET=SchedulerApp	RESULT=SUCCESS	APPID=application_1580953164575_0006	CONTAINERID=container_1580953164575_0006_01_000001
2020-02-06 02:04:42,958 INFO org.apache.hadoop.yarn.server.resourcemanager.scheduler.SchedulerNode: Released container container_1580953164575_0006_01_000001 of capacity <memory:4096, vCores:1> on host nodemaster:8050, which currently has 0 containers, <memory:0, vCores:0> used and <memory:32768, vCores:10> available, release resources=true
2020-02-06 02:04:42,958 INFO org.apache.hadoop.yarn.server.resourcemanager.rmapp.attempt.RMAppAttemptImpl: appattempt_1580953164575_0006_000001 State change from FINISHING to FINISHED
2020-02-06 02:04:42,958 INFO org.apache.hadoop.yarn.server.resourcemanager.rmapp.RMAppImpl: application_1580953164575_0006 State change from FINISHING to FINISHED on event=ATTEMPT_FINISHED
2020-02-06 02:04:42,958 INFO org.apache.hadoop.yarn.server.resourcemanager.scheduler.capacity.LeafQueue: default used=<memory:0, vCores:0> numContainers=0 user=hadoop user-resources=<memory:0, vCores:0>
2020-02-06 02:04:42,958 INFO org.apache.hadoop.yarn.server.resourcemanager.RMAuditLogger: USER=hadoop	OPERATION=Application Finished - Succeeded	TARGET=RMAppManager	RESULT=SUCCESS	APPID=application_1580953164575_0006
2020-02-06 02:04:42,958 INFO org.apache.hadoop.yarn.server.resourcemanager.scheduler.capacity.LeafQueue: completedContainer container=Container: [ContainerId: container_1580953164575_0006_01_000001, NodeId: nodemaster:8050, NodeHttpAddress: nodemaster:8042, Resource: <memory:4096, vCores:1>, Priority: 0, Token: Token { kind: ContainerToken, service: 172.28.1.15:8050 }, ] queue=default: capacity=1.0, absoluteCapacity=1.0, usedResources=<memory:0, vCores:0>, usedCapacity=0.0, absoluteUsedCapacity=0.0, numApps=1, numContainers=0 cluster=<memory:32768, vCores:10>
2020-02-06 02:04:42,958 INFO org.apache.hadoop.yarn.server.resourcemanager.scheduler.capacity.ParentQueue: completedContainer queue=root usedCapacity=0.0 absoluteUsedCapacity=0.0 used=<memory:0, vCores:0> cluster=<memory:32768, vCores:10>
2020-02-06 02:04:42,958 INFO org.apache.hadoop.yarn.server.resourcemanager.scheduler.capacity.ParentQueue: Re-sorting completed queue: root.default stats: default: capacity=1.0, absoluteCapacity=1.0, usedResources=<memory:0, vCores:0>, usedCapacity=0.0, absoluteUsedCapacity=0.0, numApps=1, numContainers=0
2020-02-06 02:04:42,958 INFO org.apache.hadoop.yarn.server.resourcemanager.scheduler.capacity.CapacityScheduler: Application attempt appattempt_1580953164575_0006_000001 released container container_1580953164575_0006_01_000001 on node: host: nodemaster:8050 #containers=0 available=<memory:32768, vCores:10> used=<memory:0, vCores:0> with event: FINISHED
2020-02-06 02:04:42,958 INFO org.apache.hadoop.yarn.server.resourcemanager.RMAppManager$ApplicationSummary: appId=application_1580953164575_0006,name=gen,user=hadoop,queue=default,state=FINISHED,trackingUrl=http://nodemaster:8088/proxy/application_1580953164575_0006/,appMasterHost=172.28.1.15,startTime=1580954673678,finishTime=1580954682378,finalStatus=SUCCEEDED,memorySeconds=161246,vcoreSeconds=17,preemptedAMContainers=0,preemptedNonAMContainers=0,preemptedResources=<memory:0\, vCores:0>,applicationType=SPARK
2020-02-06 02:04:42,958 INFO org.apache.hadoop.yarn.server.resourcemanager.scheduler.capacity.CapacityScheduler: Application Attempt appattempt_1580953164575_0006_000001 is done. finalState=FINISHED
2020-02-06 02:04:42,959 INFO org.apache.hadoop.yarn.server.resourcemanager.scheduler.AppSchedulingInfo: Application application_1580953164575_0006 requests cleared
2020-02-06 02:04:42,959 INFO org.apache.hadoop.yarn.server.resourcemanager.scheduler.capacity.LeafQueue: Application removed - appId: application_1580953164575_0006 user: hadoop queue: default #user-pending-applications: 0 #user-active-applications: 0 #queue-pending-applications: 0 #queue-active-applications: 0
2020-02-06 02:04:42,959 INFO org.apache.hadoop.yarn.server.resourcemanager.amlauncher.AMLauncher: Cleaning master appattempt_1580953164575_0006_000001
2020-02-06 02:04:42,959 INFO org.apache.hadoop.yarn.server.resourcemanager.scheduler.capacity.ParentQueue: Application removed - appId: application_1580953164575_0006 user: hadoop leaf-queue of parent: root #applications: 0
2020-02-06 02:04:44,962 INFO org.apache.hadoop.yarn.server.resourcemanager.scheduler.capacity.CapacityScheduler: Null container completed...
2020-02-06 02:04:44,963 INFO org.apache.hadoop.yarn.server.resourcemanager.scheduler.capacity.CapacityScheduler: Null container completed...
2020-02-06 02:06:14,617 INFO org.apache.hadoop.yarn.server.resourcemanager.ClientRMService: Allocated new applicationId: 7
2020-02-06 02:06:17,984 WARN org.apache.hadoop.yarn.server.resourcemanager.rmapp.RMAppImpl: The specific max attempts: 0 for application: 7 is invalid, because it is out of the range [1, 2]. Use the global max attempts instead.
2020-02-06 02:06:17,984 INFO org.apache.hadoop.yarn.server.resourcemanager.ClientRMService: Application with id 7 submitted by user hadoop
2020-02-06 02:06:17,984 INFO org.apache.hadoop.yarn.server.resourcemanager.RMAuditLogger: USER=hadoop	IP=172.28.1.15	OPERATION=Submit Application Request	TARGET=ClientRMService	RESULT=SUCCESS	APPID=application_1580953164575_0007
2020-02-06 02:06:17,984 INFO org.apache.hadoop.yarn.server.resourcemanager.rmapp.RMAppImpl: Storing application with id application_1580953164575_0007
2020-02-06 02:06:17,984 INFO org.apache.hadoop.yarn.server.resourcemanager.rmapp.RMAppImpl: application_1580953164575_0007 State change from NEW to NEW_SAVING on event=START
2020-02-06 02:06:17,984 INFO org.apache.hadoop.yarn.server.resourcemanager.recovery.RMStateStore: Storing info for app: application_1580953164575_0007
2020-02-06 02:06:17,984 INFO org.apache.hadoop.yarn.server.resourcemanager.rmapp.RMAppImpl: application_1580953164575_0007 State change from NEW_SAVING to SUBMITTED on event=APP_NEW_SAVED
2020-02-06 02:06:17,984 INFO org.apache.hadoop.yarn.server.resourcemanager.scheduler.capacity.ParentQueue: Application added - appId: application_1580953164575_0007 user: hadoop leaf-queue of parent: root #applications: 1
2020-02-06 02:06:17,984 INFO org.apache.hadoop.yarn.server.resourcemanager.scheduler.capacity.CapacityScheduler: Accepted application application_1580953164575_0007 from user: hadoop, in queue: default
2020-02-06 02:06:17,984 INFO org.apache.hadoop.yarn.server.resourcemanager.rmapp.RMAppImpl: application_1580953164575_0007 State change from SUBMITTED to ACCEPTED on event=APP_ACCEPTED
2020-02-06 02:06:17,984 INFO org.apache.hadoop.yarn.server.resourcemanager.ApplicationMasterService: Registering app attempt : appattempt_1580953164575_0007_000001
2020-02-06 02:06:17,984 INFO org.apache.hadoop.yarn.server.resourcemanager.rmapp.attempt.RMAppAttemptImpl: appattempt_1580953164575_0007_000001 State change from NEW to SUBMITTED
2020-02-06 02:06:17,985 INFO org.apache.hadoop.yarn.server.resourcemanager.scheduler.capacity.LeafQueue: Application application_1580953164575_0007 from user: hadoop activated in queue: default
2020-02-06 02:06:17,985 INFO org.apache.hadoop.yarn.server.resourcemanager.scheduler.capacity.LeafQueue: Application added - appId: application_1580953164575_0007 user: org.apache.hadoop.yarn.server.resourcemanager.scheduler.capacity.LeafQueue$User@6ce8f656, leaf-queue: default #user-pending-applications: 0 #user-active-applications: 1 #queue-pending-applications: 0 #queue-active-applications: 1
2020-02-06 02:06:17,985 INFO org.apache.hadoop.yarn.server.resourcemanager.scheduler.capacity.CapacityScheduler: Added Application Attempt appattempt_1580953164575_0007_000001 to scheduler from user hadoop in queue default
2020-02-06 02:06:17,985 INFO org.apache.hadoop.yarn.server.resourcemanager.rmapp.attempt.RMAppAttemptImpl: appattempt_1580953164575_0007_000001 State change from SUBMITTED to SCHEDULED
2020-02-06 02:06:18,083 INFO org.apache.hadoop.yarn.server.resourcemanager.rmcontainer.RMContainerImpl: container_1580953164575_0007_01_000001 Container Transitioned from NEW to ALLOCATED
2020-02-06 02:06:18,083 INFO org.apache.hadoop.yarn.server.resourcemanager.RMAuditLogger: USER=hadoop	OPERATION=AM Allocated Container	TARGET=SchedulerApp	RESULT=SUCCESS	APPID=application_1580953164575_0007	CONTAINERID=container_1580953164575_0007_01_000001
2020-02-06 02:06:18,083 INFO org.apache.hadoop.yarn.server.resourcemanager.scheduler.SchedulerNode: Assigned container container_1580953164575_0007_01_000001 of capacity <memory:4096, vCores:1> on host nodemaster:8050, which has 1 containers, <memory:4096, vCores:1> used and <memory:28672, vCores:9> available after allocation
2020-02-06 02:06:18,083 INFO org.apache.hadoop.yarn.server.resourcemanager.scheduler.capacity.LeafQueue: assignedContainer application attempt=appattempt_1580953164575_0007_000001 container=Container: [ContainerId: container_1580953164575_0007_01_000001, NodeId: nodemaster:8050, NodeHttpAddress: nodemaster:8042, Resource: <memory:4096, vCores:1>, Priority: 0, Token: null, ] queue=default: capacity=1.0, absoluteCapacity=1.0, usedResources=<memory:0, vCores:0>, usedCapacity=0.0, absoluteUsedCapacity=0.0, numApps=1, numContainers=0 clusterResource=<memory:32768, vCores:10> type=OFF_SWITCH requestedPartition=
2020-02-06 02:06:18,083 INFO org.apache.hadoop.yarn.server.resourcemanager.scheduler.capacity.ParentQueue: Re-sorting assigned queue: root.default stats: default: capacity=1.0, absoluteCapacity=1.0, usedResources=<memory:4096, vCores:1>, usedCapacity=0.125, absoluteUsedCapacity=0.125, numApps=1, numContainers=1
2020-02-06 02:06:18,083 INFO org.apache.hadoop.yarn.server.resourcemanager.scheduler.capacity.ParentQueue: assignedContainer queue=root usedCapacity=0.125 absoluteUsedCapacity=0.125 used=<memory:4096, vCores:1> cluster=<memory:32768, vCores:10>
2020-02-06 02:06:18,084 INFO org.apache.hadoop.yarn.server.resourcemanager.security.NMTokenSecretManagerInRM: Sending NMToken for nodeId : nodemaster:8050 for container : container_1580953164575_0007_01_000001
2020-02-06 02:06:18,084 INFO org.apache.hadoop.yarn.server.resourcemanager.rmcontainer.RMContainerImpl: container_1580953164575_0007_01_000001 Container Transitioned from ALLOCATED to ACQUIRED
2020-02-06 02:06:18,084 INFO org.apache.hadoop.yarn.server.resourcemanager.security.NMTokenSecretManagerInRM: Clear node set for appattempt_1580953164575_0007_000001
2020-02-06 02:06:18,084 INFO org.apache.hadoop.yarn.server.resourcemanager.rmapp.attempt.RMAppAttemptImpl: Storing attempt: AppId: application_1580953164575_0007 AttemptId: appattempt_1580953164575_0007_000001 MasterContainer: Container: [ContainerId: container_1580953164575_0007_01_000001, NodeId: nodemaster:8050, NodeHttpAddress: nodemaster:8042, Resource: <memory:4096, vCores:1>, Priority: 0, Token: Token { kind: ContainerToken, service: 172.28.1.15:8050 }, ]
2020-02-06 02:06:18,084 INFO org.apache.hadoop.yarn.server.resourcemanager.rmapp.attempt.RMAppAttemptImpl: appattempt_1580953164575_0007_000001 State change from SCHEDULED to ALLOCATED_SAVING
2020-02-06 02:06:18,084 INFO org.apache.hadoop.yarn.server.resourcemanager.rmapp.attempt.RMAppAttemptImpl: appattempt_1580953164575_0007_000001 State change from ALLOCATED_SAVING to ALLOCATED
2020-02-06 02:06:18,085 INFO org.apache.hadoop.yarn.server.resourcemanager.amlauncher.AMLauncher: Launching masterappattempt_1580953164575_0007_000001
2020-02-06 02:06:18,086 INFO org.apache.hadoop.yarn.server.resourcemanager.amlauncher.AMLauncher: Setting up container Container: [ContainerId: container_1580953164575_0007_01_000001, NodeId: nodemaster:8050, NodeHttpAddress: nodemaster:8042, Resource: <memory:4096, vCores:1>, Priority: 0, Token: Token { kind: ContainerToken, service: 172.28.1.15:8050 }, ] for AM appattempt_1580953164575_0007_000001
2020-02-06 02:06:18,086 INFO org.apache.hadoop.yarn.server.resourcemanager.amlauncher.AMLauncher: Command to launch container container_1580953164575_0007_01_000001 : {{JAVA_HOME}}/bin/java,-server,-Xmx512m,-Djava.io.tmpdir={{PWD}}/tmp,-Dspark.yarn.app.container.log.dir=<LOG_DIR>,org.apache.spark.deploy.yarn.ExecutorLauncher,--arg,'nodemaster:36913',--properties-file,{{PWD}}/__spark_conf__/__spark_conf__.properties,1>,<LOG_DIR>/stdout,2>,<LOG_DIR>/stderr
2020-02-06 02:06:18,086 INFO org.apache.hadoop.yarn.server.resourcemanager.security.AMRMTokenSecretManager: Create AMRMToken for ApplicationAttempt: appattempt_1580953164575_0007_000001
2020-02-06 02:06:18,086 INFO org.apache.hadoop.yarn.server.resourcemanager.security.AMRMTokenSecretManager: Creating password for appattempt_1580953164575_0007_000001
2020-02-06 02:06:18,091 INFO org.apache.hadoop.yarn.server.resourcemanager.amlauncher.AMLauncher: Done launching container Container: [ContainerId: container_1580953164575_0007_01_000001, NodeId: nodemaster:8050, NodeHttpAddress: nodemaster:8042, Resource: <memory:4096, vCores:1>, Priority: 0, Token: Token { kind: ContainerToken, service: 172.28.1.15:8050 }, ] for AM appattempt_1580953164575_0007_000001
2020-02-06 02:06:18,091 INFO org.apache.hadoop.yarn.server.resourcemanager.rmapp.attempt.RMAppAttemptImpl: appattempt_1580953164575_0007_000001 State change from ALLOCATED to LAUNCHED
2020-02-06 02:06:19,084 INFO org.apache.hadoop.yarn.server.resourcemanager.rmcontainer.RMContainerImpl: container_1580953164575_0007_01_000001 Container Transitioned from ACQUIRED to RUNNING
2020-02-06 02:06:20,465 INFO SecurityLogger.org.apache.hadoop.ipc.Server: Auth successful for appattempt_1580953164575_0007_000001 (auth:SIMPLE)
2020-02-06 02:06:20,467 INFO org.apache.hadoop.yarn.server.resourcemanager.ApplicationMasterService: AM registration appattempt_1580953164575_0007_000001
2020-02-06 02:06:20,467 INFO org.apache.hadoop.yarn.server.resourcemanager.RMAuditLogger: USER=hadoop	IP=172.28.1.15	OPERATION=Register App Master	TARGET=ApplicationMasterService	RESULT=SUCCESS	APPID=application_1580953164575_0007	APPATTEMPTID=appattempt_1580953164575_0007_000001
2020-02-06 02:06:20,467 INFO org.apache.hadoop.yarn.server.resourcemanager.rmapp.attempt.RMAppAttemptImpl: appattempt_1580953164575_0007_000001 State change from LAUNCHED to RUNNING
2020-02-06 02:06:20,467 INFO org.apache.hadoop.yarn.server.resourcemanager.rmapp.RMAppImpl: application_1580953164575_0007 State change from ACCEPTED to RUNNING on event=ATTEMPT_REGISTERED
2020-02-06 02:06:21,085 INFO org.apache.hadoop.yarn.server.resourcemanager.rmcontainer.RMContainerImpl: container_1580953164575_0007_01_000002 Container Transitioned from NEW to ALLOCATED
2020-02-06 02:06:21,085 INFO org.apache.hadoop.yarn.server.resourcemanager.RMAuditLogger: USER=hadoop	OPERATION=AM Allocated Container	TARGET=SchedulerApp	RESULT=SUCCESS	APPID=application_1580953164575_0007	CONTAINERID=container_1580953164575_0007_01_000002
2020-02-06 02:06:21,085 INFO org.apache.hadoop.yarn.server.resourcemanager.scheduler.SchedulerNode: Assigned container container_1580953164575_0007_01_000002 of capacity <memory:12288, vCores:1> on host nodemaster:8050, which has 2 containers, <memory:16384, vCores:2> used and <memory:16384, vCores:8> available after allocation
2020-02-06 02:06:21,085 INFO org.apache.hadoop.yarn.server.resourcemanager.scheduler.capacity.LeafQueue: assignedContainer application attempt=appattempt_1580953164575_0007_000001 container=Container: [ContainerId: container_1580953164575_0007_01_000002, NodeId: nodemaster:8050, NodeHttpAddress: nodemaster:8042, Resource: <memory:12288, vCores:1>, Priority: 1, Token: null, ] queue=default: capacity=1.0, absoluteCapacity=1.0, usedResources=<memory:4096, vCores:1>, usedCapacity=0.125, absoluteUsedCapacity=0.125, numApps=1, numContainers=1 clusterResource=<memory:32768, vCores:10> type=OFF_SWITCH requestedPartition=
2020-02-06 02:06:21,085 INFO org.apache.hadoop.yarn.server.resourcemanager.scheduler.capacity.ParentQueue: Re-sorting assigned queue: root.default stats: default: capacity=1.0, absoluteCapacity=1.0, usedResources=<memory:16384, vCores:2>, usedCapacity=0.5, absoluteUsedCapacity=0.5, numApps=1, numContainers=2
2020-02-06 02:06:21,085 INFO org.apache.hadoop.yarn.server.resourcemanager.scheduler.capacity.ParentQueue: assignedContainer queue=root usedCapacity=0.5 absoluteUsedCapacity=0.5 used=<memory:16384, vCores:2> cluster=<memory:32768, vCores:10>
2020-02-06 02:06:21,135 INFO org.apache.hadoop.yarn.server.resourcemanager.security.NMTokenSecretManagerInRM: Sending NMToken for nodeId : nodemaster:8050 for container : container_1580953164575_0007_01_000002
2020-02-06 02:06:21,135 INFO org.apache.hadoop.yarn.server.resourcemanager.rmcontainer.RMContainerImpl: container_1580953164575_0007_01_000002 Container Transitioned from ALLOCATED to ACQUIRED
2020-02-06 02:06:22,085 INFO org.apache.hadoop.yarn.server.resourcemanager.rmcontainer.RMContainerImpl: container_1580953164575_0007_01_000002 Container Transitioned from ACQUIRED to RUNNING
2020-02-06 02:06:22,086 INFO org.apache.hadoop.yarn.server.resourcemanager.rmcontainer.RMContainerImpl: container_1580953164575_0007_01_000003 Container Transitioned from NEW to ALLOCATED
2020-02-06 02:06:22,086 INFO org.apache.hadoop.yarn.server.resourcemanager.RMAuditLogger: USER=hadoop	OPERATION=AM Allocated Container	TARGET=SchedulerApp	RESULT=SUCCESS	APPID=application_1580953164575_0007	CONTAINERID=container_1580953164575_0007_01_000003
2020-02-06 02:06:22,086 INFO org.apache.hadoop.yarn.server.resourcemanager.scheduler.SchedulerNode: Assigned container container_1580953164575_0007_01_000003 of capacity <memory:12288, vCores:1> on host nodemaster:8050, which has 3 containers, <memory:28672, vCores:3> used and <memory:4096, vCores:7> available after allocation
2020-02-06 02:06:22,086 INFO org.apache.hadoop.yarn.server.resourcemanager.scheduler.capacity.LeafQueue: assignedContainer application attempt=appattempt_1580953164575_0007_000001 container=Container: [ContainerId: container_1580953164575_0007_01_000003, NodeId: nodemaster:8050, NodeHttpAddress: nodemaster:8042, Resource: <memory:12288, vCores:1>, Priority: 1, Token: null, ] queue=default: capacity=1.0, absoluteCapacity=1.0, usedResources=<memory:16384, vCores:2>, usedCapacity=0.5, absoluteUsedCapacity=0.5, numApps=1, numContainers=2 clusterResource=<memory:32768, vCores:10> type=OFF_SWITCH requestedPartition=
2020-02-06 02:06:22,086 INFO org.apache.hadoop.yarn.server.resourcemanager.scheduler.capacity.ParentQueue: Re-sorting assigned queue: root.default stats: default: capacity=1.0, absoluteCapacity=1.0, usedResources=<memory:28672, vCores:3>, usedCapacity=0.875, absoluteUsedCapacity=0.875, numApps=1, numContainers=3
2020-02-06 02:06:22,086 INFO org.apache.hadoop.yarn.server.resourcemanager.scheduler.capacity.ParentQueue: assignedContainer queue=root usedCapacity=0.875 absoluteUsedCapacity=0.875 used=<memory:28672, vCores:3> cluster=<memory:32768, vCores:10>
2020-02-06 02:06:23,545 INFO org.apache.hadoop.yarn.server.resourcemanager.rmcontainer.RMContainerImpl: container_1580953164575_0007_01_000003 Container Transitioned from ALLOCATED to ACQUIRED
2020-02-06 02:06:24,087 INFO org.apache.hadoop.yarn.server.resourcemanager.rmcontainer.RMContainerImpl: container_1580953164575_0007_01_000003 Container Transitioned from ACQUIRED to RUNNING
2020-02-06 02:06:26,548 INFO org.apache.hadoop.yarn.server.resourcemanager.scheduler.AppSchedulingInfo: checking for deactivate of application :application_1580953164575_0007
2020-02-06 02:06:26,586 INFO org.apache.hadoop.yarn.server.resourcemanager.rmapp.attempt.RMAppAttemptImpl: Updating application attempt appattempt_1580953164575_0007_000001 with final state: FINISHING, and exit status: -1000
2020-02-06 02:06:26,587 INFO org.apache.hadoop.yarn.server.resourcemanager.rmapp.attempt.RMAppAttemptImpl: appattempt_1580953164575_0007_000001 State change from RUNNING to FINAL_SAVING
2020-02-06 02:06:26,587 INFO org.apache.hadoop.yarn.server.resourcemanager.rmapp.RMAppImpl: Updating application application_1580953164575_0007 with final state: FINISHING
2020-02-06 02:06:26,587 INFO org.apache.hadoop.yarn.server.resourcemanager.rmapp.RMAppImpl: application_1580953164575_0007 State change from RUNNING to FINAL_SAVING on event=ATTEMPT_UNREGISTERED
2020-02-06 02:06:26,587 INFO org.apache.hadoop.yarn.server.resourcemanager.recovery.RMStateStore: Updating info for app: application_1580953164575_0007
2020-02-06 02:06:26,587 INFO org.apache.hadoop.yarn.server.resourcemanager.rmapp.attempt.RMAppAttemptImpl: appattempt_1580953164575_0007_000001 State change from FINAL_SAVING to FINISHING
2020-02-06 02:06:26,587 INFO org.apache.hadoop.yarn.server.resourcemanager.rmapp.RMAppImpl: application_1580953164575_0007 State change from FINAL_SAVING to FINISHING on event=APP_UPDATE_SAVED
2020-02-06 02:06:26,632 INFO org.apache.hadoop.yarn.server.resourcemanager.rmcontainer.RMContainerImpl: container_1580953164575_0007_01_000002 Container Transitioned from RUNNING to COMPLETED
2020-02-06 02:06:26,632 INFO org.apache.hadoop.yarn.server.resourcemanager.scheduler.common.fica.FiCaSchedulerApp: Completed container: container_1580953164575_0007_01_000002 in state: COMPLETED event:FINISHED
2020-02-06 02:06:26,632 INFO org.apache.hadoop.yarn.server.resourcemanager.RMAuditLogger: USER=hadoop	OPERATION=AM Released Container	TARGET=SchedulerApp	RESULT=SUCCESS	APPID=application_1580953164575_0007	CONTAINERID=container_1580953164575_0007_01_000002
2020-02-06 02:06:26,632 INFO org.apache.hadoop.yarn.server.resourcemanager.scheduler.SchedulerNode: Released container container_1580953164575_0007_01_000002 of capacity <memory:12288, vCores:1> on host nodemaster:8050, which currently has 2 containers, <memory:16384, vCores:2> used and <memory:16384, vCores:8> available, release resources=true
2020-02-06 02:06:26,632 INFO org.apache.hadoop.yarn.server.resourcemanager.scheduler.capacity.LeafQueue: default used=<memory:16384, vCores:2> numContainers=2 user=hadoop user-resources=<memory:16384, vCores:2>
2020-02-06 02:06:26,633 INFO org.apache.hadoop.yarn.server.resourcemanager.scheduler.capacity.LeafQueue: completedContainer container=Container: [ContainerId: container_1580953164575_0007_01_000002, NodeId: nodemaster:8050, NodeHttpAddress: nodemaster:8042, Resource: <memory:12288, vCores:1>, Priority: 1, Token: Token { kind: ContainerToken, service: 172.28.1.15:8050 }, ] queue=default: capacity=1.0, absoluteCapacity=1.0, usedResources=<memory:16384, vCores:2>, usedCapacity=0.5, absoluteUsedCapacity=0.5, numApps=1, numContainers=2 cluster=<memory:32768, vCores:10>
2020-02-06 02:06:26,633 INFO org.apache.hadoop.yarn.server.resourcemanager.scheduler.capacity.ParentQueue: completedContainer queue=root usedCapacity=0.5 absoluteUsedCapacity=0.5 used=<memory:16384, vCores:2> cluster=<memory:32768, vCores:10>
2020-02-06 02:06:26,633 INFO org.apache.hadoop.yarn.server.resourcemanager.scheduler.capacity.ParentQueue: Re-sorting completed queue: root.default stats: default: capacity=1.0, absoluteCapacity=1.0, usedResources=<memory:16384, vCores:2>, usedCapacity=0.5, absoluteUsedCapacity=0.5, numApps=1, numContainers=2
2020-02-06 02:06:26,633 INFO org.apache.hadoop.yarn.server.resourcemanager.scheduler.capacity.CapacityScheduler: Application attempt appattempt_1580953164575_0007_000001 released container container_1580953164575_0007_01_000002 on node: host: nodemaster:8050 #containers=2 available=<memory:16384, vCores:8> used=<memory:16384, vCores:2> with event: FINISHED
2020-02-06 02:06:26,689 INFO org.apache.hadoop.yarn.server.resourcemanager.ApplicationMasterService: application_1580953164575_0007 unregistered successfully. 
2020-02-06 02:06:26,953 INFO org.apache.hadoop.yarn.server.resourcemanager.rmcontainer.RMContainerImpl: container_1580953164575_0007_01_000003 Container Transitioned from RUNNING to COMPLETED
2020-02-06 02:06:26,953 INFO org.apache.hadoop.yarn.server.resourcemanager.scheduler.common.fica.FiCaSchedulerApp: Completed container: container_1580953164575_0007_01_000003 in state: COMPLETED event:FINISHED
2020-02-06 02:06:26,953 INFO org.apache.hadoop.yarn.server.resourcemanager.RMAuditLogger: USER=hadoop	OPERATION=AM Released Container	TARGET=SchedulerApp	RESULT=SUCCESS	APPID=application_1580953164575_0007	CONTAINERID=container_1580953164575_0007_01_000003
2020-02-06 02:06:26,953 INFO org.apache.hadoop.yarn.server.resourcemanager.scheduler.SchedulerNode: Released container container_1580953164575_0007_01_000003 of capacity <memory:12288, vCores:1> on host nodemaster:8050, which currently has 1 containers, <memory:4096, vCores:1> used and <memory:28672, vCores:9> available, release resources=true
2020-02-06 02:06:26,953 INFO org.apache.hadoop.yarn.server.resourcemanager.scheduler.capacity.LeafQueue: default used=<memory:4096, vCores:1> numContainers=1 user=hadoop user-resources=<memory:4096, vCores:1>
2020-02-06 02:06:26,953 INFO org.apache.hadoop.yarn.server.resourcemanager.scheduler.capacity.LeafQueue: completedContainer container=Container: [ContainerId: container_1580953164575_0007_01_000003, NodeId: nodemaster:8050, NodeHttpAddress: nodemaster:8042, Resource: <memory:12288, vCores:1>, Priority: 1, Token: Token { kind: ContainerToken, service: 172.28.1.15:8050 }, ] queue=default: capacity=1.0, absoluteCapacity=1.0, usedResources=<memory:4096, vCores:1>, usedCapacity=0.125, absoluteUsedCapacity=0.125, numApps=1, numContainers=1 cluster=<memory:32768, vCores:10>
2020-02-06 02:06:26,953 INFO org.apache.hadoop.yarn.server.resourcemanager.scheduler.capacity.ParentQueue: completedContainer queue=root usedCapacity=0.125 absoluteUsedCapacity=0.125 used=<memory:4096, vCores:1> cluster=<memory:32768, vCores:10>
2020-02-06 02:06:26,954 INFO org.apache.hadoop.yarn.server.resourcemanager.scheduler.capacity.ParentQueue: Re-sorting completed queue: root.default stats: default: capacity=1.0, absoluteCapacity=1.0, usedResources=<memory:4096, vCores:1>, usedCapacity=0.125, absoluteUsedCapacity=0.125, numApps=1, numContainers=1
2020-02-06 02:06:26,954 INFO org.apache.hadoop.yarn.server.resourcemanager.scheduler.capacity.CapacityScheduler: Application attempt appattempt_1580953164575_0007_000001 released container container_1580953164575_0007_01_000003 on node: host: nodemaster:8050 #containers=1 available=<memory:28672, vCores:9> used=<memory:4096, vCores:1> with event: FINISHED
2020-02-06 02:06:27,086 INFO org.apache.hadoop.yarn.server.resourcemanager.rmcontainer.RMContainerImpl: container_1580953164575_0007_01_000001 Container Transitioned from RUNNING to COMPLETED
2020-02-06 02:06:27,086 INFO org.apache.hadoop.yarn.server.resourcemanager.scheduler.common.fica.FiCaSchedulerApp: Completed container: container_1580953164575_0007_01_000001 in state: COMPLETED event:FINISHED
2020-02-06 02:06:27,086 INFO org.apache.hadoop.yarn.server.resourcemanager.ApplicationMasterService: Unregistering app attempt : appattempt_1580953164575_0007_000001
2020-02-06 02:06:27,086 INFO org.apache.hadoop.yarn.server.resourcemanager.RMAuditLogger: USER=hadoop	OPERATION=AM Released Container	TARGET=SchedulerApp	RESULT=SUCCESS	APPID=application_1580953164575_0007	CONTAINERID=container_1580953164575_0007_01_000001
2020-02-06 02:06:27,087 INFO org.apache.hadoop.yarn.server.resourcemanager.security.AMRMTokenSecretManager: Application finished, removing password for appattempt_1580953164575_0007_000001
2020-02-06 02:06:27,087 INFO org.apache.hadoop.yarn.server.resourcemanager.scheduler.SchedulerNode: Released container container_1580953164575_0007_01_000001 of capacity <memory:4096, vCores:1> on host nodemaster:8050, which currently has 0 containers, <memory:0, vCores:0> used and <memory:32768, vCores:10> available, release resources=true
2020-02-06 02:06:27,087 INFO org.apache.hadoop.yarn.server.resourcemanager.scheduler.capacity.LeafQueue: default used=<memory:0, vCores:0> numContainers=0 user=hadoop user-resources=<memory:0, vCores:0>
2020-02-06 02:06:27,087 INFO org.apache.hadoop.yarn.server.resourcemanager.scheduler.capacity.LeafQueue: completedContainer container=Container: [ContainerId: container_1580953164575_0007_01_000001, NodeId: nodemaster:8050, NodeHttpAddress: nodemaster:8042, Resource: <memory:4096, vCores:1>, Priority: 0, Token: Token { kind: ContainerToken, service: 172.28.1.15:8050 }, ] queue=default: capacity=1.0, absoluteCapacity=1.0, usedResources=<memory:0, vCores:0>, usedCapacity=0.0, absoluteUsedCapacity=0.0, numApps=1, numContainers=0 cluster=<memory:32768, vCores:10>
2020-02-06 02:06:27,087 INFO org.apache.hadoop.yarn.server.resourcemanager.scheduler.capacity.ParentQueue: completedContainer queue=root usedCapacity=0.0 absoluteUsedCapacity=0.0 used=<memory:0, vCores:0> cluster=<memory:32768, vCores:10>
2020-02-06 02:06:27,087 INFO org.apache.hadoop.yarn.server.resourcemanager.scheduler.capacity.ParentQueue: Re-sorting completed queue: root.default stats: default: capacity=1.0, absoluteCapacity=1.0, usedResources=<memory:0, vCores:0>, usedCapacity=0.0, absoluteUsedCapacity=0.0, numApps=1, numContainers=0
2020-02-06 02:06:27,087 INFO org.apache.hadoop.yarn.server.resourcemanager.scheduler.capacity.CapacityScheduler: Application attempt appattempt_1580953164575_0007_000001 released container container_1580953164575_0007_01_000001 on node: host: nodemaster:8050 #containers=0 available=<memory:32768, vCores:10> used=<memory:0, vCores:0> with event: FINISHED
2020-02-06 02:06:27,087 INFO org.apache.hadoop.yarn.server.resourcemanager.rmapp.attempt.RMAppAttemptImpl: appattempt_1580953164575_0007_000001 State change from FINISHING to FINISHED
2020-02-06 02:06:27,088 INFO org.apache.hadoop.yarn.server.resourcemanager.rmapp.RMAppImpl: application_1580953164575_0007 State change from FINISHING to FINISHED on event=ATTEMPT_FINISHED
2020-02-06 02:06:27,088 INFO org.apache.hadoop.yarn.server.resourcemanager.scheduler.capacity.CapacityScheduler: Application Attempt appattempt_1580953164575_0007_000001 is done. finalState=FINISHED
2020-02-06 02:06:27,088 INFO org.apache.hadoop.yarn.server.resourcemanager.RMAuditLogger: USER=hadoop	OPERATION=Application Finished - Succeeded	TARGET=RMAppManager	RESULT=SUCCESS	APPID=application_1580953164575_0007
2020-02-06 02:06:27,089 INFO org.apache.hadoop.yarn.server.resourcemanager.scheduler.AppSchedulingInfo: Application application_1580953164575_0007 requests cleared
2020-02-06 02:06:27,089 INFO org.apache.hadoop.yarn.server.resourcemanager.scheduler.capacity.LeafQueue: Application removed - appId: application_1580953164575_0007 user: hadoop queue: default #user-pending-applications: 0 #user-active-applications: 0 #queue-pending-applications: 0 #queue-active-applications: 0
2020-02-06 02:06:27,089 INFO org.apache.hadoop.yarn.server.resourcemanager.scheduler.capacity.ParentQueue: Application removed - appId: application_1580953164575_0007 user: hadoop leaf-queue of parent: root #applications: 0
2020-02-06 02:06:27,089 INFO org.apache.hadoop.yarn.server.resourcemanager.amlauncher.AMLauncher: Cleaning master appattempt_1580953164575_0007_000001
2020-02-06 02:06:27,089 INFO org.apache.hadoop.yarn.server.resourcemanager.RMAppManager$ApplicationSummary: appId=application_1580953164575_0007,name=gen,user=hadoop,queue=default,state=FINISHED,trackingUrl=http://nodemaster:8088/proxy/application_1580953164575_0007/,appMasterHost=172.28.1.15,startTime=1580954777984,finishTime=1580954786587,finalStatus=SUCCEEDED,memorySeconds=164842,vcoreSeconds=18,preemptedAMContainers=0,preemptedNonAMContainers=0,preemptedResources=<memory:0\, vCores:0>,applicationType=SPARK
2020-02-06 02:06:29,090 INFO org.apache.hadoop.yarn.server.resourcemanager.scheduler.capacity.CapacityScheduler: Null container completed...
2020-02-06 02:06:29,091 INFO org.apache.hadoop.yarn.server.resourcemanager.scheduler.capacity.CapacityScheduler: Null container completed...
2020-02-06 02:11:30,442 INFO org.apache.hadoop.yarn.server.resourcemanager.ClientRMService: Allocated new applicationId: 8
2020-02-06 02:11:33,374 WARN org.apache.hadoop.yarn.server.resourcemanager.rmapp.RMAppImpl: The specific max attempts: 0 for application: 8 is invalid, because it is out of the range [1, 2]. Use the global max attempts instead.
2020-02-06 02:11:33,374 INFO org.apache.hadoop.yarn.server.resourcemanager.ClientRMService: Application with id 8 submitted by user hadoop
2020-02-06 02:11:33,374 INFO org.apache.hadoop.yarn.server.resourcemanager.RMAuditLogger: USER=hadoop	IP=172.28.1.15	OPERATION=Submit Application Request	TARGET=ClientRMService	RESULT=SUCCESS	APPID=application_1580953164575_0008
2020-02-06 02:11:33,374 INFO org.apache.hadoop.yarn.server.resourcemanager.rmapp.RMAppImpl: Storing application with id application_1580953164575_0008
2020-02-06 02:11:33,374 INFO org.apache.hadoop.yarn.server.resourcemanager.rmapp.RMAppImpl: application_1580953164575_0008 State change from NEW to NEW_SAVING on event=START
2020-02-06 02:11:33,374 INFO org.apache.hadoop.yarn.server.resourcemanager.recovery.RMStateStore: Storing info for app: application_1580953164575_0008
2020-02-06 02:11:33,374 INFO org.apache.hadoop.yarn.server.resourcemanager.rmapp.RMAppImpl: application_1580953164575_0008 State change from NEW_SAVING to SUBMITTED on event=APP_NEW_SAVED
2020-02-06 02:11:33,374 INFO org.apache.hadoop.yarn.server.resourcemanager.scheduler.capacity.ParentQueue: Application added - appId: application_1580953164575_0008 user: hadoop leaf-queue of parent: root #applications: 1
2020-02-06 02:11:33,374 INFO org.apache.hadoop.yarn.server.resourcemanager.scheduler.capacity.CapacityScheduler: Accepted application application_1580953164575_0008 from user: hadoop, in queue: default
2020-02-06 02:11:33,375 INFO org.apache.hadoop.yarn.server.resourcemanager.rmapp.RMAppImpl: application_1580953164575_0008 State change from SUBMITTED to ACCEPTED on event=APP_ACCEPTED
2020-02-06 02:11:33,375 INFO org.apache.hadoop.yarn.server.resourcemanager.ApplicationMasterService: Registering app attempt : appattempt_1580953164575_0008_000001
2020-02-06 02:11:33,375 INFO org.apache.hadoop.yarn.server.resourcemanager.rmapp.attempt.RMAppAttemptImpl: appattempt_1580953164575_0008_000001 State change from NEW to SUBMITTED
2020-02-06 02:11:33,375 INFO org.apache.hadoop.yarn.server.resourcemanager.scheduler.capacity.LeafQueue: Application application_1580953164575_0008 from user: hadoop activated in queue: default
2020-02-06 02:11:33,375 INFO org.apache.hadoop.yarn.server.resourcemanager.scheduler.capacity.LeafQueue: Application added - appId: application_1580953164575_0008 user: org.apache.hadoop.yarn.server.resourcemanager.scheduler.capacity.LeafQueue$User@13f22137, leaf-queue: default #user-pending-applications: 0 #user-active-applications: 1 #queue-pending-applications: 0 #queue-active-applications: 1
2020-02-06 02:11:33,375 INFO org.apache.hadoop.yarn.server.resourcemanager.scheduler.capacity.CapacityScheduler: Added Application Attempt appattempt_1580953164575_0008_000001 to scheduler from user hadoop in queue default
2020-02-06 02:11:33,375 INFO org.apache.hadoop.yarn.server.resourcemanager.rmapp.attempt.RMAppAttemptImpl: appattempt_1580953164575_0008_000001 State change from SUBMITTED to SCHEDULED
2020-02-06 02:11:33,447 INFO org.apache.hadoop.yarn.server.resourcemanager.rmcontainer.RMContainerImpl: container_1580953164575_0008_01_000001 Container Transitioned from NEW to ALLOCATED
2020-02-06 02:11:33,447 INFO org.apache.hadoop.yarn.server.resourcemanager.RMAuditLogger: USER=hadoop	OPERATION=AM Allocated Container	TARGET=SchedulerApp	RESULT=SUCCESS	APPID=application_1580953164575_0008	CONTAINERID=container_1580953164575_0008_01_000001
2020-02-06 02:11:33,447 INFO org.apache.hadoop.yarn.server.resourcemanager.scheduler.SchedulerNode: Assigned container container_1580953164575_0008_01_000001 of capacity <memory:4096, vCores:1> on host nodemaster:8050, which has 1 containers, <memory:4096, vCores:1> used and <memory:28672, vCores:9> available after allocation
2020-02-06 02:11:33,447 INFO org.apache.hadoop.yarn.server.resourcemanager.scheduler.capacity.LeafQueue: assignedContainer application attempt=appattempt_1580953164575_0008_000001 container=Container: [ContainerId: container_1580953164575_0008_01_000001, NodeId: nodemaster:8050, NodeHttpAddress: nodemaster:8042, Resource: <memory:4096, vCores:1>, Priority: 0, Token: null, ] queue=default: capacity=1.0, absoluteCapacity=1.0, usedResources=<memory:0, vCores:0>, usedCapacity=0.0, absoluteUsedCapacity=0.0, numApps=1, numContainers=0 clusterResource=<memory:32768, vCores:10> type=OFF_SWITCH requestedPartition=
2020-02-06 02:11:33,447 INFO org.apache.hadoop.yarn.server.resourcemanager.scheduler.capacity.ParentQueue: Re-sorting assigned queue: root.default stats: default: capacity=1.0, absoluteCapacity=1.0, usedResources=<memory:4096, vCores:1>, usedCapacity=0.125, absoluteUsedCapacity=0.125, numApps=1, numContainers=1
2020-02-06 02:11:33,447 INFO org.apache.hadoop.yarn.server.resourcemanager.scheduler.capacity.ParentQueue: assignedContainer queue=root usedCapacity=0.125 absoluteUsedCapacity=0.125 used=<memory:4096, vCores:1> cluster=<memory:32768, vCores:10>
2020-02-06 02:11:33,448 INFO org.apache.hadoop.yarn.server.resourcemanager.security.NMTokenSecretManagerInRM: Sending NMToken for nodeId : nodemaster:8050 for container : container_1580953164575_0008_01_000001
2020-02-06 02:11:33,448 INFO org.apache.hadoop.yarn.server.resourcemanager.rmcontainer.RMContainerImpl: container_1580953164575_0008_01_000001 Container Transitioned from ALLOCATED to ACQUIRED
2020-02-06 02:11:33,448 INFO org.apache.hadoop.yarn.server.resourcemanager.security.NMTokenSecretManagerInRM: Clear node set for appattempt_1580953164575_0008_000001
2020-02-06 02:11:33,448 INFO org.apache.hadoop.yarn.server.resourcemanager.rmapp.attempt.RMAppAttemptImpl: Storing attempt: AppId: application_1580953164575_0008 AttemptId: appattempt_1580953164575_0008_000001 MasterContainer: Container: [ContainerId: container_1580953164575_0008_01_000001, NodeId: nodemaster:8050, NodeHttpAddress: nodemaster:8042, Resource: <memory:4096, vCores:1>, Priority: 0, Token: Token { kind: ContainerToken, service: 172.28.1.15:8050 }, ]
2020-02-06 02:11:33,448 INFO org.apache.hadoop.yarn.server.resourcemanager.rmapp.attempt.RMAppAttemptImpl: appattempt_1580953164575_0008_000001 State change from SCHEDULED to ALLOCATED_SAVING
2020-02-06 02:11:33,448 INFO org.apache.hadoop.yarn.server.resourcemanager.rmapp.attempt.RMAppAttemptImpl: appattempt_1580953164575_0008_000001 State change from ALLOCATED_SAVING to ALLOCATED
2020-02-06 02:11:33,449 INFO org.apache.hadoop.yarn.server.resourcemanager.amlauncher.AMLauncher: Launching masterappattempt_1580953164575_0008_000001
2020-02-06 02:11:33,449 INFO org.apache.hadoop.yarn.server.resourcemanager.amlauncher.AMLauncher: Setting up container Container: [ContainerId: container_1580953164575_0008_01_000001, NodeId: nodemaster:8050, NodeHttpAddress: nodemaster:8042, Resource: <memory:4096, vCores:1>, Priority: 0, Token: Token { kind: ContainerToken, service: 172.28.1.15:8050 }, ] for AM appattempt_1580953164575_0008_000001
2020-02-06 02:11:33,449 INFO org.apache.hadoop.yarn.server.resourcemanager.amlauncher.AMLauncher: Command to launch container container_1580953164575_0008_01_000001 : {{JAVA_HOME}}/bin/java,-server,-Xmx512m,-Djava.io.tmpdir={{PWD}}/tmp,-Dspark.yarn.app.container.log.dir=<LOG_DIR>,org.apache.spark.deploy.yarn.ExecutorLauncher,--arg,'nodemaster:46247',--properties-file,{{PWD}}/__spark_conf__/__spark_conf__.properties,1>,<LOG_DIR>/stdout,2>,<LOG_DIR>/stderr
2020-02-06 02:11:33,450 INFO org.apache.hadoop.yarn.server.resourcemanager.security.AMRMTokenSecretManager: Create AMRMToken for ApplicationAttempt: appattempt_1580953164575_0008_000001
2020-02-06 02:11:33,450 INFO org.apache.hadoop.yarn.server.resourcemanager.security.AMRMTokenSecretManager: Creating password for appattempt_1580953164575_0008_000001
2020-02-06 02:11:33,455 INFO org.apache.hadoop.yarn.server.resourcemanager.amlauncher.AMLauncher: Done launching container Container: [ContainerId: container_1580953164575_0008_01_000001, NodeId: nodemaster:8050, NodeHttpAddress: nodemaster:8042, Resource: <memory:4096, vCores:1>, Priority: 0, Token: Token { kind: ContainerToken, service: 172.28.1.15:8050 }, ] for AM appattempt_1580953164575_0008_000001
2020-02-06 02:11:33,455 INFO org.apache.hadoop.yarn.server.resourcemanager.rmapp.attempt.RMAppAttemptImpl: appattempt_1580953164575_0008_000001 State change from ALLOCATED to LAUNCHED
2020-02-06 02:11:34,448 INFO org.apache.hadoop.yarn.server.resourcemanager.rmcontainer.RMContainerImpl: container_1580953164575_0008_01_000001 Container Transitioned from ACQUIRED to RUNNING
2020-02-06 02:11:35,808 INFO SecurityLogger.org.apache.hadoop.ipc.Server: Auth successful for appattempt_1580953164575_0008_000001 (auth:SIMPLE)
2020-02-06 02:11:35,811 INFO org.apache.hadoop.yarn.server.resourcemanager.ApplicationMasterService: AM registration appattempt_1580953164575_0008_000001
2020-02-06 02:11:35,811 INFO org.apache.hadoop.yarn.server.resourcemanager.RMAuditLogger: USER=hadoop	IP=172.28.1.15	OPERATION=Register App Master	TARGET=ApplicationMasterService	RESULT=SUCCESS	APPID=application_1580953164575_0008	APPATTEMPTID=appattempt_1580953164575_0008_000001
2020-02-06 02:11:35,811 INFO org.apache.hadoop.yarn.server.resourcemanager.rmapp.attempt.RMAppAttemptImpl: appattempt_1580953164575_0008_000001 State change from LAUNCHED to RUNNING
2020-02-06 02:11:35,811 INFO org.apache.hadoop.yarn.server.resourcemanager.rmapp.RMAppImpl: application_1580953164575_0008 State change from ACCEPTED to RUNNING on event=ATTEMPT_REGISTERED
2020-02-06 02:11:36,449 INFO org.apache.hadoop.yarn.server.resourcemanager.rmcontainer.RMContainerImpl: container_1580953164575_0008_01_000002 Container Transitioned from NEW to ALLOCATED
2020-02-06 02:11:36,449 INFO org.apache.hadoop.yarn.server.resourcemanager.RMAuditLogger: USER=hadoop	OPERATION=AM Allocated Container	TARGET=SchedulerApp	RESULT=SUCCESS	APPID=application_1580953164575_0008	CONTAINERID=container_1580953164575_0008_01_000002
2020-02-06 02:11:36,449 INFO org.apache.hadoop.yarn.server.resourcemanager.scheduler.SchedulerNode: Assigned container container_1580953164575_0008_01_000002 of capacity <memory:12288, vCores:1> on host nodemaster:8050, which has 2 containers, <memory:16384, vCores:2> used and <memory:16384, vCores:8> available after allocation
2020-02-06 02:11:36,449 INFO org.apache.hadoop.yarn.server.resourcemanager.scheduler.capacity.LeafQueue: assignedContainer application attempt=appattempt_1580953164575_0008_000001 container=Container: [ContainerId: container_1580953164575_0008_01_000002, NodeId: nodemaster:8050, NodeHttpAddress: nodemaster:8042, Resource: <memory:12288, vCores:1>, Priority: 1, Token: null, ] queue=default: capacity=1.0, absoluteCapacity=1.0, usedResources=<memory:4096, vCores:1>, usedCapacity=0.125, absoluteUsedCapacity=0.125, numApps=1, numContainers=1 clusterResource=<memory:32768, vCores:10> type=OFF_SWITCH requestedPartition=
2020-02-06 02:11:36,449 INFO org.apache.hadoop.yarn.server.resourcemanager.scheduler.capacity.ParentQueue: Re-sorting assigned queue: root.default stats: default: capacity=1.0, absoluteCapacity=1.0, usedResources=<memory:16384, vCores:2>, usedCapacity=0.5, absoluteUsedCapacity=0.5, numApps=1, numContainers=2
2020-02-06 02:11:36,449 INFO org.apache.hadoop.yarn.server.resourcemanager.scheduler.capacity.ParentQueue: assignedContainer queue=root usedCapacity=0.5 absoluteUsedCapacity=0.5 used=<memory:16384, vCores:2> cluster=<memory:32768, vCores:10>
2020-02-06 02:11:36,473 INFO org.apache.hadoop.yarn.server.resourcemanager.security.NMTokenSecretManagerInRM: Sending NMToken for nodeId : nodemaster:8050 for container : container_1580953164575_0008_01_000002
2020-02-06 02:11:36,474 INFO org.apache.hadoop.yarn.server.resourcemanager.rmcontainer.RMContainerImpl: container_1580953164575_0008_01_000002 Container Transitioned from ALLOCATED to ACQUIRED
2020-02-06 02:11:37,450 INFO org.apache.hadoop.yarn.server.resourcemanager.rmcontainer.RMContainerImpl: container_1580953164575_0008_01_000002 Container Transitioned from ACQUIRED to RUNNING
2020-02-06 02:11:37,451 INFO org.apache.hadoop.yarn.server.resourcemanager.rmcontainer.RMContainerImpl: container_1580953164575_0008_01_000003 Container Transitioned from NEW to ALLOCATED
2020-02-06 02:11:37,451 INFO org.apache.hadoop.yarn.server.resourcemanager.RMAuditLogger: USER=hadoop	OPERATION=AM Allocated Container	TARGET=SchedulerApp	RESULT=SUCCESS	APPID=application_1580953164575_0008	CONTAINERID=container_1580953164575_0008_01_000003
2020-02-06 02:11:37,451 INFO org.apache.hadoop.yarn.server.resourcemanager.scheduler.SchedulerNode: Assigned container container_1580953164575_0008_01_000003 of capacity <memory:12288, vCores:1> on host nodemaster:8050, which has 3 containers, <memory:28672, vCores:3> used and <memory:4096, vCores:7> available after allocation
2020-02-06 02:11:37,451 INFO org.apache.hadoop.yarn.server.resourcemanager.scheduler.capacity.LeafQueue: assignedContainer application attempt=appattempt_1580953164575_0008_000001 container=Container: [ContainerId: container_1580953164575_0008_01_000003, NodeId: nodemaster:8050, NodeHttpAddress: nodemaster:8042, Resource: <memory:12288, vCores:1>, Priority: 1, Token: null, ] queue=default: capacity=1.0, absoluteCapacity=1.0, usedResources=<memory:16384, vCores:2>, usedCapacity=0.5, absoluteUsedCapacity=0.5, numApps=1, numContainers=2 clusterResource=<memory:32768, vCores:10> type=OFF_SWITCH requestedPartition=
2020-02-06 02:11:37,451 INFO org.apache.hadoop.yarn.server.resourcemanager.scheduler.capacity.ParentQueue: Re-sorting assigned queue: root.default stats: default: capacity=1.0, absoluteCapacity=1.0, usedResources=<memory:28672, vCores:3>, usedCapacity=0.875, absoluteUsedCapacity=0.875, numApps=1, numContainers=3
2020-02-06 02:11:37,451 INFO org.apache.hadoop.yarn.server.resourcemanager.scheduler.capacity.ParentQueue: assignedContainer queue=root usedCapacity=0.875 absoluteUsedCapacity=0.875 used=<memory:28672, vCores:3> cluster=<memory:32768, vCores:10>
2020-02-06 02:11:38,884 INFO org.apache.hadoop.yarn.server.resourcemanager.rmcontainer.RMContainerImpl: container_1580953164575_0008_01_000003 Container Transitioned from ALLOCATED to ACQUIRED
2020-02-06 02:11:39,451 INFO org.apache.hadoop.yarn.server.resourcemanager.rmcontainer.RMContainerImpl: container_1580953164575_0008_01_000003 Container Transitioned from ACQUIRED to RUNNING
2020-02-06 02:11:41,887 INFO org.apache.hadoop.yarn.server.resourcemanager.scheduler.AppSchedulingInfo: checking for deactivate of application :application_1580953164575_0008
2020-02-06 02:11:42,102 INFO org.apache.hadoop.yarn.server.resourcemanager.rmapp.attempt.RMAppAttemptImpl: Updating application attempt appattempt_1580953164575_0008_000001 with final state: FINISHING, and exit status: -1000
2020-02-06 02:11:42,102 INFO org.apache.hadoop.yarn.server.resourcemanager.rmapp.attempt.RMAppAttemptImpl: appattempt_1580953164575_0008_000001 State change from RUNNING to FINAL_SAVING
2020-02-06 02:11:42,102 INFO org.apache.hadoop.yarn.server.resourcemanager.rmapp.RMAppImpl: Updating application application_1580953164575_0008 with final state: FINISHING
2020-02-06 02:11:42,102 INFO org.apache.hadoop.yarn.server.resourcemanager.rmapp.RMAppImpl: application_1580953164575_0008 State change from RUNNING to FINAL_SAVING on event=ATTEMPT_UNREGISTERED
2020-02-06 02:11:42,102 INFO org.apache.hadoop.yarn.server.resourcemanager.recovery.RMStateStore: Updating info for app: application_1580953164575_0008
2020-02-06 02:11:42,102 INFO org.apache.hadoop.yarn.server.resourcemanager.rmapp.attempt.RMAppAttemptImpl: appattempt_1580953164575_0008_000001 State change from FINAL_SAVING to FINISHING
2020-02-06 02:11:42,102 INFO org.apache.hadoop.yarn.server.resourcemanager.rmapp.RMAppImpl: application_1580953164575_0008 State change from FINAL_SAVING to FINISHING on event=APP_UPDATE_SAVED
2020-02-06 02:11:42,135 INFO org.apache.hadoop.yarn.server.resourcemanager.rmcontainer.RMContainerImpl: container_1580953164575_0008_01_000002 Container Transitioned from RUNNING to COMPLETED
2020-02-06 02:11:42,135 INFO org.apache.hadoop.yarn.server.resourcemanager.scheduler.common.fica.FiCaSchedulerApp: Completed container: container_1580953164575_0008_01_000002 in state: COMPLETED event:FINISHED
2020-02-06 02:11:42,135 INFO org.apache.hadoop.yarn.server.resourcemanager.RMAuditLogger: USER=hadoop	OPERATION=AM Released Container	TARGET=SchedulerApp	RESULT=SUCCESS	APPID=application_1580953164575_0008	CONTAINERID=container_1580953164575_0008_01_000002
2020-02-06 02:11:42,135 INFO org.apache.hadoop.yarn.server.resourcemanager.scheduler.SchedulerNode: Released container container_1580953164575_0008_01_000002 of capacity <memory:12288, vCores:1> on host nodemaster:8050, which currently has 2 containers, <memory:16384, vCores:2> used and <memory:16384, vCores:8> available, release resources=true
2020-02-06 02:11:42,135 INFO org.apache.hadoop.yarn.server.resourcemanager.scheduler.capacity.LeafQueue: default used=<memory:16384, vCores:2> numContainers=2 user=hadoop user-resources=<memory:16384, vCores:2>
2020-02-06 02:11:42,136 INFO org.apache.hadoop.yarn.server.resourcemanager.scheduler.capacity.LeafQueue: completedContainer container=Container: [ContainerId: container_1580953164575_0008_01_000002, NodeId: nodemaster:8050, NodeHttpAddress: nodemaster:8042, Resource: <memory:12288, vCores:1>, Priority: 1, Token: Token { kind: ContainerToken, service: 172.28.1.15:8050 }, ] queue=default: capacity=1.0, absoluteCapacity=1.0, usedResources=<memory:16384, vCores:2>, usedCapacity=0.5, absoluteUsedCapacity=0.5, numApps=1, numContainers=2 cluster=<memory:32768, vCores:10>
2020-02-06 02:11:42,136 INFO org.apache.hadoop.yarn.server.resourcemanager.scheduler.capacity.ParentQueue: completedContainer queue=root usedCapacity=0.5 absoluteUsedCapacity=0.5 used=<memory:16384, vCores:2> cluster=<memory:32768, vCores:10>
2020-02-06 02:11:42,136 INFO org.apache.hadoop.yarn.server.resourcemanager.scheduler.capacity.ParentQueue: Re-sorting completed queue: root.default stats: default: capacity=1.0, absoluteCapacity=1.0, usedResources=<memory:16384, vCores:2>, usedCapacity=0.5, absoluteUsedCapacity=0.5, numApps=1, numContainers=2
2020-02-06 02:11:42,136 INFO org.apache.hadoop.yarn.server.resourcemanager.scheduler.capacity.CapacityScheduler: Application attempt appattempt_1580953164575_0008_000001 released container container_1580953164575_0008_01_000002 on node: host: nodemaster:8050 #containers=2 available=<memory:16384, vCores:8> used=<memory:16384, vCores:2> with event: FINISHED
2020-02-06 02:11:42,204 INFO org.apache.hadoop.yarn.server.resourcemanager.ApplicationMasterService: application_1580953164575_0008 unregistered successfully. 
2020-02-06 02:11:42,369 INFO org.apache.hadoop.yarn.server.resourcemanager.rmcontainer.RMContainerImpl: container_1580953164575_0008_01_000003 Container Transitioned from RUNNING to COMPLETED
2020-02-06 02:11:42,369 INFO org.apache.hadoop.yarn.server.resourcemanager.scheduler.common.fica.FiCaSchedulerApp: Completed container: container_1580953164575_0008_01_000003 in state: COMPLETED event:FINISHED
2020-02-06 02:11:42,369 INFO org.apache.hadoop.yarn.server.resourcemanager.RMAuditLogger: USER=hadoop	OPERATION=AM Released Container	TARGET=SchedulerApp	RESULT=SUCCESS	APPID=application_1580953164575_0008	CONTAINERID=container_1580953164575_0008_01_000003
2020-02-06 02:11:42,369 INFO org.apache.hadoop.yarn.server.resourcemanager.scheduler.SchedulerNode: Released container container_1580953164575_0008_01_000003 of capacity <memory:12288, vCores:1> on host nodemaster:8050, which currently has 1 containers, <memory:4096, vCores:1> used and <memory:28672, vCores:9> available, release resources=true
2020-02-06 02:11:42,369 INFO org.apache.hadoop.yarn.server.resourcemanager.scheduler.capacity.LeafQueue: default used=<memory:4096, vCores:1> numContainers=1 user=hadoop user-resources=<memory:4096, vCores:1>
2020-02-06 02:11:42,369 INFO org.apache.hadoop.yarn.server.resourcemanager.scheduler.capacity.LeafQueue: completedContainer container=Container: [ContainerId: container_1580953164575_0008_01_000003, NodeId: nodemaster:8050, NodeHttpAddress: nodemaster:8042, Resource: <memory:12288, vCores:1>, Priority: 1, Token: Token { kind: ContainerToken, service: 172.28.1.15:8050 }, ] queue=default: capacity=1.0, absoluteCapacity=1.0, usedResources=<memory:4096, vCores:1>, usedCapacity=0.125, absoluteUsedCapacity=0.125, numApps=1, numContainers=1 cluster=<memory:32768, vCores:10>
2020-02-06 02:11:42,369 INFO org.apache.hadoop.yarn.server.resourcemanager.scheduler.capacity.ParentQueue: completedContainer queue=root usedCapacity=0.125 absoluteUsedCapacity=0.125 used=<memory:4096, vCores:1> cluster=<memory:32768, vCores:10>
2020-02-06 02:11:42,369 INFO org.apache.hadoop.yarn.server.resourcemanager.scheduler.capacity.ParentQueue: Re-sorting completed queue: root.default stats: default: capacity=1.0, absoluteCapacity=1.0, usedResources=<memory:4096, vCores:1>, usedCapacity=0.125, absoluteUsedCapacity=0.125, numApps=1, numContainers=1
2020-02-06 02:11:42,369 INFO org.apache.hadoop.yarn.server.resourcemanager.scheduler.capacity.CapacityScheduler: Application attempt appattempt_1580953164575_0008_000001 released container container_1580953164575_0008_01_000003 on node: host: nodemaster:8050 #containers=1 available=<memory:28672, vCores:9> used=<memory:4096, vCores:1> with event: FINISHED
2020-02-06 02:11:42,801 INFO org.apache.hadoop.yarn.server.resourcemanager.rmcontainer.RMContainerImpl: container_1580953164575_0008_01_000001 Container Transitioned from RUNNING to COMPLETED
2020-02-06 02:11:42,801 INFO org.apache.hadoop.yarn.server.resourcemanager.scheduler.common.fica.FiCaSchedulerApp: Completed container: container_1580953164575_0008_01_000001 in state: COMPLETED event:FINISHED
2020-02-06 02:11:42,801 INFO org.apache.hadoop.yarn.server.resourcemanager.ApplicationMasterService: Unregistering app attempt : appattempt_1580953164575_0008_000001
2020-02-06 02:11:42,801 INFO org.apache.hadoop.yarn.server.resourcemanager.security.AMRMTokenSecretManager: Application finished, removing password for appattempt_1580953164575_0008_000001
2020-02-06 02:11:42,801 INFO org.apache.hadoop.yarn.server.resourcemanager.RMAuditLogger: USER=hadoop	OPERATION=AM Released Container	TARGET=SchedulerApp	RESULT=SUCCESS	APPID=application_1580953164575_0008	CONTAINERID=container_1580953164575_0008_01_000001
2020-02-06 02:11:42,801 INFO org.apache.hadoop.yarn.server.resourcemanager.rmapp.attempt.RMAppAttemptImpl: appattempt_1580953164575_0008_000001 State change from FINISHING to FINISHED
2020-02-06 02:11:42,801 INFO org.apache.hadoop.yarn.server.resourcemanager.scheduler.SchedulerNode: Released container container_1580953164575_0008_01_000001 of capacity <memory:4096, vCores:1> on host nodemaster:8050, which currently has 0 containers, <memory:0, vCores:0> used and <memory:32768, vCores:10> available, release resources=true
2020-02-06 02:11:42,801 INFO org.apache.hadoop.yarn.server.resourcemanager.rmapp.RMAppImpl: application_1580953164575_0008 State change from FINISHING to FINISHED on event=ATTEMPT_FINISHED
2020-02-06 02:11:42,801 INFO org.apache.hadoop.yarn.server.resourcemanager.scheduler.capacity.LeafQueue: default used=<memory:0, vCores:0> numContainers=0 user=hadoop user-resources=<memory:0, vCores:0>
2020-02-06 02:11:42,801 INFO org.apache.hadoop.yarn.server.resourcemanager.RMAuditLogger: USER=hadoop	OPERATION=Application Finished - Succeeded	TARGET=RMAppManager	RESULT=SUCCESS	APPID=application_1580953164575_0008
2020-02-06 02:11:42,801 INFO org.apache.hadoop.yarn.server.resourcemanager.scheduler.capacity.LeafQueue: completedContainer container=Container: [ContainerId: container_1580953164575_0008_01_000001, NodeId: nodemaster:8050, NodeHttpAddress: nodemaster:8042, Resource: <memory:4096, vCores:1>, Priority: 0, Token: Token { kind: ContainerToken, service: 172.28.1.15:8050 }, ] queue=default: capacity=1.0, absoluteCapacity=1.0, usedResources=<memory:0, vCores:0>, usedCapacity=0.0, absoluteUsedCapacity=0.0, numApps=1, numContainers=0 cluster=<memory:32768, vCores:10>
2020-02-06 02:11:42,801 INFO org.apache.hadoop.yarn.server.resourcemanager.scheduler.capacity.ParentQueue: completedContainer queue=root usedCapacity=0.0 absoluteUsedCapacity=0.0 used=<memory:0, vCores:0> cluster=<memory:32768, vCores:10>
2020-02-06 02:11:42,801 INFO org.apache.hadoop.yarn.server.resourcemanager.scheduler.capacity.ParentQueue: Re-sorting completed queue: root.default stats: default: capacity=1.0, absoluteCapacity=1.0, usedResources=<memory:0, vCores:0>, usedCapacity=0.0, absoluteUsedCapacity=0.0, numApps=1, numContainers=0
2020-02-06 02:11:42,801 INFO org.apache.hadoop.yarn.server.resourcemanager.scheduler.capacity.CapacityScheduler: Application attempt appattempt_1580953164575_0008_000001 released container container_1580953164575_0008_01_000001 on node: host: nodemaster:8050 #containers=0 available=<memory:32768, vCores:10> used=<memory:0, vCores:0> with event: FINISHED
2020-02-06 02:11:42,801 INFO org.apache.hadoop.yarn.server.resourcemanager.RMAppManager$ApplicationSummary: appId=application_1580953164575_0008,name=gen,user=hadoop,queue=default,state=FINISHED,trackingUrl=http://nodemaster:8088/proxy/application_1580953164575_0008/,appMasterHost=172.28.1.15,startTime=1580955093374,finishTime=1580955102102,finalStatus=SUCCEEDED,memorySeconds=168614,vcoreSeconds=18,preemptedAMContainers=0,preemptedNonAMContainers=0,preemptedResources=<memory:0\, vCores:0>,applicationType=SPARK
2020-02-06 02:11:42,802 INFO org.apache.hadoop.yarn.server.resourcemanager.scheduler.capacity.CapacityScheduler: Application Attempt appattempt_1580953164575_0008_000001 is done. finalState=FINISHED
2020-02-06 02:11:42,802 INFO org.apache.hadoop.yarn.server.resourcemanager.scheduler.AppSchedulingInfo: Application application_1580953164575_0008 requests cleared
2020-02-06 02:11:42,802 INFO org.apache.hadoop.yarn.server.resourcemanager.amlauncher.AMLauncher: Cleaning master appattempt_1580953164575_0008_000001
2020-02-06 02:11:42,802 INFO org.apache.hadoop.yarn.server.resourcemanager.scheduler.capacity.LeafQueue: Application removed - appId: application_1580953164575_0008 user: hadoop queue: default #user-pending-applications: 0 #user-active-applications: 0 #queue-pending-applications: 0 #queue-active-applications: 0
2020-02-06 02:11:42,802 INFO org.apache.hadoop.yarn.server.resourcemanager.scheduler.capacity.ParentQueue: Application removed - appId: application_1580953164575_0008 user: hadoop leaf-queue of parent: root #applications: 0
2020-02-06 02:11:44,805 INFO org.apache.hadoop.yarn.server.resourcemanager.scheduler.capacity.CapacityScheduler: Null container completed...
2020-02-06 02:11:44,806 INFO org.apache.hadoop.yarn.server.resourcemanager.scheduler.capacity.CapacityScheduler: Null container completed...
2020-02-06 02:15:56,206 INFO org.apache.hadoop.yarn.server.resourcemanager.ClientRMService: Allocated new applicationId: 9
2020-02-06 02:15:59,549 WARN org.apache.hadoop.yarn.server.resourcemanager.rmapp.RMAppImpl: The specific max attempts: 0 for application: 9 is invalid, because it is out of the range [1, 2]. Use the global max attempts instead.
2020-02-06 02:15:59,549 INFO org.apache.hadoop.yarn.server.resourcemanager.ClientRMService: Application with id 9 submitted by user hadoop
2020-02-06 02:15:59,549 INFO org.apache.hadoop.yarn.server.resourcemanager.RMAuditLogger: USER=hadoop	IP=172.28.1.15	OPERATION=Submit Application Request	TARGET=ClientRMService	RESULT=SUCCESS	APPID=application_1580953164575_0009
2020-02-06 02:15:59,549 INFO org.apache.hadoop.yarn.server.resourcemanager.rmapp.RMAppImpl: Storing application with id application_1580953164575_0009
2020-02-06 02:15:59,549 INFO org.apache.hadoop.yarn.server.resourcemanager.rmapp.RMAppImpl: application_1580953164575_0009 State change from NEW to NEW_SAVING on event=START
2020-02-06 02:15:59,549 INFO org.apache.hadoop.yarn.server.resourcemanager.recovery.RMStateStore: Storing info for app: application_1580953164575_0009
2020-02-06 02:15:59,549 INFO org.apache.hadoop.yarn.server.resourcemanager.rmapp.RMAppImpl: application_1580953164575_0009 State change from NEW_SAVING to SUBMITTED on event=APP_NEW_SAVED
2020-02-06 02:15:59,549 INFO org.apache.hadoop.yarn.server.resourcemanager.scheduler.capacity.ParentQueue: Application added - appId: application_1580953164575_0009 user: hadoop leaf-queue of parent: root #applications: 1
2020-02-06 02:15:59,549 INFO org.apache.hadoop.yarn.server.resourcemanager.scheduler.capacity.CapacityScheduler: Accepted application application_1580953164575_0009 from user: hadoop, in queue: default
2020-02-06 02:15:59,549 INFO org.apache.hadoop.yarn.server.resourcemanager.rmapp.RMAppImpl: application_1580953164575_0009 State change from SUBMITTED to ACCEPTED on event=APP_ACCEPTED
2020-02-06 02:15:59,549 INFO org.apache.hadoop.yarn.server.resourcemanager.ApplicationMasterService: Registering app attempt : appattempt_1580953164575_0009_000001
2020-02-06 02:15:59,549 INFO org.apache.hadoop.yarn.server.resourcemanager.rmapp.attempt.RMAppAttemptImpl: appattempt_1580953164575_0009_000001 State change from NEW to SUBMITTED
2020-02-06 02:15:59,550 INFO org.apache.hadoop.yarn.server.resourcemanager.scheduler.capacity.LeafQueue: Application application_1580953164575_0009 from user: hadoop activated in queue: default
2020-02-06 02:15:59,550 INFO org.apache.hadoop.yarn.server.resourcemanager.scheduler.capacity.LeafQueue: Application added - appId: application_1580953164575_0009 user: org.apache.hadoop.yarn.server.resourcemanager.scheduler.capacity.LeafQueue$User@3612c75f, leaf-queue: default #user-pending-applications: 0 #user-active-applications: 1 #queue-pending-applications: 0 #queue-active-applications: 1
2020-02-06 02:15:59,550 INFO org.apache.hadoop.yarn.server.resourcemanager.scheduler.capacity.CapacityScheduler: Added Application Attempt appattempt_1580953164575_0009_000001 to scheduler from user hadoop in queue default
2020-02-06 02:15:59,550 INFO org.apache.hadoop.yarn.server.resourcemanager.rmapp.attempt.RMAppAttemptImpl: appattempt_1580953164575_0009_000001 State change from SUBMITTED to SCHEDULED
2020-02-06 02:16:00,131 INFO org.apache.hadoop.yarn.server.resourcemanager.rmcontainer.RMContainerImpl: container_1580953164575_0009_01_000001 Container Transitioned from NEW to ALLOCATED
2020-02-06 02:16:00,131 INFO org.apache.hadoop.yarn.server.resourcemanager.RMAuditLogger: USER=hadoop	OPERATION=AM Allocated Container	TARGET=SchedulerApp	RESULT=SUCCESS	APPID=application_1580953164575_0009	CONTAINERID=container_1580953164575_0009_01_000001
2020-02-06 02:16:00,131 INFO org.apache.hadoop.yarn.server.resourcemanager.scheduler.SchedulerNode: Assigned container container_1580953164575_0009_01_000001 of capacity <memory:4096, vCores:1> on host nodemaster:8050, which has 1 containers, <memory:4096, vCores:1> used and <memory:28672, vCores:9> available after allocation
2020-02-06 02:16:00,131 INFO org.apache.hadoop.yarn.server.resourcemanager.scheduler.capacity.LeafQueue: assignedContainer application attempt=appattempt_1580953164575_0009_000001 container=Container: [ContainerId: container_1580953164575_0009_01_000001, NodeId: nodemaster:8050, NodeHttpAddress: nodemaster:8042, Resource: <memory:4096, vCores:1>, Priority: 0, Token: null, ] queue=default: capacity=1.0, absoluteCapacity=1.0, usedResources=<memory:0, vCores:0>, usedCapacity=0.0, absoluteUsedCapacity=0.0, numApps=1, numContainers=0 clusterResource=<memory:32768, vCores:10> type=OFF_SWITCH requestedPartition=
2020-02-06 02:16:00,131 INFO org.apache.hadoop.yarn.server.resourcemanager.scheduler.capacity.ParentQueue: Re-sorting assigned queue: root.default stats: default: capacity=1.0, absoluteCapacity=1.0, usedResources=<memory:4096, vCores:1>, usedCapacity=0.125, absoluteUsedCapacity=0.125, numApps=1, numContainers=1
2020-02-06 02:16:00,131 INFO org.apache.hadoop.yarn.server.resourcemanager.scheduler.capacity.ParentQueue: assignedContainer queue=root usedCapacity=0.125 absoluteUsedCapacity=0.125 used=<memory:4096, vCores:1> cluster=<memory:32768, vCores:10>
2020-02-06 02:16:00,131 INFO org.apache.hadoop.yarn.server.resourcemanager.security.NMTokenSecretManagerInRM: Sending NMToken for nodeId : nodemaster:8050 for container : container_1580953164575_0009_01_000001
2020-02-06 02:16:00,132 INFO org.apache.hadoop.yarn.server.resourcemanager.rmcontainer.RMContainerImpl: container_1580953164575_0009_01_000001 Container Transitioned from ALLOCATED to ACQUIRED
2020-02-06 02:16:00,132 INFO org.apache.hadoop.yarn.server.resourcemanager.security.NMTokenSecretManagerInRM: Clear node set for appattempt_1580953164575_0009_000001
2020-02-06 02:16:00,132 INFO org.apache.hadoop.yarn.server.resourcemanager.rmapp.attempt.RMAppAttemptImpl: Storing attempt: AppId: application_1580953164575_0009 AttemptId: appattempt_1580953164575_0009_000001 MasterContainer: Container: [ContainerId: container_1580953164575_0009_01_000001, NodeId: nodemaster:8050, NodeHttpAddress: nodemaster:8042, Resource: <memory:4096, vCores:1>, Priority: 0, Token: Token { kind: ContainerToken, service: 172.28.1.15:8050 }, ]
2020-02-06 02:16:00,132 INFO org.apache.hadoop.yarn.server.resourcemanager.rmapp.attempt.RMAppAttemptImpl: appattempt_1580953164575_0009_000001 State change from SCHEDULED to ALLOCATED_SAVING
2020-02-06 02:16:00,132 INFO org.apache.hadoop.yarn.server.resourcemanager.rmapp.attempt.RMAppAttemptImpl: appattempt_1580953164575_0009_000001 State change from ALLOCATED_SAVING to ALLOCATED
2020-02-06 02:16:00,132 INFO org.apache.hadoop.yarn.server.resourcemanager.amlauncher.AMLauncher: Launching masterappattempt_1580953164575_0009_000001
2020-02-06 02:16:00,133 INFO org.apache.hadoop.yarn.server.resourcemanager.amlauncher.AMLauncher: Setting up container Container: [ContainerId: container_1580953164575_0009_01_000001, NodeId: nodemaster:8050, NodeHttpAddress: nodemaster:8042, Resource: <memory:4096, vCores:1>, Priority: 0, Token: Token { kind: ContainerToken, service: 172.28.1.15:8050 }, ] for AM appattempt_1580953164575_0009_000001
2020-02-06 02:16:00,133 INFO org.apache.hadoop.yarn.server.resourcemanager.amlauncher.AMLauncher: Command to launch container container_1580953164575_0009_01_000001 : {{JAVA_HOME}}/bin/java,-server,-Xmx512m,-Djava.io.tmpdir={{PWD}}/tmp,-Dspark.yarn.app.container.log.dir=<LOG_DIR>,org.apache.spark.deploy.yarn.ExecutorLauncher,--arg,'nodemaster:34665',--properties-file,{{PWD}}/__spark_conf__/__spark_conf__.properties,1>,<LOG_DIR>/stdout,2>,<LOG_DIR>/stderr
2020-02-06 02:16:00,133 INFO org.apache.hadoop.yarn.server.resourcemanager.security.AMRMTokenSecretManager: Create AMRMToken for ApplicationAttempt: appattempt_1580953164575_0009_000001
2020-02-06 02:16:00,133 INFO org.apache.hadoop.yarn.server.resourcemanager.security.AMRMTokenSecretManager: Creating password for appattempt_1580953164575_0009_000001
2020-02-06 02:16:00,138 INFO org.apache.hadoop.yarn.server.resourcemanager.amlauncher.AMLauncher: Done launching container Container: [ContainerId: container_1580953164575_0009_01_000001, NodeId: nodemaster:8050, NodeHttpAddress: nodemaster:8042, Resource: <memory:4096, vCores:1>, Priority: 0, Token: Token { kind: ContainerToken, service: 172.28.1.15:8050 }, ] for AM appattempt_1580953164575_0009_000001
2020-02-06 02:16:00,139 INFO org.apache.hadoop.yarn.server.resourcemanager.rmapp.attempt.RMAppAttemptImpl: appattempt_1580953164575_0009_000001 State change from ALLOCATED to LAUNCHED
2020-02-06 02:16:01,132 INFO org.apache.hadoop.yarn.server.resourcemanager.rmcontainer.RMContainerImpl: container_1580953164575_0009_01_000001 Container Transitioned from ACQUIRED to RUNNING
2020-02-06 02:16:02,504 INFO SecurityLogger.org.apache.hadoop.ipc.Server: Auth successful for appattempt_1580953164575_0009_000001 (auth:SIMPLE)
2020-02-06 02:16:02,506 INFO org.apache.hadoop.yarn.server.resourcemanager.ApplicationMasterService: AM registration appattempt_1580953164575_0009_000001
2020-02-06 02:16:02,506 INFO org.apache.hadoop.yarn.server.resourcemanager.RMAuditLogger: USER=hadoop	IP=172.28.1.15	OPERATION=Register App Master	TARGET=ApplicationMasterService	RESULT=SUCCESS	APPID=application_1580953164575_0009	APPATTEMPTID=appattempt_1580953164575_0009_000001
2020-02-06 02:16:02,506 INFO org.apache.hadoop.yarn.server.resourcemanager.rmapp.attempt.RMAppAttemptImpl: appattempt_1580953164575_0009_000001 State change from LAUNCHED to RUNNING
2020-02-06 02:16:02,506 INFO org.apache.hadoop.yarn.server.resourcemanager.rmapp.RMAppImpl: application_1580953164575_0009 State change from ACCEPTED to RUNNING on event=ATTEMPT_REGISTERED
2020-02-06 02:16:03,133 INFO org.apache.hadoop.yarn.server.resourcemanager.rmcontainer.RMContainerImpl: container_1580953164575_0009_01_000002 Container Transitioned from NEW to ALLOCATED
2020-02-06 02:16:03,133 INFO org.apache.hadoop.yarn.server.resourcemanager.RMAuditLogger: USER=hadoop	OPERATION=AM Allocated Container	TARGET=SchedulerApp	RESULT=SUCCESS	APPID=application_1580953164575_0009	CONTAINERID=container_1580953164575_0009_01_000002
2020-02-06 02:16:03,133 INFO org.apache.hadoop.yarn.server.resourcemanager.scheduler.SchedulerNode: Assigned container container_1580953164575_0009_01_000002 of capacity <memory:12288, vCores:1> on host nodemaster:8050, which has 2 containers, <memory:16384, vCores:2> used and <memory:16384, vCores:8> available after allocation
2020-02-06 02:16:03,133 INFO org.apache.hadoop.yarn.server.resourcemanager.scheduler.capacity.LeafQueue: assignedContainer application attempt=appattempt_1580953164575_0009_000001 container=Container: [ContainerId: container_1580953164575_0009_01_000002, NodeId: nodemaster:8050, NodeHttpAddress: nodemaster:8042, Resource: <memory:12288, vCores:1>, Priority: 1, Token: null, ] queue=default: capacity=1.0, absoluteCapacity=1.0, usedResources=<memory:4096, vCores:1>, usedCapacity=0.125, absoluteUsedCapacity=0.125, numApps=1, numContainers=1 clusterResource=<memory:32768, vCores:10> type=OFF_SWITCH requestedPartition=
2020-02-06 02:16:03,133 INFO org.apache.hadoop.yarn.server.resourcemanager.scheduler.capacity.ParentQueue: Re-sorting assigned queue: root.default stats: default: capacity=1.0, absoluteCapacity=1.0, usedResources=<memory:16384, vCores:2>, usedCapacity=0.5, absoluteUsedCapacity=0.5, numApps=1, numContainers=2
2020-02-06 02:16:03,133 INFO org.apache.hadoop.yarn.server.resourcemanager.scheduler.capacity.ParentQueue: assignedContainer queue=root usedCapacity=0.5 absoluteUsedCapacity=0.5 used=<memory:16384, vCores:2> cluster=<memory:32768, vCores:10>
2020-02-06 02:16:03,170 INFO org.apache.hadoop.yarn.server.resourcemanager.security.NMTokenSecretManagerInRM: Sending NMToken for nodeId : nodemaster:8050 for container : container_1580953164575_0009_01_000002
2020-02-06 02:16:03,170 INFO org.apache.hadoop.yarn.server.resourcemanager.rmcontainer.RMContainerImpl: container_1580953164575_0009_01_000002 Container Transitioned from ALLOCATED to ACQUIRED
2020-02-06 02:16:04,134 INFO org.apache.hadoop.yarn.server.resourcemanager.rmcontainer.RMContainerImpl: container_1580953164575_0009_01_000002 Container Transitioned from ACQUIRED to RUNNING
2020-02-06 02:16:04,134 INFO org.apache.hadoop.yarn.server.resourcemanager.rmcontainer.RMContainerImpl: container_1580953164575_0009_01_000003 Container Transitioned from NEW to ALLOCATED
2020-02-06 02:16:04,134 INFO org.apache.hadoop.yarn.server.resourcemanager.RMAuditLogger: USER=hadoop	OPERATION=AM Allocated Container	TARGET=SchedulerApp	RESULT=SUCCESS	APPID=application_1580953164575_0009	CONTAINERID=container_1580953164575_0009_01_000003
2020-02-06 02:16:04,135 INFO org.apache.hadoop.yarn.server.resourcemanager.scheduler.SchedulerNode: Assigned container container_1580953164575_0009_01_000003 of capacity <memory:12288, vCores:1> on host nodemaster:8050, which has 3 containers, <memory:28672, vCores:3> used and <memory:4096, vCores:7> available after allocation
2020-02-06 02:16:04,135 INFO org.apache.hadoop.yarn.server.resourcemanager.scheduler.capacity.LeafQueue: assignedContainer application attempt=appattempt_1580953164575_0009_000001 container=Container: [ContainerId: container_1580953164575_0009_01_000003, NodeId: nodemaster:8050, NodeHttpAddress: nodemaster:8042, Resource: <memory:12288, vCores:1>, Priority: 1, Token: null, ] queue=default: capacity=1.0, absoluteCapacity=1.0, usedResources=<memory:16384, vCores:2>, usedCapacity=0.5, absoluteUsedCapacity=0.5, numApps=1, numContainers=2 clusterResource=<memory:32768, vCores:10> type=OFF_SWITCH requestedPartition=
2020-02-06 02:16:04,135 INFO org.apache.hadoop.yarn.server.resourcemanager.scheduler.capacity.ParentQueue: Re-sorting assigned queue: root.default stats: default: capacity=1.0, absoluteCapacity=1.0, usedResources=<memory:28672, vCores:3>, usedCapacity=0.875, absoluteUsedCapacity=0.875, numApps=1, numContainers=3
2020-02-06 02:16:04,135 INFO org.apache.hadoop.yarn.server.resourcemanager.scheduler.capacity.ParentQueue: assignedContainer queue=root usedCapacity=0.875 absoluteUsedCapacity=0.875 used=<memory:28672, vCores:3> cluster=<memory:32768, vCores:10>
2020-02-06 02:16:05,580 INFO org.apache.hadoop.yarn.server.resourcemanager.rmcontainer.RMContainerImpl: container_1580953164575_0009_01_000003 Container Transitioned from ALLOCATED to ACQUIRED
2020-02-06 02:16:06,135 INFO org.apache.hadoop.yarn.server.resourcemanager.rmcontainer.RMContainerImpl: container_1580953164575_0009_01_000003 Container Transitioned from ACQUIRED to RUNNING
2020-02-06 02:16:08,582 INFO org.apache.hadoop.yarn.server.resourcemanager.scheduler.AppSchedulingInfo: checking for deactivate of application :application_1580953164575_0009
2020-02-06 02:16:20,999 INFO org.apache.hadoop.yarn.server.resourcemanager.rmapp.attempt.RMAppAttemptImpl: Updating application attempt appattempt_1580953164575_0009_000001 with final state: FINISHING, and exit status: -1000
2020-02-06 02:16:20,999 INFO org.apache.hadoop.yarn.server.resourcemanager.rmapp.attempt.RMAppAttemptImpl: appattempt_1580953164575_0009_000001 State change from RUNNING to FINAL_SAVING
2020-02-06 02:16:20,999 INFO org.apache.hadoop.yarn.server.resourcemanager.rmapp.RMAppImpl: Updating application application_1580953164575_0009 with final state: FINISHING
2020-02-06 02:16:20,999 INFO org.apache.hadoop.yarn.server.resourcemanager.rmapp.RMAppImpl: application_1580953164575_0009 State change from RUNNING to FINAL_SAVING on event=ATTEMPT_UNREGISTERED
2020-02-06 02:16:20,999 INFO org.apache.hadoop.yarn.server.resourcemanager.recovery.RMStateStore: Updating info for app: application_1580953164575_0009
2020-02-06 02:16:20,999 INFO org.apache.hadoop.yarn.server.resourcemanager.rmapp.attempt.RMAppAttemptImpl: appattempt_1580953164575_0009_000001 State change from FINAL_SAVING to FINISHING
2020-02-06 02:16:20,999 INFO org.apache.hadoop.yarn.server.resourcemanager.rmapp.RMAppImpl: application_1580953164575_0009 State change from FINAL_SAVING to FINISHING on event=APP_UPDATE_SAVED
2020-02-06 02:16:21,101 INFO org.apache.hadoop.yarn.server.resourcemanager.ApplicationMasterService: application_1580953164575_0009 unregistered successfully. 
2020-02-06 02:16:21,382 INFO org.apache.hadoop.yarn.server.resourcemanager.rmcontainer.RMContainerImpl: container_1580953164575_0009_01_000002 Container Transitioned from RUNNING to COMPLETED
2020-02-06 02:16:21,382 INFO org.apache.hadoop.yarn.server.resourcemanager.scheduler.common.fica.FiCaSchedulerApp: Completed container: container_1580953164575_0009_01_000002 in state: COMPLETED event:FINISHED
2020-02-06 02:16:21,382 INFO org.apache.hadoop.yarn.server.resourcemanager.RMAuditLogger: USER=hadoop	OPERATION=AM Released Container	TARGET=SchedulerApp	RESULT=SUCCESS	APPID=application_1580953164575_0009	CONTAINERID=container_1580953164575_0009_01_000002
2020-02-06 02:16:21,383 INFO org.apache.hadoop.yarn.server.resourcemanager.scheduler.SchedulerNode: Released container container_1580953164575_0009_01_000002 of capacity <memory:12288, vCores:1> on host nodemaster:8050, which currently has 2 containers, <memory:16384, vCores:2> used and <memory:16384, vCores:8> available, release resources=true
2020-02-06 02:16:21,383 INFO org.apache.hadoop.yarn.server.resourcemanager.scheduler.capacity.LeafQueue: default used=<memory:16384, vCores:2> numContainers=2 user=hadoop user-resources=<memory:16384, vCores:2>
2020-02-06 02:16:21,383 INFO org.apache.hadoop.yarn.server.resourcemanager.scheduler.capacity.LeafQueue: completedContainer container=Container: [ContainerId: container_1580953164575_0009_01_000002, NodeId: nodemaster:8050, NodeHttpAddress: nodemaster:8042, Resource: <memory:12288, vCores:1>, Priority: 1, Token: Token { kind: ContainerToken, service: 172.28.1.15:8050 }, ] queue=default: capacity=1.0, absoluteCapacity=1.0, usedResources=<memory:16384, vCores:2>, usedCapacity=0.5, absoluteUsedCapacity=0.5, numApps=1, numContainers=2 cluster=<memory:32768, vCores:10>
2020-02-06 02:16:21,383 INFO org.apache.hadoop.yarn.server.resourcemanager.scheduler.capacity.ParentQueue: completedContainer queue=root usedCapacity=0.5 absoluteUsedCapacity=0.5 used=<memory:16384, vCores:2> cluster=<memory:32768, vCores:10>
2020-02-06 02:16:21,383 INFO org.apache.hadoop.yarn.server.resourcemanager.scheduler.capacity.ParentQueue: Re-sorting completed queue: root.default stats: default: capacity=1.0, absoluteCapacity=1.0, usedResources=<memory:16384, vCores:2>, usedCapacity=0.5, absoluteUsedCapacity=0.5, numApps=1, numContainers=2
2020-02-06 02:16:21,383 INFO org.apache.hadoop.yarn.server.resourcemanager.scheduler.capacity.CapacityScheduler: Application attempt appattempt_1580953164575_0009_000001 released container container_1580953164575_0009_01_000002 on node: host: nodemaster:8050 #containers=2 available=<memory:16384, vCores:8> used=<memory:16384, vCores:2> with event: FINISHED
2020-02-06 02:16:21,432 INFO org.apache.hadoop.yarn.server.resourcemanager.rmcontainer.RMContainerImpl: container_1580953164575_0009_01_000003 Container Transitioned from RUNNING to COMPLETED
2020-02-06 02:16:21,432 INFO org.apache.hadoop.yarn.server.resourcemanager.scheduler.common.fica.FiCaSchedulerApp: Completed container: container_1580953164575_0009_01_000003 in state: COMPLETED event:FINISHED
2020-02-06 02:16:21,432 INFO org.apache.hadoop.yarn.server.resourcemanager.RMAuditLogger: USER=hadoop	OPERATION=AM Released Container	TARGET=SchedulerApp	RESULT=SUCCESS	APPID=application_1580953164575_0009	CONTAINERID=container_1580953164575_0009_01_000003
2020-02-06 02:16:21,432 INFO org.apache.hadoop.yarn.server.resourcemanager.scheduler.SchedulerNode: Released container container_1580953164575_0009_01_000003 of capacity <memory:12288, vCores:1> on host nodemaster:8050, which currently has 1 containers, <memory:4096, vCores:1> used and <memory:28672, vCores:9> available, release resources=true
2020-02-06 02:16:21,432 INFO org.apache.hadoop.yarn.server.resourcemanager.scheduler.capacity.LeafQueue: default used=<memory:4096, vCores:1> numContainers=1 user=hadoop user-resources=<memory:4096, vCores:1>
2020-02-06 02:16:21,433 INFO org.apache.hadoop.yarn.server.resourcemanager.scheduler.capacity.LeafQueue: completedContainer container=Container: [ContainerId: container_1580953164575_0009_01_000003, NodeId: nodemaster:8050, NodeHttpAddress: nodemaster:8042, Resource: <memory:12288, vCores:1>, Priority: 1, Token: Token { kind: ContainerToken, service: 172.28.1.15:8050 }, ] queue=default: capacity=1.0, absoluteCapacity=1.0, usedResources=<memory:4096, vCores:1>, usedCapacity=0.125, absoluteUsedCapacity=0.125, numApps=1, numContainers=1 cluster=<memory:32768, vCores:10>
2020-02-06 02:16:21,433 INFO org.apache.hadoop.yarn.server.resourcemanager.scheduler.capacity.ParentQueue: completedContainer queue=root usedCapacity=0.125 absoluteUsedCapacity=0.125 used=<memory:4096, vCores:1> cluster=<memory:32768, vCores:10>
2020-02-06 02:16:21,433 INFO org.apache.hadoop.yarn.server.resourcemanager.scheduler.capacity.ParentQueue: Re-sorting completed queue: root.default stats: default: capacity=1.0, absoluteCapacity=1.0, usedResources=<memory:4096, vCores:1>, usedCapacity=0.125, absoluteUsedCapacity=0.125, numApps=1, numContainers=1
2020-02-06 02:16:21,433 INFO org.apache.hadoop.yarn.server.resourcemanager.scheduler.capacity.CapacityScheduler: Application attempt appattempt_1580953164575_0009_000001 released container container_1580953164575_0009_01_000003 on node: host: nodemaster:8050 #containers=1 available=<memory:28672, vCores:9> used=<memory:4096, vCores:1> with event: FINISHED
2020-02-06 02:16:21,472 INFO org.apache.hadoop.yarn.server.resourcemanager.rmcontainer.RMContainerImpl: container_1580953164575_0009_01_000001 Container Transitioned from RUNNING to COMPLETED
2020-02-06 02:16:21,472 INFO org.apache.hadoop.yarn.server.resourcemanager.scheduler.common.fica.FiCaSchedulerApp: Completed container: container_1580953164575_0009_01_000001 in state: COMPLETED event:FINISHED
2020-02-06 02:16:21,473 INFO org.apache.hadoop.yarn.server.resourcemanager.RMAuditLogger: USER=hadoop	OPERATION=AM Released Container	TARGET=SchedulerApp	RESULT=SUCCESS	APPID=application_1580953164575_0009	CONTAINERID=container_1580953164575_0009_01_000001
2020-02-06 02:16:21,473 INFO org.apache.hadoop.yarn.server.resourcemanager.ApplicationMasterService: Unregistering app attempt : appattempt_1580953164575_0009_000001
2020-02-06 02:16:21,473 INFO org.apache.hadoop.yarn.server.resourcemanager.scheduler.SchedulerNode: Released container container_1580953164575_0009_01_000001 of capacity <memory:4096, vCores:1> on host nodemaster:8050, which currently has 0 containers, <memory:0, vCores:0> used and <memory:32768, vCores:10> available, release resources=true
2020-02-06 02:16:21,473 INFO org.apache.hadoop.yarn.server.resourcemanager.security.AMRMTokenSecretManager: Application finished, removing password for appattempt_1580953164575_0009_000001
2020-02-06 02:16:21,473 INFO org.apache.hadoop.yarn.server.resourcemanager.rmapp.attempt.RMAppAttemptImpl: appattempt_1580953164575_0009_000001 State change from FINISHING to FINISHED
2020-02-06 02:16:21,473 INFO org.apache.hadoop.yarn.server.resourcemanager.scheduler.capacity.LeafQueue: default used=<memory:0, vCores:0> numContainers=0 user=hadoop user-resources=<memory:0, vCores:0>
2020-02-06 02:16:21,473 INFO org.apache.hadoop.yarn.server.resourcemanager.rmapp.RMAppImpl: application_1580953164575_0009 State change from FINISHING to FINISHED on event=ATTEMPT_FINISHED
2020-02-06 02:16:21,473 INFO org.apache.hadoop.yarn.server.resourcemanager.scheduler.capacity.LeafQueue: completedContainer container=Container: [ContainerId: container_1580953164575_0009_01_000001, NodeId: nodemaster:8050, NodeHttpAddress: nodemaster:8042, Resource: <memory:4096, vCores:1>, Priority: 0, Token: Token { kind: ContainerToken, service: 172.28.1.15:8050 }, ] queue=default: capacity=1.0, absoluteCapacity=1.0, usedResources=<memory:0, vCores:0>, usedCapacity=0.0, absoluteUsedCapacity=0.0, numApps=1, numContainers=0 cluster=<memory:32768, vCores:10>
2020-02-06 02:16:21,473 INFO org.apache.hadoop.yarn.server.resourcemanager.scheduler.capacity.ParentQueue: completedContainer queue=root usedCapacity=0.0 absoluteUsedCapacity=0.0 used=<memory:0, vCores:0> cluster=<memory:32768, vCores:10>
2020-02-06 02:16:21,473 INFO org.apache.hadoop.yarn.server.resourcemanager.RMAuditLogger: USER=hadoop	OPERATION=Application Finished - Succeeded	TARGET=RMAppManager	RESULT=SUCCESS	APPID=application_1580953164575_0009
2020-02-06 02:16:21,473 INFO org.apache.hadoop.yarn.server.resourcemanager.scheduler.capacity.ParentQueue: Re-sorting completed queue: root.default stats: default: capacity=1.0, absoluteCapacity=1.0, usedResources=<memory:0, vCores:0>, usedCapacity=0.0, absoluteUsedCapacity=0.0, numApps=1, numContainers=0
2020-02-06 02:16:21,473 INFO org.apache.hadoop.yarn.server.resourcemanager.scheduler.capacity.CapacityScheduler: Application attempt appattempt_1580953164575_0009_000001 released container container_1580953164575_0009_01_000001 on node: host: nodemaster:8050 #containers=0 available=<memory:32768, vCores:10> used=<memory:0, vCores:0> with event: FINISHED
2020-02-06 02:16:21,473 INFO org.apache.hadoop.yarn.server.resourcemanager.scheduler.capacity.CapacityScheduler: Application Attempt appattempt_1580953164575_0009_000001 is done. finalState=FINISHED
2020-02-06 02:16:21,473 INFO org.apache.hadoop.yarn.server.resourcemanager.RMAppManager$ApplicationSummary: appId=application_1580953164575_0009,name=import,user=hadoop,queue=default,state=FINISHED,trackingUrl=http://nodemaster:8088/proxy/application_1580953164575_0009/,appMasterHost=172.28.1.15,startTime=1580955359549,finishTime=1580955380999,finalStatus=SUCCEEDED,memorySeconds=524212,vcoreSeconds=56,preemptedAMContainers=0,preemptedNonAMContainers=0,preemptedResources=<memory:0\, vCores:0>,applicationType=SPARK
2020-02-06 02:16:21,473 INFO org.apache.hadoop.yarn.server.resourcemanager.scheduler.AppSchedulingInfo: Application application_1580953164575_0009 requests cleared
2020-02-06 02:16:21,473 INFO org.apache.hadoop.yarn.server.resourcemanager.scheduler.capacity.LeafQueue: Application removed - appId: application_1580953164575_0009 user: hadoop queue: default #user-pending-applications: 0 #user-active-applications: 0 #queue-pending-applications: 0 #queue-active-applications: 0
2020-02-06 02:16:21,473 INFO org.apache.hadoop.yarn.server.resourcemanager.scheduler.capacity.ParentQueue: Application removed - appId: application_1580953164575_0009 user: hadoop leaf-queue of parent: root #applications: 0
2020-02-06 02:16:21,473 INFO org.apache.hadoop.yarn.server.resourcemanager.amlauncher.AMLauncher: Cleaning master appattempt_1580953164575_0009_000001
2020-02-06 02:16:23,477 INFO org.apache.hadoop.yarn.server.resourcemanager.scheduler.capacity.CapacityScheduler: Null container completed...
2020-02-06 02:16:23,477 INFO org.apache.hadoop.yarn.server.resourcemanager.scheduler.capacity.CapacityScheduler: Null container completed...
2020-02-06 02:27:15,304 INFO org.apache.hadoop.yarn.server.resourcemanager.ClientRMService: Allocated new applicationId: 10
2020-02-06 02:27:18,382 WARN org.apache.hadoop.yarn.server.resourcemanager.rmapp.RMAppImpl: The specific max attempts: 0 for application: 10 is invalid, because it is out of the range [1, 2]. Use the global max attempts instead.
2020-02-06 02:27:18,382 INFO org.apache.hadoop.yarn.server.resourcemanager.ClientRMService: Application with id 10 submitted by user hadoop
2020-02-06 02:27:18,382 INFO org.apache.hadoop.yarn.server.resourcemanager.RMAuditLogger: USER=hadoop	IP=172.28.1.15	OPERATION=Submit Application Request	TARGET=ClientRMService	RESULT=SUCCESS	APPID=application_1580953164575_0010
2020-02-06 02:27:18,382 INFO org.apache.hadoop.yarn.server.resourcemanager.rmapp.RMAppImpl: Storing application with id application_1580953164575_0010
2020-02-06 02:27:18,382 INFO org.apache.hadoop.yarn.server.resourcemanager.rmapp.RMAppImpl: application_1580953164575_0010 State change from NEW to NEW_SAVING on event=START
2020-02-06 02:27:18,382 INFO org.apache.hadoop.yarn.server.resourcemanager.recovery.RMStateStore: Storing info for app: application_1580953164575_0010
2020-02-06 02:27:18,382 INFO org.apache.hadoop.yarn.server.resourcemanager.rmapp.RMAppImpl: application_1580953164575_0010 State change from NEW_SAVING to SUBMITTED on event=APP_NEW_SAVED
2020-02-06 02:27:18,382 INFO org.apache.hadoop.yarn.server.resourcemanager.scheduler.capacity.ParentQueue: Application added - appId: application_1580953164575_0010 user: hadoop leaf-queue of parent: root #applications: 1
2020-02-06 02:27:18,382 INFO org.apache.hadoop.yarn.server.resourcemanager.scheduler.capacity.CapacityScheduler: Accepted application application_1580953164575_0010 from user: hadoop, in queue: default
2020-02-06 02:27:18,383 INFO org.apache.hadoop.yarn.server.resourcemanager.rmapp.RMAppImpl: application_1580953164575_0010 State change from SUBMITTED to ACCEPTED on event=APP_ACCEPTED
2020-02-06 02:27:18,383 INFO org.apache.hadoop.yarn.server.resourcemanager.ApplicationMasterService: Registering app attempt : appattempt_1580953164575_0010_000001
2020-02-06 02:27:18,383 INFO org.apache.hadoop.yarn.server.resourcemanager.rmapp.attempt.RMAppAttemptImpl: appattempt_1580953164575_0010_000001 State change from NEW to SUBMITTED
2020-02-06 02:27:18,383 INFO org.apache.hadoop.yarn.server.resourcemanager.scheduler.capacity.LeafQueue: Application application_1580953164575_0010 from user: hadoop activated in queue: default
2020-02-06 02:27:18,383 INFO org.apache.hadoop.yarn.server.resourcemanager.scheduler.capacity.LeafQueue: Application added - appId: application_1580953164575_0010 user: org.apache.hadoop.yarn.server.resourcemanager.scheduler.capacity.LeafQueue$User@281a8fe4, leaf-queue: default #user-pending-applications: 0 #user-active-applications: 1 #queue-pending-applications: 0 #queue-active-applications: 1
2020-02-06 02:27:18,383 INFO org.apache.hadoop.yarn.server.resourcemanager.scheduler.capacity.CapacityScheduler: Added Application Attempt appattempt_1580953164575_0010_000001 to scheduler from user hadoop in queue default
2020-02-06 02:27:18,383 INFO org.apache.hadoop.yarn.server.resourcemanager.rmapp.attempt.RMAppAttemptImpl: appattempt_1580953164575_0010_000001 State change from SUBMITTED to SCHEDULED
2020-02-06 02:27:19,274 INFO org.apache.hadoop.yarn.server.resourcemanager.rmcontainer.RMContainerImpl: container_1580953164575_0010_01_000001 Container Transitioned from NEW to ALLOCATED
2020-02-06 02:27:19,274 INFO org.apache.hadoop.yarn.server.resourcemanager.RMAuditLogger: USER=hadoop	OPERATION=AM Allocated Container	TARGET=SchedulerApp	RESULT=SUCCESS	APPID=application_1580953164575_0010	CONTAINERID=container_1580953164575_0010_01_000001
2020-02-06 02:27:19,274 INFO org.apache.hadoop.yarn.server.resourcemanager.scheduler.SchedulerNode: Assigned container container_1580953164575_0010_01_000001 of capacity <memory:4096, vCores:1> on host nodemaster:8050, which has 1 containers, <memory:4096, vCores:1> used and <memory:28672, vCores:9> available after allocation
2020-02-06 02:27:19,274 INFO org.apache.hadoop.yarn.server.resourcemanager.scheduler.capacity.LeafQueue: assignedContainer application attempt=appattempt_1580953164575_0010_000001 container=Container: [ContainerId: container_1580953164575_0010_01_000001, NodeId: nodemaster:8050, NodeHttpAddress: nodemaster:8042, Resource: <memory:4096, vCores:1>, Priority: 0, Token: null, ] queue=default: capacity=1.0, absoluteCapacity=1.0, usedResources=<memory:0, vCores:0>, usedCapacity=0.0, absoluteUsedCapacity=0.0, numApps=1, numContainers=0 clusterResource=<memory:32768, vCores:10> type=OFF_SWITCH requestedPartition=
2020-02-06 02:27:19,274 INFO org.apache.hadoop.yarn.server.resourcemanager.scheduler.capacity.ParentQueue: Re-sorting assigned queue: root.default stats: default: capacity=1.0, absoluteCapacity=1.0, usedResources=<memory:4096, vCores:1>, usedCapacity=0.125, absoluteUsedCapacity=0.125, numApps=1, numContainers=1
2020-02-06 02:27:19,274 INFO org.apache.hadoop.yarn.server.resourcemanager.scheduler.capacity.ParentQueue: assignedContainer queue=root usedCapacity=0.125 absoluteUsedCapacity=0.125 used=<memory:4096, vCores:1> cluster=<memory:32768, vCores:10>
2020-02-06 02:27:19,274 INFO org.apache.hadoop.yarn.server.resourcemanager.security.NMTokenSecretManagerInRM: Sending NMToken for nodeId : nodemaster:8050 for container : container_1580953164575_0010_01_000001
2020-02-06 02:27:19,275 INFO org.apache.hadoop.yarn.server.resourcemanager.rmcontainer.RMContainerImpl: container_1580953164575_0010_01_000001 Container Transitioned from ALLOCATED to ACQUIRED
2020-02-06 02:27:19,275 INFO org.apache.hadoop.yarn.server.resourcemanager.security.NMTokenSecretManagerInRM: Clear node set for appattempt_1580953164575_0010_000001
2020-02-06 02:27:19,275 INFO org.apache.hadoop.yarn.server.resourcemanager.rmapp.attempt.RMAppAttemptImpl: Storing attempt: AppId: application_1580953164575_0010 AttemptId: appattempt_1580953164575_0010_000001 MasterContainer: Container: [ContainerId: container_1580953164575_0010_01_000001, NodeId: nodemaster:8050, NodeHttpAddress: nodemaster:8042, Resource: <memory:4096, vCores:1>, Priority: 0, Token: Token { kind: ContainerToken, service: 172.28.1.15:8050 }, ]
2020-02-06 02:27:19,275 INFO org.apache.hadoop.yarn.server.resourcemanager.rmapp.attempt.RMAppAttemptImpl: appattempt_1580953164575_0010_000001 State change from SCHEDULED to ALLOCATED_SAVING
2020-02-06 02:27:19,275 INFO org.apache.hadoop.yarn.server.resourcemanager.rmapp.attempt.RMAppAttemptImpl: appattempt_1580953164575_0010_000001 State change from ALLOCATED_SAVING to ALLOCATED
2020-02-06 02:27:19,275 INFO org.apache.hadoop.yarn.server.resourcemanager.amlauncher.AMLauncher: Launching masterappattempt_1580953164575_0010_000001
2020-02-06 02:27:19,276 INFO org.apache.hadoop.yarn.server.resourcemanager.amlauncher.AMLauncher: Setting up container Container: [ContainerId: container_1580953164575_0010_01_000001, NodeId: nodemaster:8050, NodeHttpAddress: nodemaster:8042, Resource: <memory:4096, vCores:1>, Priority: 0, Token: Token { kind: ContainerToken, service: 172.28.1.15:8050 }, ] for AM appattempt_1580953164575_0010_000001
2020-02-06 02:27:19,276 INFO org.apache.hadoop.yarn.server.resourcemanager.amlauncher.AMLauncher: Command to launch container container_1580953164575_0010_01_000001 : {{JAVA_HOME}}/bin/java,-server,-Xmx512m,-Djava.io.tmpdir={{PWD}}/tmp,-Dspark.yarn.app.container.log.dir=<LOG_DIR>,org.apache.spark.deploy.yarn.ExecutorLauncher,--arg,'nodemaster:40875',--properties-file,{{PWD}}/__spark_conf__/__spark_conf__.properties,1>,<LOG_DIR>/stdout,2>,<LOG_DIR>/stderr
2020-02-06 02:27:19,276 INFO org.apache.hadoop.yarn.server.resourcemanager.security.AMRMTokenSecretManager: Create AMRMToken for ApplicationAttempt: appattempt_1580953164575_0010_000001
2020-02-06 02:27:19,276 INFO org.apache.hadoop.yarn.server.resourcemanager.security.AMRMTokenSecretManager: Creating password for appattempt_1580953164575_0010_000001
2020-02-06 02:27:19,282 INFO org.apache.hadoop.yarn.server.resourcemanager.amlauncher.AMLauncher: Done launching container Container: [ContainerId: container_1580953164575_0010_01_000001, NodeId: nodemaster:8050, NodeHttpAddress: nodemaster:8042, Resource: <memory:4096, vCores:1>, Priority: 0, Token: Token { kind: ContainerToken, service: 172.28.1.15:8050 }, ] for AM appattempt_1580953164575_0010_000001
2020-02-06 02:27:19,282 INFO org.apache.hadoop.yarn.server.resourcemanager.rmapp.attempt.RMAppAttemptImpl: appattempt_1580953164575_0010_000001 State change from ALLOCATED to LAUNCHED
2020-02-06 02:27:20,274 INFO org.apache.hadoop.yarn.server.resourcemanager.rmcontainer.RMContainerImpl: container_1580953164575_0010_01_000001 Container Transitioned from ACQUIRED to RUNNING
2020-02-06 02:27:21,728 INFO SecurityLogger.org.apache.hadoop.ipc.Server: Auth successful for appattempt_1580953164575_0010_000001 (auth:SIMPLE)
2020-02-06 02:27:21,730 INFO org.apache.hadoop.yarn.server.resourcemanager.ApplicationMasterService: AM registration appattempt_1580953164575_0010_000001
2020-02-06 02:27:21,730 INFO org.apache.hadoop.yarn.server.resourcemanager.RMAuditLogger: USER=hadoop	IP=172.28.1.15	OPERATION=Register App Master	TARGET=ApplicationMasterService	RESULT=SUCCESS	APPID=application_1580953164575_0010	APPATTEMPTID=appattempt_1580953164575_0010_000001
2020-02-06 02:27:21,730 INFO org.apache.hadoop.yarn.server.resourcemanager.rmapp.attempt.RMAppAttemptImpl: appattempt_1580953164575_0010_000001 State change from LAUNCHED to RUNNING
2020-02-06 02:27:21,730 INFO org.apache.hadoop.yarn.server.resourcemanager.rmapp.RMAppImpl: application_1580953164575_0010 State change from ACCEPTED to RUNNING on event=ATTEMPT_REGISTERED
2020-02-06 02:27:22,276 INFO org.apache.hadoop.yarn.server.resourcemanager.rmcontainer.RMContainerImpl: container_1580953164575_0010_01_000002 Container Transitioned from NEW to ALLOCATED
2020-02-06 02:27:22,276 INFO org.apache.hadoop.yarn.server.resourcemanager.RMAuditLogger: USER=hadoop	OPERATION=AM Allocated Container	TARGET=SchedulerApp	RESULT=SUCCESS	APPID=application_1580953164575_0010	CONTAINERID=container_1580953164575_0010_01_000002
2020-02-06 02:27:22,276 INFO org.apache.hadoop.yarn.server.resourcemanager.scheduler.SchedulerNode: Assigned container container_1580953164575_0010_01_000002 of capacity <memory:12288, vCores:1> on host nodemaster:8050, which has 2 containers, <memory:16384, vCores:2> used and <memory:16384, vCores:8> available after allocation
2020-02-06 02:27:22,276 INFO org.apache.hadoop.yarn.server.resourcemanager.scheduler.capacity.LeafQueue: assignedContainer application attempt=appattempt_1580953164575_0010_000001 container=Container: [ContainerId: container_1580953164575_0010_01_000002, NodeId: nodemaster:8050, NodeHttpAddress: nodemaster:8042, Resource: <memory:12288, vCores:1>, Priority: 1, Token: null, ] queue=default: capacity=1.0, absoluteCapacity=1.0, usedResources=<memory:4096, vCores:1>, usedCapacity=0.125, absoluteUsedCapacity=0.125, numApps=1, numContainers=1 clusterResource=<memory:32768, vCores:10> type=OFF_SWITCH requestedPartition=
2020-02-06 02:27:22,276 INFO org.apache.hadoop.yarn.server.resourcemanager.scheduler.capacity.ParentQueue: Re-sorting assigned queue: root.default stats: default: capacity=1.0, absoluteCapacity=1.0, usedResources=<memory:16384, vCores:2>, usedCapacity=0.5, absoluteUsedCapacity=0.5, numApps=1, numContainers=2
2020-02-06 02:27:22,276 INFO org.apache.hadoop.yarn.server.resourcemanager.scheduler.capacity.ParentQueue: assignedContainer queue=root usedCapacity=0.5 absoluteUsedCapacity=0.5 used=<memory:16384, vCores:2> cluster=<memory:32768, vCores:10>
2020-02-06 02:27:22,399 INFO org.apache.hadoop.yarn.server.resourcemanager.security.NMTokenSecretManagerInRM: Sending NMToken for nodeId : nodemaster:8050 for container : container_1580953164575_0010_01_000002
2020-02-06 02:27:22,399 INFO org.apache.hadoop.yarn.server.resourcemanager.rmcontainer.RMContainerImpl: container_1580953164575_0010_01_000002 Container Transitioned from ALLOCATED to ACQUIRED
2020-02-06 02:27:23,276 INFO org.apache.hadoop.yarn.server.resourcemanager.rmcontainer.RMContainerImpl: container_1580953164575_0010_01_000002 Container Transitioned from ACQUIRED to RUNNING
2020-02-06 02:27:23,276 INFO org.apache.hadoop.yarn.server.resourcemanager.rmcontainer.RMContainerImpl: container_1580953164575_0010_01_000003 Container Transitioned from NEW to ALLOCATED
2020-02-06 02:27:23,276 INFO org.apache.hadoop.yarn.server.resourcemanager.RMAuditLogger: USER=hadoop	OPERATION=AM Allocated Container	TARGET=SchedulerApp	RESULT=SUCCESS	APPID=application_1580953164575_0010	CONTAINERID=container_1580953164575_0010_01_000003
2020-02-06 02:27:23,276 INFO org.apache.hadoop.yarn.server.resourcemanager.scheduler.SchedulerNode: Assigned container container_1580953164575_0010_01_000003 of capacity <memory:12288, vCores:1> on host nodemaster:8050, which has 3 containers, <memory:28672, vCores:3> used and <memory:4096, vCores:7> available after allocation
2020-02-06 02:27:23,276 INFO org.apache.hadoop.yarn.server.resourcemanager.scheduler.capacity.LeafQueue: assignedContainer application attempt=appattempt_1580953164575_0010_000001 container=Container: [ContainerId: container_1580953164575_0010_01_000003, NodeId: nodemaster:8050, NodeHttpAddress: nodemaster:8042, Resource: <memory:12288, vCores:1>, Priority: 1, Token: null, ] queue=default: capacity=1.0, absoluteCapacity=1.0, usedResources=<memory:16384, vCores:2>, usedCapacity=0.5, absoluteUsedCapacity=0.5, numApps=1, numContainers=2 clusterResource=<memory:32768, vCores:10> type=OFF_SWITCH requestedPartition=
2020-02-06 02:27:23,276 INFO org.apache.hadoop.yarn.server.resourcemanager.scheduler.capacity.ParentQueue: Re-sorting assigned queue: root.default stats: default: capacity=1.0, absoluteCapacity=1.0, usedResources=<memory:28672, vCores:3>, usedCapacity=0.875, absoluteUsedCapacity=0.875, numApps=1, numContainers=3
2020-02-06 02:27:23,276 INFO org.apache.hadoop.yarn.server.resourcemanager.scheduler.capacity.ParentQueue: assignedContainer queue=root usedCapacity=0.875 absoluteUsedCapacity=0.875 used=<memory:28672, vCores:3> cluster=<memory:32768, vCores:10>
2020-02-06 02:27:24,810 INFO org.apache.hadoop.yarn.server.resourcemanager.rmcontainer.RMContainerImpl: container_1580953164575_0010_01_000003 Container Transitioned from ALLOCATED to ACQUIRED
2020-02-06 02:27:25,277 INFO org.apache.hadoop.yarn.server.resourcemanager.rmcontainer.RMContainerImpl: container_1580953164575_0010_01_000003 Container Transitioned from ACQUIRED to RUNNING
2020-02-06 02:27:27,812 INFO org.apache.hadoop.yarn.server.resourcemanager.scheduler.AppSchedulingInfo: checking for deactivate of application :application_1580953164575_0010
2020-02-06 02:27:32,584 INFO org.apache.hadoop.yarn.server.resourcemanager.rmapp.attempt.RMAppAttemptImpl: Updating application attempt appattempt_1580953164575_0010_000001 with final state: FINISHING, and exit status: -1000
2020-02-06 02:27:32,584 INFO org.apache.hadoop.yarn.server.resourcemanager.rmapp.attempt.RMAppAttemptImpl: appattempt_1580953164575_0010_000001 State change from RUNNING to FINAL_SAVING
2020-02-06 02:27:32,584 INFO org.apache.hadoop.yarn.server.resourcemanager.rmapp.RMAppImpl: Updating application application_1580953164575_0010 with final state: FINISHING
2020-02-06 02:27:32,584 INFO org.apache.hadoop.yarn.server.resourcemanager.rmapp.RMAppImpl: application_1580953164575_0010 State change from RUNNING to FINAL_SAVING on event=ATTEMPT_UNREGISTERED
2020-02-06 02:27:32,584 INFO org.apache.hadoop.yarn.server.resourcemanager.recovery.RMStateStore: Updating info for app: application_1580953164575_0010
2020-02-06 02:27:32,585 INFO org.apache.hadoop.yarn.server.resourcemanager.rmapp.attempt.RMAppAttemptImpl: appattempt_1580953164575_0010_000001 State change from FINAL_SAVING to FINISHING
2020-02-06 02:27:32,585 INFO org.apache.hadoop.yarn.server.resourcemanager.rmapp.RMAppImpl: application_1580953164575_0010 State change from FINAL_SAVING to FINISHING on event=APP_UPDATE_SAVED
2020-02-06 02:27:32,618 INFO org.apache.hadoop.yarn.server.resourcemanager.rmcontainer.RMContainerImpl: container_1580953164575_0010_01_000002 Container Transitioned from RUNNING to COMPLETED
2020-02-06 02:27:32,618 INFO org.apache.hadoop.yarn.server.resourcemanager.scheduler.common.fica.FiCaSchedulerApp: Completed container: container_1580953164575_0010_01_000002 in state: COMPLETED event:FINISHED
2020-02-06 02:27:32,618 INFO org.apache.hadoop.yarn.server.resourcemanager.RMAuditLogger: USER=hadoop	OPERATION=AM Released Container	TARGET=SchedulerApp	RESULT=SUCCESS	APPID=application_1580953164575_0010	CONTAINERID=container_1580953164575_0010_01_000002
2020-02-06 02:27:32,618 INFO org.apache.hadoop.yarn.server.resourcemanager.scheduler.SchedulerNode: Released container container_1580953164575_0010_01_000002 of capacity <memory:12288, vCores:1> on host nodemaster:8050, which currently has 2 containers, <memory:16384, vCores:2> used and <memory:16384, vCores:8> available, release resources=true
2020-02-06 02:27:32,618 INFO org.apache.hadoop.yarn.server.resourcemanager.scheduler.capacity.LeafQueue: default used=<memory:16384, vCores:2> numContainers=2 user=hadoop user-resources=<memory:16384, vCores:2>
2020-02-06 02:27:32,619 INFO org.apache.hadoop.yarn.server.resourcemanager.scheduler.capacity.LeafQueue: completedContainer container=Container: [ContainerId: container_1580953164575_0010_01_000002, NodeId: nodemaster:8050, NodeHttpAddress: nodemaster:8042, Resource: <memory:12288, vCores:1>, Priority: 1, Token: Token { kind: ContainerToken, service: 172.28.1.15:8050 }, ] queue=default: capacity=1.0, absoluteCapacity=1.0, usedResources=<memory:16384, vCores:2>, usedCapacity=0.5, absoluteUsedCapacity=0.5, numApps=1, numContainers=2 cluster=<memory:32768, vCores:10>
2020-02-06 02:27:32,619 INFO org.apache.hadoop.yarn.server.resourcemanager.scheduler.capacity.ParentQueue: completedContainer queue=root usedCapacity=0.5 absoluteUsedCapacity=0.5 used=<memory:16384, vCores:2> cluster=<memory:32768, vCores:10>
2020-02-06 02:27:32,619 INFO org.apache.hadoop.yarn.server.resourcemanager.scheduler.capacity.ParentQueue: Re-sorting completed queue: root.default stats: default: capacity=1.0, absoluteCapacity=1.0, usedResources=<memory:16384, vCores:2>, usedCapacity=0.5, absoluteUsedCapacity=0.5, numApps=1, numContainers=2
2020-02-06 02:27:32,619 INFO org.apache.hadoop.yarn.server.resourcemanager.scheduler.capacity.CapacityScheduler: Application attempt appattempt_1580953164575_0010_000001 released container container_1580953164575_0010_01_000002 on node: host: nodemaster:8050 #containers=2 available=<memory:16384, vCores:8> used=<memory:16384, vCores:2> with event: FINISHED
2020-02-06 02:27:32,629 INFO org.apache.hadoop.yarn.server.resourcemanager.rmcontainer.RMContainerImpl: container_1580953164575_0010_01_000003 Container Transitioned from RUNNING to COMPLETED
2020-02-06 02:27:32,629 INFO org.apache.hadoop.yarn.server.resourcemanager.scheduler.common.fica.FiCaSchedulerApp: Completed container: container_1580953164575_0010_01_000003 in state: COMPLETED event:FINISHED
2020-02-06 02:27:32,629 INFO org.apache.hadoop.yarn.server.resourcemanager.RMAuditLogger: USER=hadoop	OPERATION=AM Released Container	TARGET=SchedulerApp	RESULT=SUCCESS	APPID=application_1580953164575_0010	CONTAINERID=container_1580953164575_0010_01_000003
2020-02-06 02:27:32,629 INFO org.apache.hadoop.yarn.server.resourcemanager.scheduler.SchedulerNode: Released container container_1580953164575_0010_01_000003 of capacity <memory:12288, vCores:1> on host nodemaster:8050, which currently has 1 containers, <memory:4096, vCores:1> used and <memory:28672, vCores:9> available, release resources=true
2020-02-06 02:27:32,629 INFO org.apache.hadoop.yarn.server.resourcemanager.scheduler.capacity.LeafQueue: default used=<memory:4096, vCores:1> numContainers=1 user=hadoop user-resources=<memory:4096, vCores:1>
2020-02-06 02:27:32,629 INFO org.apache.hadoop.yarn.server.resourcemanager.scheduler.capacity.LeafQueue: completedContainer container=Container: [ContainerId: container_1580953164575_0010_01_000003, NodeId: nodemaster:8050, NodeHttpAddress: nodemaster:8042, Resource: <memory:12288, vCores:1>, Priority: 1, Token: Token { kind: ContainerToken, service: 172.28.1.15:8050 }, ] queue=default: capacity=1.0, absoluteCapacity=1.0, usedResources=<memory:4096, vCores:1>, usedCapacity=0.125, absoluteUsedCapacity=0.125, numApps=1, numContainers=1 cluster=<memory:32768, vCores:10>
2020-02-06 02:27:32,629 INFO org.apache.hadoop.yarn.server.resourcemanager.scheduler.capacity.ParentQueue: completedContainer queue=root usedCapacity=0.125 absoluteUsedCapacity=0.125 used=<memory:4096, vCores:1> cluster=<memory:32768, vCores:10>
2020-02-06 02:27:32,629 INFO org.apache.hadoop.yarn.server.resourcemanager.scheduler.capacity.ParentQueue: Re-sorting completed queue: root.default stats: default: capacity=1.0, absoluteCapacity=1.0, usedResources=<memory:4096, vCores:1>, usedCapacity=0.125, absoluteUsedCapacity=0.125, numApps=1, numContainers=1
2020-02-06 02:27:32,629 INFO org.apache.hadoop.yarn.server.resourcemanager.scheduler.capacity.CapacityScheduler: Application attempt appattempt_1580953164575_0010_000001 released container container_1580953164575_0010_01_000003 on node: host: nodemaster:8050 #containers=1 available=<memory:28672, vCores:9> used=<memory:4096, vCores:1> with event: FINISHED
2020-02-06 02:27:32,687 INFO org.apache.hadoop.yarn.server.resourcemanager.ApplicationMasterService: application_1580953164575_0010 unregistered successfully. 
2020-02-06 02:27:33,089 INFO org.apache.hadoop.yarn.server.resourcemanager.rmcontainer.RMContainerImpl: container_1580953164575_0010_01_000001 Container Transitioned from RUNNING to COMPLETED
2020-02-06 02:27:33,089 INFO org.apache.hadoop.yarn.server.resourcemanager.ApplicationMasterService: Unregistering app attempt : appattempt_1580953164575_0010_000001
2020-02-06 02:27:33,090 INFO org.apache.hadoop.yarn.server.resourcemanager.security.AMRMTokenSecretManager: Application finished, removing password for appattempt_1580953164575_0010_000001
2020-02-06 02:27:33,089 INFO org.apache.hadoop.yarn.server.resourcemanager.scheduler.common.fica.FiCaSchedulerApp: Completed container: container_1580953164575_0010_01_000001 in state: COMPLETED event:FINISHED
2020-02-06 02:27:33,090 INFO org.apache.hadoop.yarn.server.resourcemanager.rmapp.attempt.RMAppAttemptImpl: appattempt_1580953164575_0010_000001 State change from FINISHING to FINISHED
2020-02-06 02:27:33,090 INFO org.apache.hadoop.yarn.server.resourcemanager.RMAuditLogger: USER=hadoop	OPERATION=AM Released Container	TARGET=SchedulerApp	RESULT=SUCCESS	APPID=application_1580953164575_0010	CONTAINERID=container_1580953164575_0010_01_000001
2020-02-06 02:27:33,090 INFO org.apache.hadoop.yarn.server.resourcemanager.rmapp.RMAppImpl: application_1580953164575_0010 State change from FINISHING to FINISHED on event=ATTEMPT_FINISHED
2020-02-06 02:27:33,090 INFO org.apache.hadoop.yarn.server.resourcemanager.scheduler.SchedulerNode: Released container container_1580953164575_0010_01_000001 of capacity <memory:4096, vCores:1> on host nodemaster:8050, which currently has 0 containers, <memory:0, vCores:0> used and <memory:32768, vCores:10> available, release resources=true
2020-02-06 02:27:33,090 INFO org.apache.hadoop.yarn.server.resourcemanager.RMAuditLogger: USER=hadoop	OPERATION=Application Finished - Succeeded	TARGET=RMAppManager	RESULT=SUCCESS	APPID=application_1580953164575_0010
2020-02-06 02:27:33,090 INFO org.apache.hadoop.yarn.server.resourcemanager.scheduler.capacity.LeafQueue: default used=<memory:0, vCores:0> numContainers=0 user=hadoop user-resources=<memory:0, vCores:0>
2020-02-06 02:27:33,090 INFO org.apache.hadoop.yarn.server.resourcemanager.scheduler.capacity.LeafQueue: completedContainer container=Container: [ContainerId: container_1580953164575_0010_01_000001, NodeId: nodemaster:8050, NodeHttpAddress: nodemaster:8042, Resource: <memory:4096, vCores:1>, Priority: 0, Token: Token { kind: ContainerToken, service: 172.28.1.15:8050 }, ] queue=default: capacity=1.0, absoluteCapacity=1.0, usedResources=<memory:0, vCores:0>, usedCapacity=0.0, absoluteUsedCapacity=0.0, numApps=1, numContainers=0 cluster=<memory:32768, vCores:10>
2020-02-06 02:27:33,090 INFO org.apache.hadoop.yarn.server.resourcemanager.scheduler.capacity.ParentQueue: completedContainer queue=root usedCapacity=0.0 absoluteUsedCapacity=0.0 used=<memory:0, vCores:0> cluster=<memory:32768, vCores:10>
2020-02-06 02:27:33,090 INFO org.apache.hadoop.yarn.server.resourcemanager.scheduler.capacity.ParentQueue: Re-sorting completed queue: root.default stats: default: capacity=1.0, absoluteCapacity=1.0, usedResources=<memory:0, vCores:0>, usedCapacity=0.0, absoluteUsedCapacity=0.0, numApps=1, numContainers=0
2020-02-06 02:27:33,090 INFO org.apache.hadoop.yarn.server.resourcemanager.scheduler.capacity.CapacityScheduler: Application attempt appattempt_1580953164575_0010_000001 released container container_1580953164575_0010_01_000001 on node: host: nodemaster:8050 #containers=0 available=<memory:32768, vCores:10> used=<memory:0, vCores:0> with event: FINISHED
2020-02-06 02:27:33,090 INFO org.apache.hadoop.yarn.server.resourcemanager.RMAppManager$ApplicationSummary: appId=application_1580953164575_0010,name=gen,user=hadoop,queue=default,state=FINISHED,trackingUrl=http://nodemaster:8088/proxy/application_1580953164575_0010/,appMasterHost=172.28.1.15,startTime=1580956038382,finishTime=1580956052584,finalStatus=SUCCEEDED,memorySeconds=298597,vcoreSeconds=32,preemptedAMContainers=0,preemptedNonAMContainers=0,preemptedResources=<memory:0\, vCores:0>,applicationType=SPARK
2020-02-06 02:27:33,090 INFO org.apache.hadoop.yarn.server.resourcemanager.scheduler.capacity.CapacityScheduler: Application Attempt appattempt_1580953164575_0010_000001 is done. finalState=FINISHED
2020-02-06 02:27:33,091 INFO org.apache.hadoop.yarn.server.resourcemanager.scheduler.AppSchedulingInfo: Application application_1580953164575_0010 requests cleared
2020-02-06 02:27:33,091 INFO org.apache.hadoop.yarn.server.resourcemanager.scheduler.capacity.LeafQueue: Application removed - appId: application_1580953164575_0010 user: hadoop queue: default #user-pending-applications: 0 #user-active-applications: 0 #queue-pending-applications: 0 #queue-active-applications: 0
2020-02-06 02:27:33,091 INFO org.apache.hadoop.yarn.server.resourcemanager.scheduler.capacity.ParentQueue: Application removed - appId: application_1580953164575_0010 user: hadoop leaf-queue of parent: root #applications: 0
2020-02-06 02:27:33,091 INFO org.apache.hadoop.yarn.server.resourcemanager.amlauncher.AMLauncher: Cleaning master appattempt_1580953164575_0010_000001
2020-02-06 02:27:35,093 INFO org.apache.hadoop.yarn.server.resourcemanager.scheduler.capacity.CapacityScheduler: Null container completed...
2020-02-06 02:27:35,094 INFO org.apache.hadoop.yarn.server.resourcemanager.scheduler.capacity.CapacityScheduler: Null container completed...
2020-02-06 02:41:16,802 INFO org.apache.hadoop.yarn.server.resourcemanager.ClientRMService: Allocated new applicationId: 11
2020-02-06 02:41:20,192 WARN org.apache.hadoop.yarn.server.resourcemanager.rmapp.RMAppImpl: The specific max attempts: 0 for application: 11 is invalid, because it is out of the range [1, 2]. Use the global max attempts instead.
2020-02-06 02:41:20,193 INFO org.apache.hadoop.yarn.server.resourcemanager.ClientRMService: Application with id 11 submitted by user hadoop
2020-02-06 02:41:20,193 INFO org.apache.hadoop.yarn.server.resourcemanager.RMAuditLogger: USER=hadoop	IP=172.28.1.15	OPERATION=Submit Application Request	TARGET=ClientRMService	RESULT=SUCCESS	APPID=application_1580953164575_0011
2020-02-06 02:41:20,193 INFO org.apache.hadoop.yarn.server.resourcemanager.rmapp.RMAppImpl: Storing application with id application_1580953164575_0011
2020-02-06 02:41:20,193 INFO org.apache.hadoop.yarn.server.resourcemanager.rmapp.RMAppImpl: application_1580953164575_0011 State change from NEW to NEW_SAVING on event=START
2020-02-06 02:41:20,193 INFO org.apache.hadoop.yarn.server.resourcemanager.recovery.RMStateStore: Storing info for app: application_1580953164575_0011
2020-02-06 02:41:20,193 INFO org.apache.hadoop.yarn.server.resourcemanager.rmapp.RMAppImpl: application_1580953164575_0011 State change from NEW_SAVING to SUBMITTED on event=APP_NEW_SAVED
2020-02-06 02:41:20,193 INFO org.apache.hadoop.yarn.server.resourcemanager.scheduler.capacity.ParentQueue: Application added - appId: application_1580953164575_0011 user: hadoop leaf-queue of parent: root #applications: 1
2020-02-06 02:41:20,193 INFO org.apache.hadoop.yarn.server.resourcemanager.scheduler.capacity.CapacityScheduler: Accepted application application_1580953164575_0011 from user: hadoop, in queue: default
2020-02-06 02:41:20,193 INFO org.apache.hadoop.yarn.server.resourcemanager.rmapp.RMAppImpl: application_1580953164575_0011 State change from SUBMITTED to ACCEPTED on event=APP_ACCEPTED
2020-02-06 02:41:20,193 INFO org.apache.hadoop.yarn.server.resourcemanager.ApplicationMasterService: Registering app attempt : appattempt_1580953164575_0011_000001
2020-02-06 02:41:20,193 INFO org.apache.hadoop.yarn.server.resourcemanager.rmapp.attempt.RMAppAttemptImpl: appattempt_1580953164575_0011_000001 State change from NEW to SUBMITTED
2020-02-06 02:41:20,193 INFO org.apache.hadoop.yarn.server.resourcemanager.scheduler.capacity.LeafQueue: Application application_1580953164575_0011 from user: hadoop activated in queue: default
2020-02-06 02:41:20,193 INFO org.apache.hadoop.yarn.server.resourcemanager.scheduler.capacity.LeafQueue: Application added - appId: application_1580953164575_0011 user: org.apache.hadoop.yarn.server.resourcemanager.scheduler.capacity.LeafQueue$User@3eb96f7, leaf-queue: default #user-pending-applications: 0 #user-active-applications: 1 #queue-pending-applications: 0 #queue-active-applications: 1
2020-02-06 02:41:20,193 INFO org.apache.hadoop.yarn.server.resourcemanager.scheduler.capacity.CapacityScheduler: Added Application Attempt appattempt_1580953164575_0011_000001 to scheduler from user hadoop in queue default
2020-02-06 02:41:20,194 INFO org.apache.hadoop.yarn.server.resourcemanager.rmapp.attempt.RMAppAttemptImpl: appattempt_1580953164575_0011_000001 State change from SUBMITTED to SCHEDULED
2020-02-06 02:41:21,091 INFO org.apache.hadoop.yarn.server.resourcemanager.rmcontainer.RMContainerImpl: container_1580953164575_0011_01_000001 Container Transitioned from NEW to ALLOCATED
2020-02-06 02:41:21,091 INFO org.apache.hadoop.yarn.server.resourcemanager.RMAuditLogger: USER=hadoop	OPERATION=AM Allocated Container	TARGET=SchedulerApp	RESULT=SUCCESS	APPID=application_1580953164575_0011	CONTAINERID=container_1580953164575_0011_01_000001
2020-02-06 02:41:21,091 INFO org.apache.hadoop.yarn.server.resourcemanager.scheduler.SchedulerNode: Assigned container container_1580953164575_0011_01_000001 of capacity <memory:4096, vCores:1> on host nodemaster:8050, which has 1 containers, <memory:4096, vCores:1> used and <memory:28672, vCores:9> available after allocation
2020-02-06 02:41:21,091 INFO org.apache.hadoop.yarn.server.resourcemanager.scheduler.capacity.LeafQueue: assignedContainer application attempt=appattempt_1580953164575_0011_000001 container=Container: [ContainerId: container_1580953164575_0011_01_000001, NodeId: nodemaster:8050, NodeHttpAddress: nodemaster:8042, Resource: <memory:4096, vCores:1>, Priority: 0, Token: null, ] queue=default: capacity=1.0, absoluteCapacity=1.0, usedResources=<memory:0, vCores:0>, usedCapacity=0.0, absoluteUsedCapacity=0.0, numApps=1, numContainers=0 clusterResource=<memory:32768, vCores:10> type=OFF_SWITCH requestedPartition=
2020-02-06 02:41:21,091 INFO org.apache.hadoop.yarn.server.resourcemanager.scheduler.capacity.ParentQueue: Re-sorting assigned queue: root.default stats: default: capacity=1.0, absoluteCapacity=1.0, usedResources=<memory:4096, vCores:1>, usedCapacity=0.125, absoluteUsedCapacity=0.125, numApps=1, numContainers=1
2020-02-06 02:41:21,091 INFO org.apache.hadoop.yarn.server.resourcemanager.scheduler.capacity.ParentQueue: assignedContainer queue=root usedCapacity=0.125 absoluteUsedCapacity=0.125 used=<memory:4096, vCores:1> cluster=<memory:32768, vCores:10>
2020-02-06 02:41:21,091 INFO org.apache.hadoop.yarn.server.resourcemanager.security.NMTokenSecretManagerInRM: Sending NMToken for nodeId : nodemaster:8050 for container : container_1580953164575_0011_01_000001
2020-02-06 02:41:21,092 INFO org.apache.hadoop.yarn.server.resourcemanager.rmcontainer.RMContainerImpl: container_1580953164575_0011_01_000001 Container Transitioned from ALLOCATED to ACQUIRED
2020-02-06 02:41:21,092 INFO org.apache.hadoop.yarn.server.resourcemanager.security.NMTokenSecretManagerInRM: Clear node set for appattempt_1580953164575_0011_000001
2020-02-06 02:41:21,092 INFO org.apache.hadoop.yarn.server.resourcemanager.rmapp.attempt.RMAppAttemptImpl: Storing attempt: AppId: application_1580953164575_0011 AttemptId: appattempt_1580953164575_0011_000001 MasterContainer: Container: [ContainerId: container_1580953164575_0011_01_000001, NodeId: nodemaster:8050, NodeHttpAddress: nodemaster:8042, Resource: <memory:4096, vCores:1>, Priority: 0, Token: Token { kind: ContainerToken, service: 172.28.1.15:8050 }, ]
2020-02-06 02:41:21,092 INFO org.apache.hadoop.yarn.server.resourcemanager.rmapp.attempt.RMAppAttemptImpl: appattempt_1580953164575_0011_000001 State change from SCHEDULED to ALLOCATED_SAVING
2020-02-06 02:41:21,092 INFO org.apache.hadoop.yarn.server.resourcemanager.rmapp.attempt.RMAppAttemptImpl: appattempt_1580953164575_0011_000001 State change from ALLOCATED_SAVING to ALLOCATED
2020-02-06 02:41:21,092 INFO org.apache.hadoop.yarn.server.resourcemanager.amlauncher.AMLauncher: Launching masterappattempt_1580953164575_0011_000001
2020-02-06 02:41:21,093 INFO org.apache.hadoop.yarn.server.resourcemanager.amlauncher.AMLauncher: Setting up container Container: [ContainerId: container_1580953164575_0011_01_000001, NodeId: nodemaster:8050, NodeHttpAddress: nodemaster:8042, Resource: <memory:4096, vCores:1>, Priority: 0, Token: Token { kind: ContainerToken, service: 172.28.1.15:8050 }, ] for AM appattempt_1580953164575_0011_000001
2020-02-06 02:41:21,093 INFO org.apache.hadoop.yarn.server.resourcemanager.amlauncher.AMLauncher: Command to launch container container_1580953164575_0011_01_000001 : {{JAVA_HOME}}/bin/java,-server,-Xmx512m,-Djava.io.tmpdir={{PWD}}/tmp,-Dspark.yarn.app.container.log.dir=<LOG_DIR>,org.apache.spark.deploy.yarn.ExecutorLauncher,--arg,'nodemaster:40971',--properties-file,{{PWD}}/__spark_conf__/__spark_conf__.properties,1>,<LOG_DIR>/stdout,2>,<LOG_DIR>/stderr
2020-02-06 02:41:21,093 INFO org.apache.hadoop.yarn.server.resourcemanager.security.AMRMTokenSecretManager: Create AMRMToken for ApplicationAttempt: appattempt_1580953164575_0011_000001
2020-02-06 02:41:21,093 INFO org.apache.hadoop.yarn.server.resourcemanager.security.AMRMTokenSecretManager: Creating password for appattempt_1580953164575_0011_000001
2020-02-06 02:41:21,097 INFO org.apache.hadoop.yarn.server.resourcemanager.amlauncher.AMLauncher: Done launching container Container: [ContainerId: container_1580953164575_0011_01_000001, NodeId: nodemaster:8050, NodeHttpAddress: nodemaster:8042, Resource: <memory:4096, vCores:1>, Priority: 0, Token: Token { kind: ContainerToken, service: 172.28.1.15:8050 }, ] for AM appattempt_1580953164575_0011_000001
2020-02-06 02:41:21,097 INFO org.apache.hadoop.yarn.server.resourcemanager.rmapp.attempt.RMAppAttemptImpl: appattempt_1580953164575_0011_000001 State change from ALLOCATED to LAUNCHED
2020-02-06 02:41:22,091 INFO org.apache.hadoop.yarn.server.resourcemanager.rmcontainer.RMContainerImpl: container_1580953164575_0011_01_000001 Container Transitioned from ACQUIRED to RUNNING
2020-02-06 02:41:23,436 INFO SecurityLogger.org.apache.hadoop.ipc.Server: Auth successful for appattempt_1580953164575_0011_000001 (auth:SIMPLE)
2020-02-06 02:41:23,439 INFO org.apache.hadoop.yarn.server.resourcemanager.ApplicationMasterService: AM registration appattempt_1580953164575_0011_000001
2020-02-06 02:41:23,439 INFO org.apache.hadoop.yarn.server.resourcemanager.RMAuditLogger: USER=hadoop	IP=172.28.1.15	OPERATION=Register App Master	TARGET=ApplicationMasterService	RESULT=SUCCESS	APPID=application_1580953164575_0011	APPATTEMPTID=appattempt_1580953164575_0011_000001
2020-02-06 02:41:23,439 INFO org.apache.hadoop.yarn.server.resourcemanager.rmapp.attempt.RMAppAttemptImpl: appattempt_1580953164575_0011_000001 State change from LAUNCHED to RUNNING
2020-02-06 02:41:23,439 INFO org.apache.hadoop.yarn.server.resourcemanager.rmapp.RMAppImpl: application_1580953164575_0011 State change from ACCEPTED to RUNNING on event=ATTEMPT_REGISTERED
2020-02-06 02:41:24,092 INFO org.apache.hadoop.yarn.server.resourcemanager.rmcontainer.RMContainerImpl: container_1580953164575_0011_01_000002 Container Transitioned from NEW to ALLOCATED
2020-02-06 02:41:24,093 INFO org.apache.hadoop.yarn.server.resourcemanager.RMAuditLogger: USER=hadoop	OPERATION=AM Allocated Container	TARGET=SchedulerApp	RESULT=SUCCESS	APPID=application_1580953164575_0011	CONTAINERID=container_1580953164575_0011_01_000002
2020-02-06 02:41:24,093 INFO org.apache.hadoop.yarn.server.resourcemanager.scheduler.SchedulerNode: Assigned container container_1580953164575_0011_01_000002 of capacity <memory:12288, vCores:1> on host nodemaster:8050, which has 2 containers, <memory:16384, vCores:2> used and <memory:16384, vCores:8> available after allocation
2020-02-06 02:41:24,093 INFO org.apache.hadoop.yarn.server.resourcemanager.scheduler.capacity.LeafQueue: assignedContainer application attempt=appattempt_1580953164575_0011_000001 container=Container: [ContainerId: container_1580953164575_0011_01_000002, NodeId: nodemaster:8050, NodeHttpAddress: nodemaster:8042, Resource: <memory:12288, vCores:1>, Priority: 1, Token: null, ] queue=default: capacity=1.0, absoluteCapacity=1.0, usedResources=<memory:4096, vCores:1>, usedCapacity=0.125, absoluteUsedCapacity=0.125, numApps=1, numContainers=1 clusterResource=<memory:32768, vCores:10> type=OFF_SWITCH requestedPartition=
2020-02-06 02:41:24,093 INFO org.apache.hadoop.yarn.server.resourcemanager.scheduler.capacity.ParentQueue: Re-sorting assigned queue: root.default stats: default: capacity=1.0, absoluteCapacity=1.0, usedResources=<memory:16384, vCores:2>, usedCapacity=0.5, absoluteUsedCapacity=0.5, numApps=1, numContainers=2
2020-02-06 02:41:24,093 INFO org.apache.hadoop.yarn.server.resourcemanager.scheduler.capacity.ParentQueue: assignedContainer queue=root usedCapacity=0.5 absoluteUsedCapacity=0.5 used=<memory:16384, vCores:2> cluster=<memory:32768, vCores:10>
2020-02-06 02:41:24,095 INFO org.apache.hadoop.yarn.server.resourcemanager.security.NMTokenSecretManagerInRM: Sending NMToken for nodeId : nodemaster:8050 for container : container_1580953164575_0011_01_000002
2020-02-06 02:41:24,095 INFO org.apache.hadoop.yarn.server.resourcemanager.rmcontainer.RMContainerImpl: container_1580953164575_0011_01_000002 Container Transitioned from ALLOCATED to ACQUIRED
2020-02-06 02:41:25,093 INFO org.apache.hadoop.yarn.server.resourcemanager.rmcontainer.RMContainerImpl: container_1580953164575_0011_01_000002 Container Transitioned from ACQUIRED to RUNNING
2020-02-06 02:41:25,093 INFO org.apache.hadoop.yarn.server.resourcemanager.rmcontainer.RMContainerImpl: container_1580953164575_0011_01_000003 Container Transitioned from NEW to ALLOCATED
2020-02-06 02:41:25,093 INFO org.apache.hadoop.yarn.server.resourcemanager.RMAuditLogger: USER=hadoop	OPERATION=AM Allocated Container	TARGET=SchedulerApp	RESULT=SUCCESS	APPID=application_1580953164575_0011	CONTAINERID=container_1580953164575_0011_01_000003
2020-02-06 02:41:25,093 INFO org.apache.hadoop.yarn.server.resourcemanager.scheduler.SchedulerNode: Assigned container container_1580953164575_0011_01_000003 of capacity <memory:12288, vCores:1> on host nodemaster:8050, which has 3 containers, <memory:28672, vCores:3> used and <memory:4096, vCores:7> available after allocation
2020-02-06 02:41:25,093 INFO org.apache.hadoop.yarn.server.resourcemanager.scheduler.capacity.LeafQueue: assignedContainer application attempt=appattempt_1580953164575_0011_000001 container=Container: [ContainerId: container_1580953164575_0011_01_000003, NodeId: nodemaster:8050, NodeHttpAddress: nodemaster:8042, Resource: <memory:12288, vCores:1>, Priority: 1, Token: null, ] queue=default: capacity=1.0, absoluteCapacity=1.0, usedResources=<memory:16384, vCores:2>, usedCapacity=0.5, absoluteUsedCapacity=0.5, numApps=1, numContainers=2 clusterResource=<memory:32768, vCores:10> type=OFF_SWITCH requestedPartition=
2020-02-06 02:41:25,093 INFO org.apache.hadoop.yarn.server.resourcemanager.scheduler.capacity.ParentQueue: Re-sorting assigned queue: root.default stats: default: capacity=1.0, absoluteCapacity=1.0, usedResources=<memory:28672, vCores:3>, usedCapacity=0.875, absoluteUsedCapacity=0.875, numApps=1, numContainers=3
2020-02-06 02:41:25,093 INFO org.apache.hadoop.yarn.server.resourcemanager.scheduler.capacity.ParentQueue: assignedContainer queue=root usedCapacity=0.875 absoluteUsedCapacity=0.875 used=<memory:28672, vCores:3> cluster=<memory:32768, vCores:10>
2020-02-06 02:41:26,505 INFO org.apache.hadoop.yarn.server.resourcemanager.rmcontainer.RMContainerImpl: container_1580953164575_0011_01_000003 Container Transitioned from ALLOCATED to ACQUIRED
2020-02-06 02:41:27,094 INFO org.apache.hadoop.yarn.server.resourcemanager.rmcontainer.RMContainerImpl: container_1580953164575_0011_01_000003 Container Transitioned from ACQUIRED to RUNNING
2020-02-06 02:41:29,508 INFO org.apache.hadoop.yarn.server.resourcemanager.scheduler.AppSchedulingInfo: checking for deactivate of application :application_1580953164575_0011
2020-02-06 02:41:34,785 INFO org.apache.hadoop.yarn.server.resourcemanager.rmapp.attempt.RMAppAttemptImpl: Updating application attempt appattempt_1580953164575_0011_000001 with final state: FINISHING, and exit status: -1000
2020-02-06 02:41:34,785 INFO org.apache.hadoop.yarn.server.resourcemanager.rmapp.attempt.RMAppAttemptImpl: appattempt_1580953164575_0011_000001 State change from RUNNING to FINAL_SAVING
2020-02-06 02:41:34,785 INFO org.apache.hadoop.yarn.server.resourcemanager.rmapp.RMAppImpl: Updating application application_1580953164575_0011 with final state: FINISHING
2020-02-06 02:41:34,785 INFO org.apache.hadoop.yarn.server.resourcemanager.rmapp.RMAppImpl: application_1580953164575_0011 State change from RUNNING to FINAL_SAVING on event=ATTEMPT_UNREGISTERED
2020-02-06 02:41:34,785 INFO org.apache.hadoop.yarn.server.resourcemanager.recovery.RMStateStore: Updating info for app: application_1580953164575_0011
2020-02-06 02:41:34,785 INFO org.apache.hadoop.yarn.server.resourcemanager.rmapp.attempt.RMAppAttemptImpl: appattempt_1580953164575_0011_000001 State change from FINAL_SAVING to FINISHING
2020-02-06 02:41:34,785 INFO org.apache.hadoop.yarn.server.resourcemanager.rmapp.RMAppImpl: application_1580953164575_0011 State change from FINAL_SAVING to FINISHING on event=APP_UPDATE_SAVED
2020-02-06 02:41:34,833 INFO org.apache.hadoop.yarn.server.resourcemanager.rmcontainer.RMContainerImpl: container_1580953164575_0011_01_000003 Container Transitioned from RUNNING to COMPLETED
2020-02-06 02:41:34,833 INFO org.apache.hadoop.yarn.server.resourcemanager.scheduler.common.fica.FiCaSchedulerApp: Completed container: container_1580953164575_0011_01_000003 in state: COMPLETED event:FINISHED
2020-02-06 02:41:34,833 INFO org.apache.hadoop.yarn.server.resourcemanager.RMAuditLogger: USER=hadoop	OPERATION=AM Released Container	TARGET=SchedulerApp	RESULT=SUCCESS	APPID=application_1580953164575_0011	CONTAINERID=container_1580953164575_0011_01_000003
2020-02-06 02:41:34,833 INFO org.apache.hadoop.yarn.server.resourcemanager.scheduler.SchedulerNode: Released container container_1580953164575_0011_01_000003 of capacity <memory:12288, vCores:1> on host nodemaster:8050, which currently has 2 containers, <memory:16384, vCores:2> used and <memory:16384, vCores:8> available, release resources=true
2020-02-06 02:41:34,833 INFO org.apache.hadoop.yarn.server.resourcemanager.scheduler.capacity.LeafQueue: default used=<memory:16384, vCores:2> numContainers=2 user=hadoop user-resources=<memory:16384, vCores:2>
2020-02-06 02:41:34,833 INFO org.apache.hadoop.yarn.server.resourcemanager.scheduler.capacity.LeafQueue: completedContainer container=Container: [ContainerId: container_1580953164575_0011_01_000003, NodeId: nodemaster:8050, NodeHttpAddress: nodemaster:8042, Resource: <memory:12288, vCores:1>, Priority: 1, Token: Token { kind: ContainerToken, service: 172.28.1.15:8050 }, ] queue=default: capacity=1.0, absoluteCapacity=1.0, usedResources=<memory:16384, vCores:2>, usedCapacity=0.5, absoluteUsedCapacity=0.5, numApps=1, numContainers=2 cluster=<memory:32768, vCores:10>
2020-02-06 02:41:34,833 INFO org.apache.hadoop.yarn.server.resourcemanager.scheduler.capacity.ParentQueue: completedContainer queue=root usedCapacity=0.5 absoluteUsedCapacity=0.5 used=<memory:16384, vCores:2> cluster=<memory:32768, vCores:10>
2020-02-06 02:41:34,833 INFO org.apache.hadoop.yarn.server.resourcemanager.scheduler.capacity.ParentQueue: Re-sorting completed queue: root.default stats: default: capacity=1.0, absoluteCapacity=1.0, usedResources=<memory:16384, vCores:2>, usedCapacity=0.5, absoluteUsedCapacity=0.5, numApps=1, numContainers=2
2020-02-06 02:41:34,833 INFO org.apache.hadoop.yarn.server.resourcemanager.scheduler.capacity.CapacityScheduler: Application attempt appattempt_1580953164575_0011_000001 released container container_1580953164575_0011_01_000003 on node: host: nodemaster:8050 #containers=2 available=<memory:16384, vCores:8> used=<memory:16384, vCores:2> with event: FINISHED
2020-02-06 02:41:34,844 INFO org.apache.hadoop.yarn.server.resourcemanager.rmcontainer.RMContainerImpl: container_1580953164575_0011_01_000002 Container Transitioned from RUNNING to COMPLETED
2020-02-06 02:41:34,844 INFO org.apache.hadoop.yarn.server.resourcemanager.scheduler.common.fica.FiCaSchedulerApp: Completed container: container_1580953164575_0011_01_000002 in state: COMPLETED event:FINISHED
2020-02-06 02:41:34,844 INFO org.apache.hadoop.yarn.server.resourcemanager.RMAuditLogger: USER=hadoop	OPERATION=AM Released Container	TARGET=SchedulerApp	RESULT=SUCCESS	APPID=application_1580953164575_0011	CONTAINERID=container_1580953164575_0011_01_000002
2020-02-06 02:41:34,844 INFO org.apache.hadoop.yarn.server.resourcemanager.scheduler.SchedulerNode: Released container container_1580953164575_0011_01_000002 of capacity <memory:12288, vCores:1> on host nodemaster:8050, which currently has 1 containers, <memory:4096, vCores:1> used and <memory:28672, vCores:9> available, release resources=true
2020-02-06 02:41:34,844 INFO org.apache.hadoop.yarn.server.resourcemanager.scheduler.capacity.LeafQueue: default used=<memory:4096, vCores:1> numContainers=1 user=hadoop user-resources=<memory:4096, vCores:1>
2020-02-06 02:41:34,845 INFO org.apache.hadoop.yarn.server.resourcemanager.scheduler.capacity.LeafQueue: completedContainer container=Container: [ContainerId: container_1580953164575_0011_01_000002, NodeId: nodemaster:8050, NodeHttpAddress: nodemaster:8042, Resource: <memory:12288, vCores:1>, Priority: 1, Token: Token { kind: ContainerToken, service: 172.28.1.15:8050 }, ] queue=default: capacity=1.0, absoluteCapacity=1.0, usedResources=<memory:4096, vCores:1>, usedCapacity=0.125, absoluteUsedCapacity=0.125, numApps=1, numContainers=1 cluster=<memory:32768, vCores:10>
2020-02-06 02:41:34,845 INFO org.apache.hadoop.yarn.server.resourcemanager.scheduler.capacity.ParentQueue: completedContainer queue=root usedCapacity=0.125 absoluteUsedCapacity=0.125 used=<memory:4096, vCores:1> cluster=<memory:32768, vCores:10>
2020-02-06 02:41:34,845 INFO org.apache.hadoop.yarn.server.resourcemanager.scheduler.capacity.ParentQueue: Re-sorting completed queue: root.default stats: default: capacity=1.0, absoluteCapacity=1.0, usedResources=<memory:4096, vCores:1>, usedCapacity=0.125, absoluteUsedCapacity=0.125, numApps=1, numContainers=1
2020-02-06 02:41:34,845 INFO org.apache.hadoop.yarn.server.resourcemanager.scheduler.capacity.CapacityScheduler: Application attempt appattempt_1580953164575_0011_000001 released container container_1580953164575_0011_01_000002 on node: host: nodemaster:8050 #containers=1 available=<memory:28672, vCores:9> used=<memory:4096, vCores:1> with event: FINISHED
2020-02-06 02:41:34,887 INFO org.apache.hadoop.yarn.server.resourcemanager.ApplicationMasterService: application_1580953164575_0011 unregistered successfully. 
2020-02-06 02:41:35,274 INFO org.apache.hadoop.yarn.server.resourcemanager.rmcontainer.RMContainerImpl: container_1580953164575_0011_01_000001 Container Transitioned from RUNNING to COMPLETED
2020-02-06 02:41:35,274 INFO org.apache.hadoop.yarn.server.resourcemanager.ApplicationMasterService: Unregistering app attempt : appattempt_1580953164575_0011_000001
2020-02-06 02:41:35,274 INFO org.apache.hadoop.yarn.server.resourcemanager.security.AMRMTokenSecretManager: Application finished, removing password for appattempt_1580953164575_0011_000001
2020-02-06 02:41:35,274 INFO org.apache.hadoop.yarn.server.resourcemanager.scheduler.common.fica.FiCaSchedulerApp: Completed container: container_1580953164575_0011_01_000001 in state: COMPLETED event:FINISHED
2020-02-06 02:41:35,274 INFO org.apache.hadoop.yarn.server.resourcemanager.rmapp.attempt.RMAppAttemptImpl: appattempt_1580953164575_0011_000001 State change from FINISHING to FINISHED
2020-02-06 02:41:35,274 INFO org.apache.hadoop.yarn.server.resourcemanager.RMAuditLogger: USER=hadoop	OPERATION=AM Released Container	TARGET=SchedulerApp	RESULT=SUCCESS	APPID=application_1580953164575_0011	CONTAINERID=container_1580953164575_0011_01_000001
2020-02-06 02:41:35,274 INFO org.apache.hadoop.yarn.server.resourcemanager.rmapp.RMAppImpl: application_1580953164575_0011 State change from FINISHING to FINISHED on event=ATTEMPT_FINISHED
2020-02-06 02:41:35,274 INFO org.apache.hadoop.yarn.server.resourcemanager.scheduler.SchedulerNode: Released container container_1580953164575_0011_01_000001 of capacity <memory:4096, vCores:1> on host nodemaster:8050, which currently has 0 containers, <memory:0, vCores:0> used and <memory:32768, vCores:10> available, release resources=true
2020-02-06 02:41:35,274 INFO org.apache.hadoop.yarn.server.resourcemanager.RMAuditLogger: USER=hadoop	OPERATION=Application Finished - Succeeded	TARGET=RMAppManager	RESULT=SUCCESS	APPID=application_1580953164575_0011
2020-02-06 02:41:35,274 INFO org.apache.hadoop.yarn.server.resourcemanager.scheduler.capacity.LeafQueue: default used=<memory:0, vCores:0> numContainers=0 user=hadoop user-resources=<memory:0, vCores:0>
2020-02-06 02:41:35,274 INFO org.apache.hadoop.yarn.server.resourcemanager.scheduler.capacity.LeafQueue: completedContainer container=Container: [ContainerId: container_1580953164575_0011_01_000001, NodeId: nodemaster:8050, NodeHttpAddress: nodemaster:8042, Resource: <memory:4096, vCores:1>, Priority: 0, Token: Token { kind: ContainerToken, service: 172.28.1.15:8050 }, ] queue=default: capacity=1.0, absoluteCapacity=1.0, usedResources=<memory:0, vCores:0>, usedCapacity=0.0, absoluteUsedCapacity=0.0, numApps=1, numContainers=0 cluster=<memory:32768, vCores:10>
2020-02-06 02:41:35,274 INFO org.apache.hadoop.yarn.server.resourcemanager.scheduler.capacity.ParentQueue: completedContainer queue=root usedCapacity=0.0 absoluteUsedCapacity=0.0 used=<memory:0, vCores:0> cluster=<memory:32768, vCores:10>
2020-02-06 02:41:35,274 INFO org.apache.hadoop.yarn.server.resourcemanager.scheduler.capacity.ParentQueue: Re-sorting completed queue: root.default stats: default: capacity=1.0, absoluteCapacity=1.0, usedResources=<memory:0, vCores:0>, usedCapacity=0.0, absoluteUsedCapacity=0.0, numApps=1, numContainers=0
2020-02-06 02:41:35,274 INFO org.apache.hadoop.yarn.server.resourcemanager.RMAppManager$ApplicationSummary: appId=application_1580953164575_0011,name=gen,user=hadoop,queue=default,state=FINISHED,trackingUrl=http://nodemaster:8088/proxy/application_1580953164575_0011/,appMasterHost=172.28.1.15,startTime=1580956880192,finishTime=1580956894785,finalStatus=SUCCEEDED,memorySeconds=309898,vcoreSeconds=33,preemptedAMContainers=0,preemptedNonAMContainers=0,preemptedResources=<memory:0\, vCores:0>,applicationType=SPARK
2020-02-06 02:41:35,274 INFO org.apache.hadoop.yarn.server.resourcemanager.scheduler.capacity.CapacityScheduler: Application attempt appattempt_1580953164575_0011_000001 released container container_1580953164575_0011_01_000001 on node: host: nodemaster:8050 #containers=0 available=<memory:32768, vCores:10> used=<memory:0, vCores:0> with event: FINISHED
2020-02-06 02:41:35,275 INFO org.apache.hadoop.yarn.server.resourcemanager.scheduler.capacity.CapacityScheduler: Application Attempt appattempt_1580953164575_0011_000001 is done. finalState=FINISHED
2020-02-06 02:41:35,275 INFO org.apache.hadoop.yarn.server.resourcemanager.amlauncher.AMLauncher: Cleaning master appattempt_1580953164575_0011_000001
2020-02-06 02:41:35,275 INFO org.apache.hadoop.yarn.server.resourcemanager.scheduler.AppSchedulingInfo: Application application_1580953164575_0011 requests cleared
2020-02-06 02:41:35,275 INFO org.apache.hadoop.yarn.server.resourcemanager.scheduler.capacity.LeafQueue: Application removed - appId: application_1580953164575_0011 user: hadoop queue: default #user-pending-applications: 0 #user-active-applications: 0 #queue-pending-applications: 0 #queue-active-applications: 0
2020-02-06 02:41:35,275 INFO org.apache.hadoop.yarn.server.resourcemanager.scheduler.capacity.ParentQueue: Application removed - appId: application_1580953164575_0011 user: hadoop leaf-queue of parent: root #applications: 0
2020-02-06 02:41:37,277 INFO org.apache.hadoop.yarn.server.resourcemanager.scheduler.capacity.CapacityScheduler: Null container completed...
2020-02-06 02:41:37,278 INFO org.apache.hadoop.yarn.server.resourcemanager.scheduler.capacity.CapacityScheduler: Null container completed...
